Workbook

Sheet B.S.
A1: NAME: | C1: hanno pop | F1: LOCATION: | H1: IMC | J1: C. ANALYST: | L1: ME
A2: Auditor: | F2: AMOUNTS IN: | H2: EGP | J2: D A T E : | L2: 12/2025
A3: Audited or Direct (Specify) | D3: Audited | F3: Audited | H3: Audited | J3: Audited | L3: Audited
A4: Unqualified or Qualified (Specify) | D4: Unqualified | F4: Unqualifed | H4: Unqualified | J4: Unqualified
A5: FREQUENCY/CYCLE
A6: DATE (Day, Month, Year) | D6: 31/7/2025 | F6: 31/8/2025 | H6: 31/12/2025 | J6: 28/2/2026
A7: D E S C R I P T I O N | D7: AMOUNT | E7: % | F7: AMOUNT | G7: % | H7: ي | I7: % | J7: AMOUNT | K7: % | L7: AMOUNT | M7: %
A8: REASONS FOR QUALIFICATION (IF ANY)
A20: BALANCE SHEET | D20: 31/7/2025 | F20: 31/8/2025 | H20: 31/12/2025
A21: 01 | C21: النقديه | D21: 116365.5 | E21: =IF(D$36=0,0,D21/D$36) -> 0.0058233184 | F21: 161402.9 | G21: =IF(F$36=0,0,F21/F$36) -> 0.0079971241 | H21: 519125 | I21: =IF(H$36=0,0,H21/H$36) -> 0.025577176 | K21: =IF(J$36=0,0,J21/J$36) -> 0 | M21: =IF(L$36=0,0,L21/L$36) -> 0 | O21: =IF(N$36=0,0,N21/N$36) -> 0
A22: 02 | B22: A | C22: ودائع لاجل | D22: 1150000 | E22: =IF(D$36=0,0,D22/D$36) -> 0.057549843 | F22: 1150000 | G22: =IF(F$36=0,0,F22/F$36) -> 0.056979724 | H22: 1150000 | I22: =IF(H$36=0,0,H22/H$36) -> 0.05666025 | K22: =IF(J$36=0,0,J22/J$36) -> 0 | M22: =IF(L$36=0,0,L22/L$36) -> 0 | O22: =IF(N$36=0,0,N22/N$36) -> 0 | P22: باقى فلوس القرض
A23: 03 | B23: S | C23: اوراق القبض+ رصيد العملاء | D23: 1957068 | E23: =IF(D$36=0,0,D23/D$36) -> 0.097938222 | F23: 2206877.2 | G23: =IF(F$36=0,0,F23/F$36) -> 0.10934544 | H23: =2384644+5000 -> 2389644 | I23: =IF(H$36=0,0,H23/H$36) -> 0.11773724 | K23: =IF(J$36=0,0,J23/J$36) -> 0 | M23: =IF(L$36=0,0,L23/L$36) -> 0 | O23: =IF(N$36=0,0,N23/N$36) -> 0
A24: 04 | B24: S | C24: المخزون | D24: 2737831.9 | E24: =IF(D$36=0,0,D24/D$36) -> 0.13701026 | F24: 2698031.8 | G24: =IF(F$36=0,0,F24/F$36) -> 0.13368096 | H24: 2951082.1 | I24: =IF(H$36=0,0,H24/H$36) -> 0.14539917 | K24: =IF(J$36=0,0,J24/J$36) -> 0 | M24: =IF(L$36=0,0,L24/L$36) -> 0 | O24: =IF(N$36=0,0,N24/N$36) -> 0
A25: 05 | B25: E | C25: مصروفات مقدمة | D25: 21175 | E25: =IF(D$36=0,0,D25/D$36) -> 0.0010596678 | F25: 0 | G25: =IF(F$36=0,0,F25/F$36) -> 0 | H25: 0 | I25: =IF(H$36=0,0,H25/H$36) -> 0 | K25: =IF(J$36=0,0,J25/J$36) -> 0 | M25: =IF(L$36=0,0,L25/L$36) -> 0 | O25: =IF(N$36=0,0,N25/N$36) -> 0
A26: 06 | B26: T | C26: اصول متداوله اخرى | D26: =1741113-1150000+67400+30000 -> 688513 | E26: =IF(D$36=0,0,D26/D$36) -> 0.034455491 | F26: 651081 | G26: =IF(F$36=0,0,F26/F$36) -> 0.032259492 | H26: =788978+381000 -> 1169978 | I26: =IF(H$36=0,0,H26/H$36) -> 0.057644561 | K26: =IF(J$36=0,0,J26/J$36) -> 0 | M26: =IF(L$36=0,0,L26/L$36) -> 0 | O26: =IF(N$36=0,0,N26/N$36) -> 0
A27: 07 | B27: S | C27: جاري شركات تابعة | D27: 0 | E27: =IF(D$36=0,0,D27/D$36) -> 0 | F27: 0 | G27: =IF(F$36=0,0,F27/F$36) -> 0 | H27: 0 | I27: =IF(H$36=0,0,H27/H$36) -> 0 | K27: =IF(J$36=0,0,J27/J$36) -> 0 | M27: =IF(L$36=0,0,L27/L$36) -> 0 | O27: =IF(N$36=0,0,N27/N$36) -> 0
A28: 08 | C28: اجمالى اصول متداوله | D28: =SUM(D21:D27) -> 6670953.4 | E28: =IF(D$36=0,0,D28/D$36) -> 0.3338368 | F28: =SUM(F21:F27) -> 6867392.9 | G28: =IF(F$36=0,0,F28/F$36) -> 0.34026274 | H28: =SUM(H21:H27) -> 8179829.1 | I28: =IF(H$36=0,0,H28/H$36) -> 0.4030184 | J28: =SUM(J21:J27) -> 0 | K28: =IF(J$36=0,0,J28/J$36) -> 0 | L28: =SUM(L21:L27) -> 0 | M28: =IF(L$36=0,0,L28/L$36) -> 0 | N28: =SUM(N21:N27) -> 0 | O28: =IF(N$36=0,0,N28/N$36) -> 0
A29: 09 | B29: A | C29: صافي الاصول الثابتة | D29: =14511725-1200000 -> 13311725 | E29: =IF(D$36=0,0,D29/D$36) -> 0.6661632 | F29: =+D29+3500 -> 13315225 | G29: =IF(F$36=0,0,F29/F$36) -> 0.65973726 | H29: =13315225+147650-1346288 -> 12116587 | I29: =IF(H$36=0,0,H29/H$36) -> 0.5969816 | K29: =IF(J$36=0,0,J29/J$36) -> 0 | M29: =IF(L$36=0,0,L29/L$36) -> 0 | O29: =IF(N$36=0,0,N29/N$36) -> 0
A30: 10 | B30: S | C30: استثمارات في شركات تابعة | D30: 0 | E30: =IF(D$36=0,0,D30/D$36) -> 0 | F30: 0 | G30: =IF(F$36=0,0,F30/F$36) -> 0 | H30: 0 | I30: =IF(H$36=0,0,H30/H$36) -> 0 | K30: =IF(J$36=0,0,J30/J$36) -> 0 | M30: =IF(L$36=0,0,L30/L$36) -> 0 | O30: =IF(N$36=0,0,N30/N$36) -> 0
A31: 11 | B31: S | C31: استثمارات طويلة الأجل | D31: 0 | E31: =IF(D$36=0,0,D31/D$36) -> 0 | F31: 0 | G31: =IF(F$36=0,0,F31/F$36) -> 0 | H31: 0 | I31: =IF(H$36=0,0,H31/H$36) -> 0 | K31: =IF(J$36=0,0,J31/J$36) -> 0 | M31: =IF(L$36=0,0,L31/L$36) -> 0 | O31: =IF(N$36=0,0,N31/N$36) -> 0
A32: 12 | B32: E | C32: جاري مصلحة الضرائب | D32: 0 | E32: =IF(D$36=0,0,D32/D$36) -> 0 | F32: 0 | G32: =IF(F$36=0,0,F32/F$36) -> 0 | H32: 0 | I32: =IF(H$36=0,0,H32/H$36) -> 0 | K32: =IF(J$36=0,0,J32/J$36) -> 0 | M32: =IF(L$36=0,0,L32/L$36) -> 0 | O32: =IF(N$36=0,0,N32/N$36) -> 0
A33: 13 | B33: T | C33: اصول اخرى غير متداوله | D33: 0 | E33: =IF(D$36=0,0,D33/D$36) -> 0 | F33: 0 | G33: =IF(F$36=0,0,F33/F$36) -> 0 | H33: 0 | I33: =IF(H$36=0,0,H33/H$36) -> 0 | K33: =IF(J$36=0,0,J33/J$36) -> 0 | M33: =IF(L$36=0,0,L33/L$36) -> 0 | O33: =IF(N$36=0,0,N33/N$36) -> 0
A34: 14 | B34: S | C34: (شهرة ) اصول غير ملموسه | D34: 0 | E34: =IF(D$36=0,0,D34/D$36) -> 0 | F34: 0 | G34: =IF(F$36=0,0,F34/F$36) -> 0 | H34: 0 | I34: =IF(H$36=0,0,H34/H$36) -> 0 | K34: =IF(J$36=0,0,J34/J$36) -> 0 | M34: =IF(L$36=0,0,L34/L$36) -> 0 | O34: =IF(N$36=0,0,N34/N$36) -> 0
A35: 15 | C35: اجمالى الاصول الغير متداوله | D35: =SUM(D29:D34) -> 13311725 | E35: =IF(D$36=0,0,D35/D$36) -> 0.6661632 | F35: =SUM(F29:F34) -> 13315225 | G35: =IF(F$36=0,0,F35/F$36) -> 0.65973726 | H35: =SUM(H29:H34) -> 12116587 | I35: =IF(H$36=0,0,H35/H$36) -> 0.5969816 | J35: =SUM(J29:J34) -> 0 | K35: =IF(J$36=0,0,J35/J$36) -> 0 | L35: =SUM(L29:L34) -> 0 | M35: =IF(L$36=0,0,L35/L$36) -> 0 | N35: =SUM(N29:N34) -> 0 | O35: =IF(N$36=0,0,N35/N$36) -> 0
A36: 16 | C36: اجمالى الاصول | D36: =D28+D35 -> 19982678 | E36: =IF(D$36=0,0,D36/D$36) -> 1 | F36: =F28+F35 -> 20182618 | G36: =IF(F$36=0,0,F36/F$36) -> 1 | H36: =H28+H35 -> 20296416 | I36: =IF(H$36=0,0,H36/H$36) -> 1 | J36: =J28+J35 -> 0 | K36: =IF(J$36=0,0,J36/J$36) -> 0 | L36: =L28+L35 -> 0 | M36: =IF(L$36=0,0,L36/L$36) -> 0 | N36: =N28+N35 -> 0 | O36: =IF(N$36=0,0,N36/N$36) -> 0
A37: 17 | C37: بنوك قصيرة الاجل | D37: 0 | E37: =IF(D$61=0,0,D37/D$61) -> 0 | F37: 0 | G37: =IF(F$61=0,0,F37/F$61) -> 0 | H37: 0 | I37: =IF(H$61=0,0,H37/H$61) -> 0 | K37: =IF(J$61=0,0,J37/J$61) -> 0 | M37: =IF(L$61=0,0,L37/L$61) -> 0 | O37: =IF(N$61=0,0,N37/N$61) -> 0
A38: 18 | B38: L | C38: موردون واوراق دفع | D38: 740304.52 | E38: =IF(D$61=0,0,D38/D$61) -> 0.037047312 | F38: 495164 | G38: =IF(F$61=0,0,F38/F$61) -> 0.024534181 | H38: 1046083 | I38: =IF(H$61=0,0,H38/H$61) -> 0.051540282 | K38: =IF(J$61=0,0,J38/J$61) -> 0 | M38: =IF(L$61=0,0,L38/L$61) -> 0 | O38: =IF(N$61=0,0,N38/N$61) -> 0
A39: 19 | B39: I | C39: مصروفات مستحقه | D39: 197405 | E39: =IF(D$61=0,0,D39/D$61) -> 0.0098788058 | F39: 365746 | G39: =IF(F$61=0,0,F39/F$61) -> 0.018121831 | H39: =89920+86730+10300 -> 186950 | I39: =IF(H$61=0,0,H39/H$61) -> 0.0092109858 | K39: =IF(J$61=0,0,J39/J$61) -> 0 | M39: =IF(L$61=0,0,L39/L$61) -> 0 | O39: =IF(N$61=0,0,N39/N$61) -> 0
A40: 20 | B40: A | C40: ارصده دائنه اخرى | D40: 0 | E40: =IF(D$61=0,0,D40/D$61) -> 0 | F40: 0 | G40: =IF(F$61=0,0,F40/F$61) -> 0 | I40: =IF(H$61=0,0,H40/H$61) -> 0 | K40: =IF(J$61=0,0,J40/J$61) -> 0 | M40: =IF(L$61=0,0,L40/L$61) -> 0 | O40: =IF(N$61=0,0,N40/N$61) -> 0
A41: 21 | B41: B | C41: دائنو توزيعات | D41: 0 | E41: =IF(D$61=0,0,D41/D$61) -> 0 | F41: 0 | G41: =IF(F$61=0,0,F41/F$61) -> 0 | H41: 0 | I41: =IF(H$61=0,0,H41/H$61) -> 0 | K41: =IF(J$61=0,0,J41/J$61) -> 0 | M41: =IF(L$61=0,0,L41/L$61) -> 0 | O41: =IF(N$61=0,0,N41/N$61) -> 0
A42: 22 | B42: I | C42: مخصصات | D42: 0 | E42: =IF(D$61=0,0,D42/D$61) -> 0 | F42: 0 | G42: =IF(F$61=0,0,F42/F$61) -> 0 | I42: =IF(H$61=0,0,H42/H$61) -> 0 | K42: =IF(J$61=0,0,J42/J$61) -> 0 | M42: =IF(L$61=0,0,L42/L$61) -> 0 | O42: =IF(N$61=0,0,N42/N$61) -> 0
A43: 23 | B43: L | C43: مستحق لشركات تابعه | D43: 0 | E43: =IF(D$61=0,0,D43/D$61) -> 0 | F43: 0 | G43: =IF(F$61=0,0,F43/F$61) -> 0 | H43: 0 | I43: =IF(H$61=0,0,H43/H$61) -> 0 | K43: =IF(J$61=0,0,J43/J$61) -> 0 | M43: =IF(L$61=0,0,L43/L$61) -> 0 | O43: =IF(N$61=0,0,N43/N$61) -> 0
A44: 24 | B44: I | C44: قسط قرض طويل الاجل | D44: 0 | E44: =IF(D$61=0,0,D44/D$61) -> 0 | F44: 0 | G44: =IF(F$61=0,0,F44/F$61) -> 0 | H44: 0 | I44: =IF(H$61=0,0,H44/H$61) -> 0 | K44: =IF(J$61=0,0,J44/J$61) -> 0 | M44: =IF(L$61=0,0,L44/L$61) -> 0 | O44: =IF(N$61=0,0,N44/N$61) -> 0
A45: 25 | B45: T | C45: اجمالى خصوم متداوله | D45: =SUM(D37:D44) -> 937709.52 | E45: =IF(D$61=0,0,D45/D$61) -> 0.046926118 | F45: =SUM(F37:F44) -> 860910 | G45: =IF(F$61=0,0,F45/F$61) -> 0.042656012 | H45: =SUM(H37:H44) -> 1233033 | I45: =IF(H$61=0,0,H45/H$61) -> 0.060751268 | J45: =SUM(J37:J44) -> 0 | K45: =IF(J$61=0,0,J45/J$61) -> 0 | L45: =SUM(L37:L44) -> 0 | M45: =IF(L$61=0,0,L45/L$61) -> 0 | N45: =SUM(N37:N44) -> 0 | O45: =IF(N$61=0,0,N45/N$61) -> 0
A46: 26 | B46: I | C46: (قرض المبادرة ) التزامات طويلة الاجل ذات امتياز | D46: 3000000 | E46: =IF(D$61=0,0,D46/D$61) -> 0.15013002 | F46: 3000000 | G46: =IF(F$61=0,0,F46/F$61) -> 0.14864276 | H46: 3000000 | I46: =IF(H$61=0,0,H46/H$61) -> 0.14780935 | K46: =IF(J$61=0,0,J46/J$61) -> 0 | L46: 0 | M46: =IF(L$61=0,0,L46/L$61) -> 0 | O46: =IF(N$61=0,0,N46/N$61) -> 0
A47: 27 | B47: E | C47: (قرض السيلارة ) التزامات اخرى طويلة الاجل | D47: 990833 | E47: =IF(D$61=0,0,D47/D$61) -> 0.049584594 | F47: 990833 | G47: =IF(F$61=0,0,F47/F$61) -> 0.049093383 | H47: 845831 | I47: =IF(H$61=0,0,H47/H$61) -> 0.041673909 | K47: =IF(J$61=0,0,J47/J$61) -> 0 | L47: 0 | M47: =IF(L$61=0,0,L47/L$61) -> 0 | O47: =IF(N$61=0,0,N47/N$61) -> 0
A48: 28 | B48: S | C48: قروض أ خالد و الحاج اسامة | D48: 0 | E48: =IF(D$61=0,0,D48/D$61) -> 0 | F48: 0 | G48: =IF(F$61=0,0,F48/F$61) -> 0 | H48: 0 | I48: =IF(H$61=0,0,H48/H$61) -> 0 | K48: =IF(J$61=0,0,J48/J$61) -> 0 | L48: 0 | M48: =IF(L$61=0,0,L48/L$61) -> 0 | O48: =IF(N$61=0,0,N48/N$61) -> 0
A49: 29 | D49: 0 | E49: =IF(D$61=0,0,D49/D$61) -> 0 | F49: 0 | G49: =IF(F$61=0,0,F49/F$61) -> 0 | H49: 0 | I49: =IF(H$61=0,0,H49/H$61) -> 0 | J49: £ | K49: =IF(J$61=0,0,J49/J$61) -> 0 | L49: 0 | M49: =IF(L$61=0,0,L49/L$61) -> 0 | O49: =IF(N$61=0,0,N49/N$61) -> 0
A50: 30 | C50: مخصص ضرائب | D50: 0 | E50: =IF(D$61=0,0,D50/D$61) -> 0 | F50: 0 | G50: =IF(F$61=0,0,F50/F$61) -> 0 | H50: 0 | I50: =IF(H$61=0,0,H50/H$61) -> 0 | J50: 0 | K50: =IF(J$61=0,0,J50/J$61) -> 0 | L50: 0 | M50: =IF(L$61=0,0,L50/L$61) -> 0 | O50: =IF(N$61=0,0,N50/N$61) -> 0
A51: 31 | C51: مخصصات اخرى | D51: 0 | E51: =IF(D$61=0,0,D51/D$61) -> 0 | F51: 0 | G51: =IF(F$61=0,0,F51/F$61) -> 0 | H51: 0 | I51: =IF(H$61=0,0,H51/H$61) -> 0 | J51: 0 | K51: =IF(J$61=0,0,J51/J$61) -> 0 | L51: 0 | M51: =IF(L$61=0,0,L51/L$61) -> 0 | O51: =IF(N$61=0,0,N51/N$61) -> 0
...

Sheet اصول متداولة اخرى 
D2: ارصدة نهاية 7 | L2: ارصدة نهاية 8 | U2: ارصدة نهاية 9 | AB2: ارصدة نهاية 12 2025.
D3: أصول متداولة أخرى 3 | L3: أصول متداولة أخرى 3 | U3: أصول متداولة أخرى 3 | X3: عهد سفريات وصيانة | AB3: أصول متداولة أخرى 3 | AE3: عهد سفريات وصيانة | AI3: ارصدة نهاية فبراير 2026
D4: سلفيات طويلة الاجل | G4: عهد سفريات وصيانة | L4: سلفيات طويلة الاجل | O4: عهد سفريات وصيانة | U4: سلفيات طويلة الاجل | X4: محمد امام | Y4: 10000 | AB4: سلفيات طويلة الاجل | AE4: مهند | AF4: 5000 | AI4: أصول متداولة أخرى 3 | AL4: عهد سفريات وصيانة
D5: مهند | E5: 2500 | G5: محمد امام | H5: 15000 | L5: مهند | M5: 0 | O5: محمد امام | P5: 0 | U5: مهند | V5: 2500 | X5: شعبان النعمانى | Y5: 12413 | AB5: مهند | AC5: 1000 | AE5: شعبان النعمانى | AF5: 16055 | AI5: سلفيات طويلة الاجل | AL5: مهند | AM5: 0
D6: أسامة الاعصر | E6: 1000 | G6: شعبان النعمانى | H6: 17400 | L6: أسامة الاعصر | M6: 500 | O6: شعبان النعمانى | P6: 21083 | X6: بنوك ونقدية قرض | Y6: 0 | AB6: هانى | AC6: 4500 | AE6: نوح | AF6: 1000 | AI6: مهند | AJ6: 500 | AL6: شعبان النعمانى | AM6: 15000
D7: شعبان | E7: 10000 | G7: بنوك ونقدية قرض | L7: شعبان | M7: 9000 | O7: بنوك ونقدية قرض | U7: أسامة الاعصر | V7: 0 | X7: ساهر | Y7: 550000 | AB7: عبد الله الاعصر | AC7: 5000 | AE7: بنوك ونقدية قرض | AF7: 0 | AI7: هانى | AJ7: 1500 | AL7: نوح | AM7: 0
D8: نوح | E8: 2000 | G8: ساهر | H8: 550000 | L8: نوح | M8: 1500 | O8: ساهر | P8: 550000 | U8: شعبان | X8: خالد | Y8: 550000 | AB8: شعبان | AC8: 5000 | AE8: ساهر | AF8: 550000 | AI8: عبد الله الاعصر | AJ8: 5000 | AL8: بنوك ونقدية قرض | AM8: 0
G9: خالد | H9: 550000 | L9: امام | M9: 10000 | O9: خالد | P9: 550000 | U9: نوح | V9: 1000 | X9: سامح | Y9: 50000 | AE9: خالد | AF9: 550000 | AI9: شعبان | AJ9: 4000 | AL9: ساهر | AM9: 550000
G10: سامح | H10: 50000 | L10: أبو جمال | M10: 12000 | O10: سامح | P10: 50000 | U10: امام | V10: 19000 | X10: رصيد بنك اهلى 1017 | Y10: 0 | AB10: امام | AC10: 19180 | AE10: سامح | AF10: 50000 | AI10: ايمن | AJ10: 5000 | AL10: خالد | AM10: 550000
D11: عهد ثابتة | G11: رصيد بنك اهلى 1017 | H11: 29500 | L11: عهد ثابتة | O11: رصيد بنك اهلى 1017 | P11: =29500+28000 -> 57500 | U11: أبو جمال | V11: 11000 | X11: رصيد مبادرة 1013 | Y11: 0 | AB11: أبو جمال | AC11: 11000 | AE11: رصيد بنك اهلى 1017 | AF11: 0 | AI11: امام | AJ11: 17180 | AL11: سامح | AM11: 50000
D12: هانى | E12: 1000 | G12: رصيد مبادرة | H12: =100000-32600 -> 67400 | L12: هانى | M12: 1000 | O12: رصيد مبادرة 1013 | P12: =100000-32600+28000-80000 -> 15400 | U12: سيد | V12: 3000 | X12: مخصص ديون معدومة | Y12: 0 | AB12: نوح | AC12: 3000 | AE12: رصيد مبادرة 1013 | AF12: 150000 | AI12: أبو جمال | AJ12: 10000 | AL12: رصيد بنك اهلى 1017 | AM12: 153865
D13: محمد السائق | E13: 1000 | G13: مخصص ديون معدومة | H13: 381000 | L13: محمد السائق | M13: 1000 | O13: مخصص ديون معدومة | P13: 381000 | U13: عهد ثابتة | X13: جارى شركاء | Y13: 381000 | AB13: سيد | AC13: 1000 | AE13: مخصص ديون معدومة | AF13: 381000 | AI13: نوح | AJ13: 4500 | AL13: رصيد مبادرة 1013 | AM13: 0
D14: مصطفى السائق | E14: 1000 | G14: جارى شركاء | L14: مصطفى السائق | M14: 1000 | O14: جارى شركاء | U14: هانى | V14: 1000 | X14: ساهر | Y14: 2274379.5 | AB14: عهد ثابتة | AE14: جارى شركاء | AF14: 0 | AI14: مصطفى النهضة | AJ14: 4000 | AL14: مخصص ديون معدومة | AM14: 0
D15: محمد طه | E15: 3000 | G15: ساهر | H15: 1994644.5 | L15: محمد طه | M15: 3000 | O15: ساهر | P15: 2126379.5 | U15: محمد السائق | V15: 1000 | X15: خالد | Y15: 2371051.5 | AB15: هانى | AC15: 1000 | AE15: ساهر | AF15: 0 | AI15: عهد ثابتة | AJ15: 0 | AL15: جارى شركاء | AM15: 0
D16: محمد بشرى | E16: 1000 | G16: خالد | H16: 2099806.5 | L16: محمد بشرى | M16: 1000 | O16: خالد | P16: 2215011.5 | U16: مصطفى السائق | V16: 1000 | AB16: سيف السائق | AC16: 1000 | AE16: خالد | AF16: 0 | AI16: هانى | AJ16: 1000 | AL16: ساهر | AM16: 2758009.5
U17: محمد طه | V17: 3000 | AB17: انور السائق | AC17: 1000 | AI17: محمد حامد | AJ17: 1000 | AL17: خالد | AM17: 2842231.5
D18: عهد فودافون كاش وانستا | L18: عهد فودافون كاش وانستا | U18: محمد بشرى | V18: 1000 | X18: مصروف مقدم | Y18: 0 | AB18: محمد طه | AC18: 0 | AI18: انور السائق | AJ18: 1000 | AM18: 0
D19: ساهر انستا | E19: 41484 | G19: مصروف مقدم | H19: 21175 | L19: ساهر انستا | M19: =-8347-10600 -> -18947 | O19: مصروف مقدم | P19: 0 | X19: مصروف مستحق | AB19: محمد بشرى | AC19: 1000 | AE19: مصروف مقدم | AF19: 0 | AJ19: 0 | AM19: 0
D20: ساهر فودافون كاش | E20: 31197 | G20: مصروف مستحق | L20: ساهر فودافون كاش | M20: 109399 | O20: مصروف مستحق | U20: عهد فودافون كاش وانستا | X20: مرتبات | Y20: 0 | AE20: مصروف مستحق | AI20: محمد بشرى | AJ20: 1000 | AL20: مصروف مقدم | AM20: 0
D21: محمد طه فودافون كاش | E21: 63702 | G21: مرتبات | H21: =77095.3333333333+300 -> 77395.333 | L21: محمد طه فودافون كاش | M21: 33316 | O21: مرتبات | P21: 0 | U21: ساهر انستا | V21: -34328 | X21: عمالة خارجية | Y21: 0 | AB21: عهد فودافون كاش وانستا | AE21: مرتبات | AF21: 0 | AL21: مصروف مستحق | AM21: 0
D22: أ هيثم فودافون كاش | E22: 19330 | G22: عمالة خارجية | H22: 59010 | L22: أ هيثم فودافون كاش | M22: 12330 | O22: عمالة خارجية | P22: 0 | U22: ساهر فودافون كاش | V22: 176069 | X22: عمولة البيع | Y22: 0 | AB22: ساهر انستا | AC22: 6592 | AE22: عمالة خارجية | AF22: 0 | AI22: عهد فودافون كاش وانستا | AL22: مرتبات
G23: عمولة البيع | H23: 44000 | O23: عمولة البيع | P23: 0 | U23: محمد طه فودافون كاش | V23: 124460 | X23: ايجار عربية 1842 | Y23: 12000 | AB23: ساهر فودافون كاش | AC23: 414091 | AE23: عمولة البيع | AF23: 0 | AI23: ساهر انستا | AJ23: -121002 | AL23: عمالة خارجية | AM23: 54950
G24: ايجار عربية 1842 | H24: 12000 | O24: ايجار عربية 1842 | P24: 12000 | U24: أ هيثم فودافون كاش | V24: 0 | X24: بدل ايجار عربية هيثم | Y24: 0 | AB24: مهند. فودافون كاش | AC24: 42405 | AI24: ساهر فودافون كاش | AJ24: 173558 | AL24: عمولة البيع | AM24: 0
G25: بدل ايجار عربية هيثم | H25: 5000 | O25: بدل ايجار عربية هيثم | P25: 5000 | AB25: أ خالد نقدى | AC25: 100155 | AE25: غفرة رمضان | AF25: 1650 | AI25: مهند. فودافون كاش | AJ25: 125 | AM25: 0
AE26: مكتب المحاسبة | AF26: 6000 | AI26: أ خالد نقدى | AJ26: 0 | AL26: غفرة رمضان | AM26: 2000
AJ27: =SUM(AJ5:AJ26) -> 108361 | AL27: مكتب المحاسبة | AM27: 10000
AL28: تاكى للتوابل | AM28: 13302
AI30: تعديل .حساب العملاء | AM30: 0
AI31: باقى العملاء
AI32: قروض
AI33: المبادرة | AJ33: 3000000
AI34: السياؤة | AJ34: 797497
AI35: قروض قصيرة
AI36: أ خالد | AJ36: 1024190
AI37: الحاج اسامة | AJ37: 220000
F61: مدين
F62: مدين
F67: نصف ايجار مصنع شهر 8

Sheet I.S.
C1: ='B.S.'!C1 -> hanno pop | F1: LOCATION: | H1: ='B.S.'!H1 -> IMC | J1: C. ANALYST: | L1: ='B.S.'!L1 -> ME | M1: ='B.S.'!R1 -> 0 | N1: ='B.S.'!S1 -> 0 | O1: ='B.S.'!T1 -> 0
A2: Auditor: | C2: ='B.S.'!C2 | F2: AMOUNTS IN: | H2: ='B.S.'!H2 -> EGP | J2: D A T E : | L2: ='B.S.'!L2 -> 12/2025
A3: Audited or Direct (Specify) | D3: ='B.S.'!D3 -> Audited | F3: ='B.S.'!F3 -> Audited | H3: ='B.S.'!H3 -> Audited | J3: Audited
A4: Unqualified or Qualified (Specify) | D4: ='B.S.'!D4 -> Unqualified | F4: ='B.S.'!F4 -> Unqualifed | H4: ='B.S.'!H4 -> Unqualified | J4: Unqualified
A5: FREQUENCY/CYCLE
A6: 231 | D6: ='B.S.'!D6 -> 31/7/2025 | F6: ='B.S.'!F6 -> 31/8/2025 | H6: ='B.S.'!H6 -> 31/12/2025
A7: NO. OF MONTHS | D7: 1 | F7: 1 | H7: 1
A8: D E S C R I P T I O N | D8: AMOUNT | E8: % | F8: AMOUNT | G8: % | H8: AMOUNT | I8: % | J8: AMOUNT | K8: % | L8: AMOUNT | M8: % | N8: AMOUNT | O8: %
A9: INCOME STATEMENT
A10: 43 | C10: صافى المبيعات | D10: 2536929 | E10: =IF(D$10=0,0,D10/D$10) -> 1 | F10: 3005991 | G10: =IF(F$10=0,0,F10/F$10) -> 1 | H10: 3170826 | I10: =IF(H$10=0,0,H10/H$10) -> 1 | K10: =IF(J$10=0,0,J10/J$10) -> 0 | M10: =IF(L$10=0,0,L10/L$10) -> 0 | O10: =IF(N$10=0,0,N10/N$10) -> 0
A11: 44 | C11: تكلفة المبيعات | D11: 1289237 | E11: =IF(D$10=0,0,D11/D$10) -> 0.50818805 | F11: 1745079 | G11: =IF(F$10=0,0,F11/F$10) -> 0.58053367 | H11: 1795859 | I11: =IF(H$10=0,0,H11/H$10) -> 0.56636946 | K11: =IF(J$10=0,0,J11/J$10) -> 0 | M11: =IF(L$10=0,0,L11/L$10) -> 0 | O11: =IF(N$10=0,0,N11/N$10) -> 0
A12: 45 | C12: مصاريف اداريه وعموميه | D12: 388487 | E12: =IF(D$10=0,0,D12/D$10) -> 0.15313278 | F12: 413078 | G12: =IF(F$10=0,0,F12/F$10) -> 0.13741824 | H12: 533003 | I12: =IF(H$10=0,0,H12/H$10) -> 0.16809595 | K12: =IF(J$10=0,0,J12/J$10) -> 0 | M12: =IF(L$10=0,0,L12/L$10) -> 0 | O12: =IF(N$10=0,0,N12/N$10) -> 0
A13: 46 | C13: ارباح التشغيل | D13: =D10-D11-D12 -> 859205 | E13: =IF(D$10=0,0,D13/D$10) -> 0.33867917 | F13: =F10-F11-F12 -> 847834 | G13: =IF(F$10=0,0,F13/F$10) -> 0.28204808 | H13: =H10-H11-H12 -> 841964 | I13: =IF(H$10=0,0,H13/H$10) -> 0.2655346 | J13: =J10-J11-J12 -> 0 | K13: =IF(J$10=0,0,J13/J$10) -> 0 | L13: =L10-L11-L12 -> 0 | M13: =IF(L$10=0,0,L13/L$10) -> 0 | N13: =N10-N11-N12 -> 0 | O13: =IF(N$10=0,0,N13/N$10) -> 0
A14: 47 | C14: الاهلاك | D14: 0 | E14: =IF(D$10=0,0,D14/D$10) -> 0 | F14: 0 | G14: =IF(F$10=0,0,F14/F$10) -> 0 | H14: 1346288 | I14: =IF(H$10=0,0,H14/H$10) -> 0.4245859 | K14: =IF(J$10=0,0,J14/J$10) -> 0 | L14: 0 | M14: =IF(L$10=0,0,L14/L$10) -> 0 | O14: =IF(N$10=0,0,N14/N$10) -> 0
A15: 48 | C15: مصاريف أخري غير نقدية | D15: 0 | E15: =IF(D$10=0,0,D15/D$10) -> 0 | F15: 0 | G15: =IF(F$10=0,0,F15/F$10) -> 0 | H15: 0 | I15: =IF(H$10=0,0,H15/H$10) -> 0 | K15: =IF(J$10=0,0,J15/J$10) -> 0 | L15: 0 | M15: =IF(L$10=0,0,L15/L$10) -> 0 | O15: =IF(N$10=0,0,N15/N$10) -> 0
A16: 49 | C16: مخصصات انتفى الغرض منها | D16: 0 | E16: =IF(D$10=0,0,D16/D$10) -> 0 | F16: 0 | G16: =IF(F$10=0,0,F16/F$10) -> 0 | H16: 0 | I16: =IF(H$10=0,0,H16/H$10) -> 0 | K16: =IF(J$10=0,0,J16/J$10) -> 0 | L16: 0 | M16: =IF(L$10=0,0,L16/L$10) -> 0 | O16: =IF(N$10=0,0,N16/N$10) -> 0
A17: 50 | C17: فوائد محصله | D17: 0 | E17: =IF(D$10=0,0,D17/D$10) -> 0 | F17: 0 | G17: =IF(F$10=0,0,F17/F$10) -> 0 | H17: 0 | I17: =IF(H$10=0,0,H17/H$10) -> 0 | K17: =IF(J$10=0,0,J17/J$10) -> 0 | M17: =IF(L$10=0,0,L17/L$10) -> 0 | O17: =IF(N$10=0,0,N17/N$10) -> 0
A18: 51 | C18: ارباح او خسائر استثمارات | D18: 0 | E18: =IF(D$10=0,0,D18/D$10) -> 0 | F18: 0 | G18: =IF(F$10=0,0,F18/F$10) -> 0 | H18: 0 | I18: =IF(H$10=0,0,H18/H$10) -> 0 | K18: =IF(J$10=0,0,J18/J$10) -> 0 | M18: =IF(L$10=0,0,L18/L$10) -> 0 | O18: =IF(N$10=0,0,N18/N$10) -> 0
A19: 52 | C19: مصروفات اخرى | D19: 259384 | F19: 324112 | G19: =IF(F$10=0,0,F19/F$10) -> 0.10782201 | H19: 278826 | I19: =IF(H$10=0,0,H19/H$10) -> 0.087934816 | K19: =IF(J$10=0,0,J19/J$10) -> 0 | M19: =IF(L$10=0,0,L19/L$10) -> 0 | O19: =IF(N$10=0,0,N19/N$10) -> 0
A20: 53 | C20: ايرادات اخرى | D20: 0 | E20: =IF(D$10=0,0,D20/D$10) -> 0 | F20: 0 | G20: =IF(F$10=0,0,F20/F$10) -> 0 | H20: 0 | I20: =IF(H$10=0,0,H20/H$10) -> 0 | K20: =IF(J$10=0,0,J20/J$10) -> 0 | M20: =IF(L$10=0,0,L20/L$10) -> 0 | O20: =IF(N$10=0,0,N20/N$10) -> 0
A21: 54 | C21: ارباح او خسائر فروق عمله | D21: 0 | E21: =IF(D$10=0,0,D21/D$10) -> 0 | F21: 0 | G21: =IF(F$10=0,0,F21/F$10) -> 0 | H21: 70512 | I21: =IF(H$10=0,0,H21/H$10) -> 0.022237739 | K21: =IF(J$10=0,0,J21/J$10) -> 0 | M21: =IF(L$10=0,0,L21/L$10) -> 0 | O21: =IF(N$10=0,0,N21/N$10) -> 0
A22: 55 | C22: مخصصات | D22: 0 | E22: =IF(D$10=0,0,D22/D$10) -> 0 | F22: 0 | G22: =IF(F$10=0,0,F22/F$10) -> 0 | H22: 0 | I22: =IF(H$10=0,0,H22/H$10) -> 0 | K22: =IF(J$10=0,0,J22/J$10) -> 0 | M22: =IF(L$10=0,0,L22/L$10) -> 0 | O22: =IF(N$10=0,0,N22/N$10) -> 0
A23: 56 | C23: الارباح قبل الضرائب ومصاريف التمويل | D23: =D13-D14-D15-D16+D17+D18-D19+D20-D21-D22 -> 599821 | E23: =IF(D$10=0,0,D23/D$10) -> 0.23643586 | F23: =F13-F14-F15-F16+F17+F18-F19+F20-F21-F22 -> 523722 | G23: =IF(F$10=0,0,F23/F$10) -> 0.17422607 | H23: =H13-H14-H15-H16+H17+H18-H19+H20-H21-H22 -> -853662 | I23: =IF(H$10=0,0,H23/H$10) -> -0.26922386 | J23: =J13-J14-J15-J16+J17+J18-J19+J20-J21-J22 -> 0 | K23: =IF(J$10=0,0,J23/J$10) -> 0 | L23: =L13-L14-L15-L16+L17+L18-L19+L20-L21-L22 -> 0 | M23: =IF(L$10=0,0,L23/L$10) -> 0 | N23: =N13-N14-N15-N16+N17+N18-N19+N20-N21-N22 -> 0 | O23: =IF(N$10=0,0,N23/N$10) -> 0
A24: 57 | C24: مصروفات تمويليه | D24: 126120 | E24: =IF(D$10=0,0,D24/D$10) -> 0.04971365 | F24: 0 | G24: =IF(F$10=0,0,F24/F$10) -> 0 | H24: 0 | I24: =IF(H$10=0,0,H24/H$10) -> 0 | K24: =IF(J$10=0,0,J24/J$10) -> 0 | M24: =IF(L$10=0,0,L24/L$10) -> 0 | O24: =IF(N$10=0,0,N24/N$10) -> 0
A25: 58 | C25: الربح قبل الضرائب | D25: =D23-D24 -> 473701 | E25: =IF(D$10=0,0,D25/D$10) -> 0.18672221 | F25: =F23-F24 -> 523722 | G25: =IF(F$10=0,0,F25/F$10) -> 0.17422607 | H25: =H23-H24 -> -853662 | I25: =IF(H$10=0,0,H25/H$10) -> -0.26922386 | J25: =J23-J24 -> 0 | K25: =IF(J$10=0,0,J25/J$10) -> 0 | L25: =L23-L24 -> 0 | M25: =IF(L$10=0,0,L25/L$10) -> 0 | N25: =N23-N24 -> 0 | O25: =IF(N$10=0,0,N25/N$10) -> 0
A26: 59 | C26: مخصص الضرائب | D26: 0 | E26: =IF(D$10=0,0,D26/D$10) -> 0 | F26: 0 | G26: =IF(F$10=0,0,F26/F$10) -> 0 | H26: 0 | I26: =IF(H$10=0,0,H26/H$10) -> 0 | K26: =IF(J$10=0,0,J26/J$10) -> 0 | L26: 0 | M26: =IF(L$10=0,0,L26/L$10) -> 0 | O26: =IF(N$10=0,0,N26/N$10) -> 0
A27: 60 | C27: ارباح او خسائر غير عاديه (+) | D27: 0 | E27: =IF(D$10=0,0,D27/D$10) -> 0 | F27: 0 | G27: =IF(F$10=0,0,F27/F$10) -> 0 | H27: 0 | I27: =IF(H$10=0,0,H27/H$10) -> 0 | J27: 0 | K27: =IF(J$10=0,0,J27/J$10) -> 0 | L27: 0 | M27: =IF(L$10=0,0,L27/L$10) -> 0 | O27: =IF(N$10=0,0,N27/N$10) -> 0
A28: 61 | C28: صافى الربح | D28: =D25-D26+D27 -> 473701 | E28: =IF(D$10=0,0,D28/D$10) -> 0.18672221 | F28: =F25-F26+F27 -> 523722 | G28: =IF(F$10=0,0,F28/F$10) -> 0.17422607 | H28: =H25-H26+H27 -> -853662 | I28: =IF(H$10=0,0,H28/H$10) -> -0.26922386 | J28: =J25-J26+J27 -> 0 | K28: =IF(J$10=0,0,J28/J$10) -> 0 | L28: =L25-L26+L27 -> 0 | M28: =IF(L$10=0,0,L28/L$10) -> 0 | N28: =N25-N26+N27 -> 0 | O28: =IF(N$10=0,0,N28/N$10) -> 0
A30: BALANCE SHEET RECONCILIATION
D32: NET WORTH
A33: 61 | C33: صافى حقوق الملكيه اول المده | F33: ='B.S.'!D60 -> 15054136 | H33: ='B.S.'!F60 -> 15330875 | J33: ='B.S.'!H60 -> 15217552 | L33: ='B.S.'!J60 -> 0 | N33: ='B.S.'!L60 -> 0
C34: يضاف اليه (+)
A35: 62 | C35: صافى الدخل | D35: =D28 -> 473701 | F35: =F28 -> 523722 | H35: =H28 -> -853662 | J35: =J28 -> 0 | L35: =L28 -> 0 | N35: =N28 -> 0
A36: 63 | C36: فروق اعادة تقييم استثمارات | D36: 0 | F36: 0 | H36: 0 | J36: 0 | L36: 0 | N36: 0
A37: 64 | C37: الزياده فى راس المال | D37: =IF((D33+D35+D36+D38-D41-D43)<D46,D46-(D33+D35+D36+D38-D41-D43),0) -> 14580435 | F37: =IF((F33+F35+F36+F38-F41-F43)<F46,F46-(F33+F35+F36+F38-F41-F43),0) -> 0 | H37: =IF((H33+H35+H36+H38-H41-H43)<H46,H46-(H33+H35+H36+H38-H41-H43),0) -> 740339 | J37: =IF((J33+J35+J36+J38-J41-J43)<J46,J46-(J33+J35+J36+J38-J41-J43),0) -> 0 | L37: =IF((L33+L35+L36+L38-L41-L43)<L46,L46-(L33+L35+L36+L38-L41-L43),0) -> 0 | N37: =IF((N33+N35+N36+N38-N41-N43)<N46,N46-(N33+N35+N36+N38-N41-N43),0) -> 0
A38: 65 | C38: اضافات اخرى | D38: 0 | F38: 0 | H38: 0 | J38: 0 | L38: 0 | N38: 0
A39: 66 | C39: اجمالى الزياده | D39: =D35+D36+D37+D38 -> 15054136 | F39: =F35+F36+F37+F38 -> 523722 | H39: =H35+H36+H37+H38 -> -113323 | J39: =J35+J36+J37+J38 -> 0 | L39: =L35+L36+L37+L38 -> 0 | N39: =N35+N36+N37+N38 -> 0
C40: يخصم منه(-)
A41: 67 | C41: توزيعات | D41: 0 | F41: 0 | H41: 0 | J41: 0 | N41: 0
A42: 68 | C42: مسحوبات | D42: =IF((D33+D35+D36+D38-D41-D43)>D46,(D33+D35+D36+D38-D41-D43)-D46,0) -> 0 | F42: =IF((F33+F35+F36+F38-F41-F43)>F46,(F33+F35+F36+F38-F41-F43)-F46,0) -> 246983 | H42: =IF((H33+H35+H36+H38-H41-H43)>H46,(H33+H35+H36+H38-H41-H43)-H46,0) -> 0 | J42: =IF((J33+J35+J36+J38-J41-J43)>J46,(J33+J35+J36+J38-J41-J43)-J46,0) -> 15217552 | L42: =IF((L33+L35+L36+L38-L41-L43)>L46,(L33+L35+L36+L38-L41-L43)-L46,0) -> 0 | N42: =IF((N33+N35+N36+N38-N41-N43)>N46,(N33+N35+N36+N38-N41-N43)-N46,0) -> 0
...

Sheet OPS & NON-OPS
A1: NAME: | C1: hanno pop | E1: LOCATION: | F1: ='B.S.'!H1 -> IMC | G1: C. ANALYST: | H1: ='B.S.'!L1 -> ME
A2: Auditor: | C2: ='B.S.'!C2 | E2: AMOUNTS IN: | F2: ='B.S.'!H2 -> EGP | G2: D A T E : | H2: ='B.S.'!L2 -> 12/2025
A3: Audited or Direct (Specify) | D3: ='B.S.'!D3 -> Audited | E3: ='B.S.'!F3 -> Audited | F3: ='B.S.'!H3 -> Audited | G3: Audited
A4: Unqualified or Qualified (Specify) | D4: ='B.S.'!D4 -> Unqualified | E4: ='B.S.'!F4 -> Unqualifed | F4: ='B.S.'!H4 -> Unqualified | G4: Unqualified
A5: FREQUENCY/CYCLE
A6: DATE (Day, Month, Year) | D6: ='B.S.'!D6 -> 31/7/2025 | E6: ='B.S.'!F6 -> 31/8/2025 | F6: ='B.S.'!H6 -> 31/12/2025 | G6: 28/2/2026 | H6: ='B.S.'!L6 -> 0
A7: D E S C R I P T I O N | D7: AMOUNT | E7: AMOUNT | F7: AMOUNT | G7: AMOUNT | H7: AMOUNT | I7: AMOUNT
A8: OPERATING / NON-OPERATING (CASH GENERATION STATEMENT)
A9: 91 | C9: صافى الدخل | E9: ='I.S.'!F28 -> 523722 | F9: ='I.S.'!H28 -> -853662 | G9: ='I.S.'!J28 -> 0 | H9: ='I.S.'!L28 -> 0 | I9: ='I.S.'!N28 -> 0
A10: 92 | B10: N | C10: الاهلاك | E10: ='I.S.'!F14 -> 0 | F10: ='I.S.'!H14 -> 1346288 | G10: ='I.S.'!J14 -> 0 | H10: ='I.S.'!L14 -> 0 | I10: ='I.S.'!N14 -> 0
A11: 93 | B11: E | C11: مصاريف غير نقديه | E11: ='I.S.'!F15+'I.S.'!F16 -> 0 | F11: ='I.S.'!H15+'I.S.'!H16 -> 0 | G11: ='I.S.'!J15+'I.S.'!J16 -> 0 | H11: ='I.S.'!L15+'I.S.'!L16 -> 0 | I11: ='I.S.'!N15+'I.S.'!N16 -> 0
A12: 94 | B12: T | C12: اجمالى النقديه المتولده من انشطة التشغيل | E12: =E9+E10+E11 -> 523722 | F12: =F9+F10+F11 -> 492626 | G12: =G9+G10+G11 -> 0 | H12: =H9+H10+H11 -> 0 | I12: =I9+I10+I11 -> 0
C13: مقدار الزياده او النقص
B14: O | C14: استخدامات النقديه من الانشطه التشغيليه
A15: 95 | B15: P | C15: ='B.S.'!C23 -> اوراق القبض+ رصيد العملاء | E15: ='B.S.'!F23-'B.S.'!D23 -> 249809.25 | F15: ='B.S.'!H23-'B.S.'!F23 -> 182766.75 | G15: ='B.S.'!J23-'B.S.'!H23 -> -2389644 | H15: ='B.S.'!L23-'B.S.'!J23 -> 0 | I15: ='B.S.'!N23-'B.S.'!L23 -> 0
A16: 96 | B16: E | C16: ='B.S.'!C24 -> المخزون | E16: ='B.S.'!F24-'B.S.'!D24 -> -39800.187 | F16: ='B.S.'!H24-'B.S.'!F24 -> 253050.32 | G16: ='B.S.'!J24-'B.S.'!H24 -> -2951082.1 | H16: ='B.S.'!L24-'B.S.'!J24 -> 0 | I16: ='B.S.'!N24-'B.S.'!L24 -> 0
A17: 97 | B17: R | C17: مدفوعات مقدمه للموردين | E17: ='B.S.'!F25-'B.S.'!D25 -> -21175 | F17: ='B.S.'!H25-'B.S.'!F25 -> 0 | G17: ='B.S.'!J25-'B.S.'!H25 -> 0 | H17: ='B.S.'!L25-'B.S.'!J25 -> 0 | I17: ='B.S.'!N25-'B.S.'!L25 -> 0
A18: 98 | B18: A | C18: ='B.S.'!C26 -> اصول متداوله اخرى | E18: ='B.S.'!F26-'B.S.'!D26 -> -37432 | F18: ='B.S.'!H26-'B.S.'!F26 -> 518897 | G18: ='B.S.'!J26-'B.S.'!H26 -> -1169978 | H18: ='B.S.'!L26-'B.S.'!J26 -> 0 | I18: ='B.S.'!N26-'B.S.'!L26 -> 0
A19: 99 | B19: T | C19: ='B.S.'!C27 -> جاري شركات تابعة | E19: ='B.S.'!F27-'B.S.'!D27 -> 0 | F19: ='B.S.'!H27-'B.S.'!F27 -> 0 | G19: ='B.S.'!J27-'B.S.'!H27 -> 0 | H19: ='B.S.'!L27-'B.S.'!J27 -> 0 | I19: ='B.S.'!N27-'B.S.'!L27 -> 0
A20: 100 | B20: I | C20: اجمالى الاحتياجات التشغيليه | E20: =SUM(E15:E19) -> 151402.06 | F20: =SUM(F15:F19) -> 954714.08 | G20: =SUM(G15:G19) -> -6510704.1 | H20: =SUM(H15:H19) -> 0 | I20: =SUM(I15:I19) -> 0
B21: N | C21: مقدار الزياده او النقص
B22: G | C22: مصادر النقديه المتولده من الانشطه التشغيليه
A23: 101 | C23: ='B.S.'!C38 -> موردون واوراق دفع | E23: ='B.S.'!F38-'B.S.'!D38 -> -245140.52 | F23: ='B.S.'!H38-'B.S.'!F38 -> 550919 | G23: ='B.S.'!J38-'B.S.'!H38 -> -1046083 | H23: ='B.S.'!L38-'B.S.'!J38 -> 0 | I23: ='B.S.'!N38-'B.S.'!L38 -> 0
A24: 102 | B24: C | C24: ='B.S.'!C39 -> مصروفات مستحقه | E24: ='B.S.'!F39-'B.S.'!D39 -> 168341 | F24: ='B.S.'!H39-'B.S.'!F39 -> -178796 | G24: ='B.S.'!J39-'B.S.'!H39 -> -186950 | H24: ='B.S.'!L39-'B.S.'!J39 -> 0 | I24: ='B.S.'!N39-'B.S.'!L39 -> 0
A25: 103 | B25: A | C25: ='B.S.'!C40 -> ارصده دائنه اخرى | E25: ='B.S.'!F40-'B.S.'!D40 -> 0 | F25: ='B.S.'!H40-'B.S.'!F40 -> 0 | G25: ='B.S.'!J40-'B.S.'!H40 -> 0 | H25: ='B.S.'!L40-'B.S.'!J40 -> 0 | I25: ='B.S.'!N40-'B.S.'!L40 -> 0
A26: 104 | B26: S | C26: ='B.S.'!C41 -> دائنو توزيعات | E26: ='B.S.'!F41-'B.S.'!D41 -> 0 | F26: ='B.S.'!H41-'B.S.'!F41 -> 0 | G26: ='B.S.'!J41-'B.S.'!H41 -> 0 | H26: ='B.S.'!L41-'B.S.'!J41 -> 0 | I26: ='B.S.'!N41-'B.S.'!L41 -> 0
A27: 105 | B27: H | C27: ='B.S.'!C42 -> مخصصات | E27: ='B.S.'!F42-'B.S.'!D42 -> 0 | F27: ='B.S.'!H42-'B.S.'!F42 -> 0 | G27: ='B.S.'!J42-'B.S.'!H42 -> 0 | H27: ='B.S.'!L42-'B.S.'!J42 -> 0 | I27: ='B.S.'!N42-'B.S.'!L42 -> 0
A28: 106 | C28: ='B.S.'!C43 -> مستحق لشركات تابعه | E28: ='B.S.'!F43-'B.S.'!D43 -> 0 | F28: ='B.S.'!H43-'B.S.'!F43 -> 0 | G28: ='B.S.'!J43-'B.S.'!H43 -> 0 | H28: ='B.S.'!L43-'B.S.'!J43 -> 0 | I28: ='B.S.'!N43-'B.S.'!L43 -> 0
A29: 107 | C29: اجمالى مصادر التشغيل | E29: =SUM(E23:E28) -> -76799.525 | F29: =SUM(F23:F28) -> 372123 | G29: =SUM(G23:G28) -> -1233033 | H29: =SUM(H23:H28) -> 0 | I29: =SUM(I23:I28) -> 0
A31: 108 | C31: صافى النقديه من الانشطه التشغيليه | E31: =E12-E20+E29 -> 295520.42 | F31: =F12-F20+F29 -> -89965.076 | G31: =G12-G20+G29 -> 5277671.1 | H31: =H12-H20+H29 -> 0 | I31: =I12-I20+I29 -> 0
C33: مقدار الزياده او النقص
C34: استخدامات غير تشغيليه
A35: 109 | B35: N | C35: ='I.S.'!C60 -> اجمالى المصروفات الراسماليه | E35: ='I.S.'!F60 -> 3500 | F35: ='I.S.'!H60 -> 147650 | G35: ='I.S.'!J60 -> -12116587 | H35: ='I.S.'!L60 -> 0 | I35: ='I.S.'!N60 -> 0
A36: 110 | B36: O | C36: توزيعات | E36: ='I.S.'!F41 -> 0 | F36: ='I.S.'!H41 -> 0 | G36: ='I.S.'!J41 -> 0 | H36: ='I.S.'!L41 -> 0 | I36: ='I.S.'!N41 -> 0
A37: 111 | B37: N | C37: النقص فى الالتزامات طويلة الاجل | E37: =-IF(('B.S.'!F44+'B.S.'!F46+'B.S.'!F47+'B.S.'!F48)<('B.S.'!D44+'B.S.'!D46+'B.S.'!D47+'B.S.'!D48),('B.S.'!F44+'B.S.'!F46+'B.S.'!F47+'B.S.'!F48)-('B.S.'!D44+'B.S.'!D46+'B.S.'!D47+'B.S.'!D48),0) -> 0 | F37: =-IF(('B.S.'!H44+'B.S.'!H46+'B.S.'!H47+'B.S.'!H48)<('B.S.'!F44+'B.S.'!F46+'B.S.'!F47+'B.S.'!F48),('B.S.'!H44+'B.S.'!H46+'B.S.'!H47+'B.S.'!H48)-('B.S.'!F44+'B.S.'!F46+'B.S.'!F47+'B.S.'!F48),0) -> 145002 | G37: =-IF(('B.S.'!J44+'B.S.'!J46+'B.S.'!J47+'B.S.'!J48)<('B.S.'!H44+'B.S.'!H46+'B.S.'!H47+'B.S.'!H48),('B.S.'!J44+'B.S.'!J46+'B.S.'!J47+'B.S.'!J48)-('B.S.'!H44+'B.S.'!H46+'B.S.'!H47+'B.S.'!H48),0) -> 3845831 | H37: =-IF(('B.S.'!L44+'B.S.'!L46+'B.S.'!L47+'B.S.'!L48)<('B.S.'!J44+'B.S.'!J46+'B.S.'!J47+'B.S.'!J48),('B.S.'!L44+'B.S.'!L46+'B.S.'!L47+'B.S.'!L48)-('B.S.'!J44+'B.S.'!J46+'B.S.'!J47+'B.S.'!J48),0) -> 0 | I37: =-IF(('B.S.'!N44+'B.S.'!N46+'B.S.'!N47+'B.S.'!N48)<('B.S.'!L44+'B.S.'!L46+'B.S.'!L47+'B.S.'!L48),('B.S.'!N44+'B.S.'!N46+'B.S.'!N47+'B.S.'!N48)-('B.S.'!L44+'B.S.'!L46+'B.S.'!L47+'B.S.'!L48),0) -> 0
A38: 112 | C38: النقص فى الالتزامات قصيرة الاجل | E38: =-IF('B.S.'!F37<'B.S.'!D37,'B.S.'!F37-'B.S.'!D37,0) -> 0 | F38: =-IF('B.S.'!H37<'B.S.'!F37,'B.S.'!H37-'B.S.'!F37,0) -> 0 | G38: =-IF('B.S.'!J37<'B.S.'!H37,'B.S.'!J37-'B.S.'!H37,0) -> 0 | H38: =-IF('B.S.'!L37<'B.S.'!J37,'B.S.'!L37-'B.S.'!J37,0) -> 0 | I38: =-IF('B.S.'!N37<'B.S.'!L37,'B.S.'!N37-'B.S.'!L37,0) -> 0
A39: 113 | B39: O | C39: النقص فى صافى حقوق الملكيه | E39: ='I.S.'!F42+'I.S.'!F43 -> 246983 | F39: ='I.S.'!H42+'I.S.'!H43 -> 0 | G39: ='I.S.'!J42+'I.S.'!J43 -> 15217552 | H39: ='I.S.'!L42+'I.S.'!L43 -> 0 | I39: ='I.S.'!N42+'I.S.'!N43 -> 0
A40: 114 | B40: P | C40: ='B.S.'!C30 -> استثمارات في شركات تابعة | E40: ='B.S.'!F30-'B.S.'!D30 -> 0 | F40: ='B.S.'!H30-'B.S.'!F30 -> 0 | G40: ='B.S.'!J30-'B.S.'!H30 -> 0 | H40: ='B.S.'!L30-'B.S.'!J30 -> 0 | I40: ='B.S.'!N30-'B.S.'!L30 -> 0
A41: 115 | B41: E | C41: ='B.S.'!C31 -> استثمارات طويلة الأجل | E41: ='B.S.'!F31-'B.S.'!D31 -> 0 | F41: ='B.S.'!H31-'B.S.'!F31 -> 0 | G41: ='B.S.'!J31-'B.S.'!H31 -> 0 | H41: ='B.S.'!L31-'B.S.'!J31 -> 0 | I41: ='B.S.'!N31-'B.S.'!L31 -> 0
A42: 116 | B42: R | C42: ='B.S.'!C32 -> جاري مصلحة الضرائب | E42: ='B.S.'!F32-'B.S.'!D32 -> 0 | F42: ='B.S.'!H32-'B.S.'!F32 -> 0 | G42: ='B.S.'!J32-'B.S.'!H32 -> 0 | H42: ='B.S.'!L32-'B.S.'!J32 -> 0 | I42: ='B.S.'!N32-'B.S.'!L32 -> 0
...

Sheet CASH FLOW
A1: NAME: | B1: ='I.S.'!C1 -> hanno pop | D1: LOCATION: | E1: ='B.S.'!H1 -> IMC | F1: C. ANALYST: | G1: ='B.S.'!L1 -> ME
A2: Auditor: | B2: ='I.S.'!C2 | D2: AMOUNTS IN: | E2: ='B.S.'!H2 -> EGP | F2: D A T E : | G2: ='B.S.'!L2 -> 12/2025
A3: Audited or Direct (Specify) | C3: ='B.S.'!D3 -> Audited | D3: ='B.S.'!F3 -> Audited | E3: ='B.S.'!H3 -> Audited | F3: Audited | G3: Audited
A4: Unqualified or Qualified (Specify) | C4: ='B.S.'!D4 -> Unqualified | D4: ='B.S.'!F4 -> Unqualifed | E4: ='B.S.'!H4 -> Unqualified | F4: Unqualified
A5: FREQUENCY/CYCLE
A6: DATE (Day, Month, Year) | C6: 31/12/2025 | D6: 31/12/2025 | E6: 31/12/2025 | F6: 30/09/2028 | G6: ='B.S.'!L6 -> 0
A7: D E S C R I P T I O N | C7: AMOUNT | D7: AMOUNT | E7: AMOUNT | F7: AMOUNT | G7: AMOUNT | H7: AMOUNT
A8: CONSOLIDATED STATEMENT OF CASH FLOWS
A9: OPERATING ACTIVITIES
A10: 91 | B10: صافى الدخل | D10: ='I.S.'!F28 -> 523722 | E10: ='I.S.'!H28 -> -853662 | F10: ='I.S.'!J28 -> 0 | G10: ='I.S.'!L28 -> 0 | H10: ='I.S.'!N28 -> 0
A11: 92 | B11: الاهلاك | D11: ='I.S.'!F14 -> 0 | E11: ='I.S.'!H14 -> 1346288 | F11: ='I.S.'!J14 -> 0 | G11: ='I.S.'!L14 -> 0 | H11: ='I.S.'!N14 -> 0
A12: 93 | B12: مصاريف غير نقديه | D12: ='I.S.'!F15+'I.S.'!F16 -> 0 | E12: ='I.S.'!H15+'I.S.'!H16 -> 0 | F12: ='I.S.'!J15+'I.S.'!J16 -> 0 | G12: ='I.S.'!L15+'I.S.'!L16 -> 0 | H12: ='I.S.'!N15+'I.S.'!N16 -> 0
B14: التغيرات فى عمليات
B15: الاصول والخصوم
A16: 94 | B16: ='B.S.'!C23 -> اوراق القبض+ رصيد العملاء | D16: =-('B.S.'!F23-'B.S.'!D23) -> -249809.25 | E16: =-('B.S.'!H23-'B.S.'!F23) -> -182766.75 | F16: =-('B.S.'!J23-'B.S.'!H23) -> 2389644 | G16: =-('B.S.'!L23-'B.S.'!J23) -> 0 | H16: =-('B.S.'!N23-'B.S.'!L23) -> 0
A17: 95 | B17: ='B.S.'!C24 -> المخزون | D17: =-('B.S.'!F24-'B.S.'!D24) -> 39800.187 | E17: =-('B.S.'!H24-'B.S.'!F24) -> -253050.32 | F17: =-('B.S.'!J24-'B.S.'!H24) -> 2951082.1 | G17: =-('B.S.'!L24-'B.S.'!J24) -> 0 | H17: =-('B.S.'!N24-'B.S.'!L24) -> 0
A18: 96 | B18: مدفوعات مقدمه للموردين | D18: =-('B.S.'!F25-'B.S.'!D25) -> 21175 | E18: =-('B.S.'!H25-'B.S.'!F25) -> 0 | F18: =-('B.S.'!J25-'B.S.'!H25) -> 0 | G18: =-('B.S.'!L25-'B.S.'!J25) -> 0 | H18: =-('B.S.'!N25-'B.S.'!L25) -> 0
A19: 97 | B19: ='B.S.'!C26 -> اصول متداوله اخرى | D19: =-('B.S.'!F26-'B.S.'!D26) -> 37432 | E19: =-('B.S.'!H26-'B.S.'!F26) -> -518897 | F19: =-('B.S.'!J26-'B.S.'!H26) -> 1169978 | G19: =-('B.S.'!L26-'B.S.'!J26) -> 0 | H19: =-('B.S.'!N26-'B.S.'!L26) -> 0
A20: 98 | B20: ='B.S.'!C27 -> جاري شركات تابعة | D20: =-('B.S.'!F27-'B.S.'!D27) -> 0 | E20: =-('B.S.'!H27-'B.S.'!F27) -> 0 | F20: =-('B.S.'!J27-'B.S.'!H27) -> 0 | G20: =-('B.S.'!L27-'B.S.'!J27) -> 0 | H20: =-('B.S.'!N27-'B.S.'!L27) -> 0
A21: 99 | B21: ='B.S.'!C31 -> استثمارات طويلة الأجل | D21: =-('B.S.'!F31-'B.S.'!D31) -> 0 | E21: =-('B.S.'!H31-'B.S.'!F31) -> 0 | F21: =-('B.S.'!J31-'B.S.'!H31) -> 0 | G21: =-('B.S.'!L31-'B.S.'!J31) -> 0 | H21: =-('B.S.'!N31-'B.S.'!L31) -> 0
A22: 100 | B22: ='B.S.'!C32 -> جاري مصلحة الضرائب | D22: =-('B.S.'!F32-'B.S.'!D32) -> 0 | E22: =-('B.S.'!H32-'B.S.'!F32) -> 0 | F22: =-('B.S.'!J32-'B.S.'!H32) -> 0 | G22: =-('B.S.'!L32-'B.S.'!J32) -> 0 | H22: =-('B.S.'!N32-'B.S.'!L32) -> 0
A23: 101 | B23: ='B.S.'!C33 -> اصول اخرى غير متداوله | D23: =-('B.S.'!F33-'B.S.'!D33) -> 0 | E23: =-('B.S.'!H33-'B.S.'!F33) -> 0 | F23: =-('B.S.'!J33-'B.S.'!H33) -> 0 | G23: =-('B.S.'!L33-'B.S.'!J33) -> 0 | H23: =-('B.S.'!N33-'B.S.'!L33) -> 0
A24: 102 | B24: ='B.S.'!C34 -> (شهرة ) اصول غير ملموسه | D24: =-('B.S.'!F34-'B.S.'!D34+'I.S.'!F15+'I.S.'!F16) -> 0 | E24: =-('B.S.'!H34-'B.S.'!F34+'I.S.'!H15+'I.S.'!H16) -> 0 | F24: =-('B.S.'!J34-'B.S.'!H34+'I.S.'!J15+'I.S.'!J16) -> 0 | G24: =-('B.S.'!L34-'B.S.'!J34+'I.S.'!L15+'I.S.'!L16) -> 0 | H24: =-('B.S.'!N34-'B.S.'!L34+'I.S.'!N15+'I.S.'!N16) -> 0
A25: 103 | B25: ='B.S.'!C38 -> موردون واوراق دفع | D25: ='B.S.'!F38-'B.S.'!D38 -> -245140.52 | E25: ='B.S.'!H38-'B.S.'!F38 -> 550919 | F25: ='B.S.'!J38-'B.S.'!H38 -> -1046083 | G25: ='B.S.'!L38-'B.S.'!J38 -> 0 | H25: ='B.S.'!N38-'B.S.'!L38 -> 0
A26: 104 | B26: ='B.S.'!C39 -> مصروفات مستحقه | D26: ='B.S.'!F39-'B.S.'!D39 -> 168341 | E26: ='B.S.'!H39-'B.S.'!F39 -> -178796 | F26: ='B.S.'!J39-'B.S.'!H39 -> -186950 | G26: ='B.S.'!L39-'B.S.'!J39 -> 0 | H26: ='B.S.'!N39-'B.S.'!L39 -> 0
A27: 105 | B27: ='B.S.'!C40 -> ارصده دائنه اخرى | D27: ='B.S.'!F40-'B.S.'!D40 -> 0 | E27: ='B.S.'!H40-'B.S.'!F40 -> 0 | F27: ='B.S.'!J40-'B.S.'!H40 -> 0 | G27: ='B.S.'!L40-'B.S.'!J40 -> 0 | H27: ='B.S.'!N40-'B.S.'!L40 -> 0
A28: 106 | B28: ='B.S.'!C41 -> دائنو توزيعات | D28: ='B.S.'!F41-'B.S.'!D41 -> 0 | E28: ='B.S.'!H41-'B.S.'!F41 -> 0 | F28: ='B.S.'!J41-'B.S.'!H41 -> 0 | G28: ='B.S.'!L41-'B.S.'!J41 -> 0 | H28: ='B.S.'!N41-'B.S.'!L41 -> 0
A29: 107 | B29: ='B.S.'!C42 -> مخصصات | D29: ='B.S.'!F42-'B.S.'!D42 -> 0 | E29: ='B.S.'!H42-'B.S.'!F42 -> 0 | F29: ='B.S.'!J42-'B.S.'!H42 -> 0 | G29: ='B.S.'!L42-'B.S.'!J42 -> 0 | H29: ='B.S.'!N42-'B.S.'!L42 -> 0
A30: 108 | B30: ='B.S.'!C43 -> مستحق لشركات تابعه | D30: ='B.S.'!F43-'B.S.'!D43 -> 0 | E30: ='B.S.'!H43-'B.S.'!F43 -> 0 | F30: ='B.S.'!J43-'B.S.'!H43 -> 0 | G30: ='B.S.'!L43-'B.S.'!J43 -> 0 | H30: ='B.S.'!N43-'B.S.'!L43 -> 0
A31: 109 | B31: ايرادات مؤجله | D31: ='B.S.'!F49-'B.S.'!D49 -> 0 | E31: ='B.S.'!H49-'B.S.'!F49 -> 0 | F31: ='B.S.'!J49-'B.S.'!H49 -> #VALUE! | G31: ='B.S.'!L49-'B.S.'!J49 -> #VALUE! | H31: ='B.S.'!N49-'B.S.'!L49 -> 0
A32: 110 | B32: ='B.S.'!C50 -> مخصص ضرائب | D32: ='B.S.'!F50-'B.S.'!D50 -> 0 | E32: ='B.S.'!H50-'B.S.'!F50 -> 0 | F32: ='B.S.'!J50-'B.S.'!H50 -> 0 | G32: ='B.S.'!L50-'B.S.'!J50 -> 0 | H32: ='B.S.'!N50-'B.S.'!L50 -> 0
A33: 111 | B33: ='B.S.'!C51 -> مخصصات اخرى | D33: ='B.S.'!F51-'B.S.'!D51 -> 0 | E33: ='B.S.'!H51-'B.S.'!F51 -> 0 | F33: ='B.S.'!J51-'B.S.'!H51 -> 0 | G33: ='B.S.'!L51-'B.S.'!J51 -> 0 | H33: ='B.S.'!N51-'B.S.'!L51 -> 0
A35: 112 | B35: صافى التدفقات النقديه من الانشطه التشغيليه | D35: =SUM(D16:D33)+D10+D11+D12 -> 295520.42 | E35: =SUM(E16:E33)+E10+E11+E12 -> -89965.076 | F35: =SUM(F16:F33)+F10+F11+F12 -> #VALUE! | G35: =SUM(G16:G33)+G10+G11+G12 -> #VALUE! | H35: =SUM(H16:H33)+H10+H11+H12 -> 0
B37: انشطه استثماريه
A39: 113 | B39: اضافات للاصول الثابته | D39: =-('I.S.'!F56) -> -3500 | E39: =-('I.S.'!H56) -> -147650 | F39: =-('I.S.'!J56) -> 12116587 | G39: =-('I.S.'!L56) -> 0 | H39: =-('I.S.'!N56) -> 0
A40: 114 | B40: ='B.S.'!C30 -> استثمارات في شركات تابعة | D40: =-('B.S.'!F30-'B.S.'!D30) -> 0 | E40: =-('B.S.'!H30-'B.S.'!F30) -> 0 | F40: =-('B.S.'!J30-'B.S.'!H30) -> 0 | G40: =-('B.S.'!L30-'B.S.'!J30) -> 0 | H40: =-('B.S.'!N30-'B.S.'!L30) -> 0
A41: 115 | B41: النقص فى الاصول | D41: ='I.S.'!F58 -> 0 | E41: ='I.S.'!H58 -> 0 | F41: ='I.S.'!J58 -> 0 | G41: ='I.S.'!L58 -> 0 | H41: ='I.S.'!N58 -> 0
A43: 116 | B43: صافى التدفقات النقديه الناتجه من الاستثمار | D43: =SUM(D39:D41) -> -3500 | E43: =SUM(E39:E41) -> -147650 | F43: =SUM(F39:F41) -> 12116587 | G43: =SUM(G39:G41) -> 0 | H43: =SUM(H39:H41) -> 0
B45: انشطه تمويليه
A47: 117 | B47: النقص فى حقوق الملكيه | D47: ='I.S.'!F36 -> 0 | E47: ='I.S.'!H36 -> 0 | F47: ='I.S.'!J36 -> 0 | G47: ='I.S.'!L36 -> 0 | H47: ='I.S.'!N36 -> 0
...

Sheet RATIOS
A1: NAME: | B1: ='B.S.'!C1 -> hanno pop | D1: LOCATION: | E1: ='B.S.'!H1 -> IMC | F1: C. ANALYST: | G1: ='B.S.'!L1 -> ME
A2: Auditor: | B2: ='B.S.'!C2 | D2: AMOUNTS IN: | E2: ='B.S.'!H2 -> EGP | F2: D A T E : | G2: ='B.S.'!L2 -> 12/2025
A3: Audited or Direct (Specify) | C3: ='B.S.'!D3 -> Audited | D3: ='B.S.'!F3 -> Audited | E3: ='B.S.'!H3 -> Audited | F3: Audited | G3: Audited
A4: Unqualified or Qualified (Specify) | C4: ='B.S.'!D4 -> Unqualified | D4: ='B.S.'!F4 -> Unqualifed | E4: ='B.S.'!H4 -> Unqualified | F4: Unqualified
A5: DATE (Day, Month, Year) | C5: ='B.S.'!D6 -> 31/7/2025 | D5: ='B.S.'!F6 -> 31/8/2025 | E5: ='B.S.'!H6 -> 31/12/2025 | F5: ='B.S.'!J6 -> 28/2/2026 | G5: ='B.S.'!L6 -> 0
A6: D E S C R I P T I O N | C6: AMOUNT | D6: AMOUNT | E6: AMOUNT | F6: AMOUNT | G6: AMOUNT | H6: AMOUNT
A7: FINANCIAL SUMMARY
A8: KEY FIGURES
B9: صافى المبيعات | C9: ='I.S.'!D10 -> 2536929 | D9: ='I.S.'!F10 -> 3005991 | E9: ='I.S.'!H10 -> 3170826 | F9: ='I.S.'!J10 -> 0 | G9: ='I.S.'!L10 -> 0 | H9: ='I.S.'!N10 -> 0
B10: ارباح التشغيل | C10: ='I.S.'!D13 -> 859205 | D10: ='I.S.'!F13 -> 847834 | E10: ='I.S.'!H13 -> 841964 | F10: ='I.S.'!J13 -> 0 | G10: ='I.S.'!L13 -> 0 | H10: ='I.S.'!N13 -> 0
B11: الارباح قبل الضرائب | C11: ='I.S.'!D25 -> 473701 | D11: ='I.S.'!F25 -> 523722 | E11: ='I.S.'!H25 -> -853662 | F11: ='I.S.'!J25 -> 0 | G11: ='I.S.'!L25 -> 0 | H11: ='I.S.'!N25 -> 0
B12: صافى الدخل | C12: ='I.S.'!D28 -> 473701 | D12: ='I.S.'!F28 -> 523722 | E12: ='I.S.'!H28 -> -853662 | F12: ='I.S.'!J28 -> 0 | G12: ='I.S.'!L28 -> 0 | H12: ='I.S.'!N28 -> 0
B13: صافى حقوق الملكيه الملموسه | C13: ='B.S.'!D60-'B.S.'!D34 -> 15054136 | D13: ='B.S.'!F60-'B.S.'!F34 -> 15330875 | E13: ='B.S.'!H60-'B.S.'!H34 -> 15217552 | F13: ='B.S.'!J60-'B.S.'!J34 -> 0 | G13: ='B.S.'!L60-'B.S.'!L34 -> 0 | H13: ='B.S.'!N60-'B.S.'!N34 -> 0
B14: اجمالى الاصول | C14: ='B.S.'!D36 -> 19982678 | D14: ='B.S.'!F36 -> 20182618 | E14: ='B.S.'!H36 -> 20296416 | F14: ='B.S.'!J36 -> 0 | G14: ='B.S.'!L36 -> 0 | H14: ='B.S.'!N36 -> 0
B15: راس المال العامل | C15: ='B.S.'!D28-'B.S.'!D45 -> 5733243.9 | D15: ='B.S.'!F28-'B.S.'!F45 -> 6006482.9 | E15: ='B.S.'!H28-'B.S.'!H45 -> 6946796.1 | F15: ='B.S.'!J28-'B.S.'!J45 -> 0 | G15: ='B.S.'!L28-'B.S.'!L45 -> 0 | H15: ='B.S.'!N28-'B.S.'!N45 -> 0
B17: التغير السنوى(%)
B18: صافى المبيعات | D18: =IF('I.S.'!F10=0,0,('I.S.'!F10-'I.S.'!D10)/'I.S.'!D10) -> 0.18489363 | E18: =IF('I.S.'!H10=0,0,('I.S.'!H10-'I.S.'!F10)/'I.S.'!F10) -> 0.054835494 | F18: =IF('I.S.'!J10=0,0,('I.S.'!J10-'I.S.'!H10)/'I.S.'!H10) -> 0 | G18: =IF('I.S.'!L10=0,0,('I.S.'!L10-'I.S.'!J10)/'I.S.'!J10) -> 0 | H18: =IF('I.S.'!N10=0,0,('I.S.'!N10-'I.S.'!L10)/'I.S.'!L10) -> 0
B19: ارباح التشغيل | D19: =IF('I.S.'!F13=0,0,('I.S.'!F13-'I.S.'!D13)/'I.S.'!D13) -> -0.013234327 | E19: =IF('I.S.'!H13=0,0,('I.S.'!H13-'I.S.'!F13)/'I.S.'!F13) -> -0.0069235251 | F19: =IF('I.S.'!J13=0,0,('I.S.'!J13-'I.S.'!H13)/'I.S.'!H13) -> 0 | G19: =IF('I.S.'!L13=0,0,('I.S.'!L13-'I.S.'!J13)/'I.S.'!J13) -> 0 | H19: =IF('I.S.'!N13=0,0,('I.S.'!N13-'I.S.'!L13)/'I.S.'!L13) -> 0
B20: صافى الدخل | D20: =IF('I.S.'!F28=0,0,('I.S.'!F28-'I.S.'!D28)/'I.S.'!D28) -> 0.10559615 | E20: =IF('I.S.'!H28=0,0,('I.S.'!H28-'I.S.'!F28)/'I.S.'!F28) -> -2.6299907 | F20: =IF('I.S.'!J28=0,0,('I.S.'!J28-'I.S.'!H28)/'I.S.'!H28) -> 0 | G20: =IF('I.S.'!L28=0,0,('I.S.'!L28-'I.S.'!J28)/'I.S.'!J28) -> 0 | H20: =IF('I.S.'!N28=0,0,('I.S.'!N28-'I.S.'!L28)/'I.S.'!L28) -> 0
B21: اجمالى الاصول | D21: =IF('B.S.'!F36=0,0,('B.S.'!F36-'B.S.'!D36)/'B.S.'!D36) -> 0.010005639 | E21: =IF('B.S.'!H36=0,0,('B.S.'!H36-'B.S.'!F36)/'B.S.'!F36) -> 0.0056384249 | F21: =IF('B.S.'!J36=0,0,('B.S.'!J36-'B.S.'!H36)/'B.S.'!H36) -> 0 | G21: =IF('B.S.'!L36=0,0,('B.S.'!L36-'B.S.'!J36)/'B.S.'!J36) -> 0 | H21: =IF('B.S.'!N36=0,0,('B.S.'!N36-'B.S.'!L36)/'B.S.'!L36) -> 0
B23: التدفقات النقديه
B24: صافى النقديه من التشغيل | D24: ='OPS & NON-OPS'!E31 -> 295520.42 | E24: ='OPS & NON-OPS'!F31 -> -89965.076 | F24: ='OPS & NON-OPS'!G31 -> 5277671.1 | G24: ='OPS & NON-OPS'!H31 -> 0 | H24: ='OPS & NON-OPS'!I31 -> 0
B25: اجمالى النقديه من التشغيل | D25: ='OPS & NON-OPS'!E12 -> 523722 | E25: ='OPS & NON-OPS'!F12 -> 492626 | F25: ='OPS & NON-OPS'!G12 -> 0 | G25: ='OPS & NON-OPS'!H12 -> 0 | H25: ='OPS & NON-OPS'!I12 -> 0
B26: سلفيات جديده | D26: =IF(('CASH FLOW'!D48+'CASH FLOW'!D49)>0,('CASH FLOW'!D48+'CASH FLOW'!D49),0) -> 0 | E26: =IF(('CASH FLOW'!E48+'CASH FLOW'!E49)>0,('CASH FLOW'!E48+'CASH FLOW'!E49),0) -> 0 | F26: =IF(('CASH FLOW'!F48+'CASH FLOW'!F49)>0,('CASH FLOW'!F48+'CASH FLOW'!F49),0) -> 0 | G26: =IF(('CASH FLOW'!G48+'CASH FLOW'!G49)>0,('CASH FLOW'!G48+'CASH FLOW'!G49),0) -> 0 | H26: =IF(('CASH FLOW'!H48+'CASH FLOW'!H49)>0,('CASH FLOW'!H48+'CASH FLOW'!H49),0) -> 0
B27: حقوق ملكيه جديده | D27: ='I.S.'!F36+'I.S.'!F37+'I.S.'!F38 -> 0 | E27: ='I.S.'!H36+'I.S.'!H37+'I.S.'!H38 -> 740339 | F27: ='I.S.'!J36+'I.S.'!J37+'I.S.'!J38 -> 0 | G27: ='I.S.'!L36+'I.S.'!L37+'I.S.'!L38 -> 0 | H27: ='I.S.'!N36+'I.S.'!N37+'I.S.'!N38 -> 0
B28: نسبة التغطيه | D28: =IF('I.S.'!F24=0,0,('I.S.'!F23+'I.S.'!F14)/'I.S.'!F24) -> 0 | E28: =IF('I.S.'!H24=0,0,('I.S.'!H23+'I.S.'!H14)/'I.S.'!H24) -> 0 | F28: =IF('I.S.'!J24=0,0,('I.S.'!J23+'I.S.'!J14)/'I.S.'!J24) -> 0 | G28: =IF('I.S.'!L24=0,0,('I.S.'!L23+'I.S.'!L14)/'I.S.'!L24) -> 0 | H28: =IF('I.S.'!N24=0,0,('I.S.'!N23+'I.S.'!N14)/'I.S.'!N24) -> 0
B29: خدمة الدين | D29: =IF('B.S.'!D44=0,0,('I.S.'!F23+'I.S.'!F14)/('I.S.'!F24+'B.S.'!D44)) -> 0 | E29: =IF('B.S.'!F44=0,0,('I.S.'!H23+'I.S.'!H14)/('I.S.'!H24+'B.S.'!F44)) -> 0 | F29: =IF('B.S.'!H44=0,0,('I.S.'!J23+'I.S.'!J14)/('I.S.'!J24+'B.S.'!H44)) -> 0 | G29: =IF('B.S.'!J44=0,0,('I.S.'!L23+'I.S.'!L14)/('I.S.'!L24+'B.S.'!J44)) -> 0 | H29: =IF('B.S.'!L44=0,0,('I.S.'!N23+'I.S.'!N14)/('B.S.'!L44+'I.S.'!N24)) -> 0
B31: النسب الماليه (%)
B32: صافى الدخل / المبيعات | C32: ='I.S.'!E28 -> 0.18672221 | D32: ='I.S.'!G28 -> 0.17422607 | E32: ='I.S.'!I28 -> -0.26922386 | F32: ='I.S.'!K28 -> 0 | G32: ='I.S.'!M28 -> 0 | H32: ='I.S.'!O28 -> 0
B33: صافى الدخل / اجمالى الاصول | C33: =IF('B.S.'!D36=0,0,'I.S.'!D28/'B.S.'!D36) -> 0.023705581 | D33: =IF('B.S.'!F36=0,0,'I.S.'!F28/'B.S.'!F36) -> 0.025949161 | E33: =IF('B.S.'!H36=0,0,'I.S.'!H28/'B.S.'!H36) -> -0.042059741 | F33: =IF('B.S.'!J36=0,0,'I.S.'!J28/'B.S.'!J36) -> 0 | G33: =IF('B.S.'!L36=0,0,'I.S.'!L28/'B.S.'!L36) -> 0 | H33: =IF('B.S.'!N36=0,0,'I.S.'!N28/'B.S.'!N36) -> 0
B34: صافى الدخل / حقوق الملكيه الملموسه | C34: =IF(C13=0,0,'I.S.'!D28/C13) -> 0.031466502 | D34: =IF(D13=0,0,'I.S.'!F28/D13) -> 0.03416126 | E34: =IF(E13=0,0,'I.S.'!H28/E13) -> -0.056097196 | F34: =IF(F13=0,0,'I.S.'!J28/F13) -> 0 | G34: =IF(G13=0,0,'I.S.'!L28/G13) -> 0 | H34: =IF(H13=0,0,'I.S.'!N28/H13) -> 0
B35: ارباح التشغيل / المبيعات | C35: ='I.S.'!E13 -> 0.33867917 | D35: ='I.S.'!G13 -> 0.28204808 | E35: ='I.S.'!I13 -> 0.2655346 | F35: ='I.S.'!K13 -> 0 | G35: ='I.S.'!M13 -> 0 | H35: ='I.S.'!O13 -> 0
B36: ارباح التشغيل / الاصول السريعه | C36: =IF('I.S.'!D13=0,0,'I.S.'!D13/('B.S.'!D28-'B.S.'!D24)) -> 0.21845371 | D36: =IF('I.S.'!F13=0,0,'I.S.'!F13/('B.S.'!F28-'B.S.'!F24)) -> 0.20334866 | E36: =IF('I.S.'!H13=0,0,'I.S.'!H13/('B.S.'!H28-'B.S.'!H24)) -> 0.16102596 | F36: =IF('I.S.'!J13=0,0,'I.S.'!J13/('B.S.'!J28-'B.S.'!J24)) -> 0 | G36: =IF('I.S.'!L13=0,0,'I.S.'!L13/('B.S.'!L28-'B.S.'!L24)) -> 0 | H36: =IF('I.S.'!N13=0,0,'I.S.'!N13/('B.S.'!N28-'B.S.'!N24)) -> 0
B38: كفائة معدلات الدوران
B39: صافى المبيعات / صافى الاصول الثابته | C39: =IF('B.S.'!D29=0,0,'I.S.'!D10/'B.S.'!D29) -> 0.19057853 | D39: =IF('B.S.'!F29=0,0,'I.S.'!F10/'B.S.'!F29) -> 0.22575593 | E39: =IF('B.S.'!H29=0,0,'I.S.'!H10/'B.S.'!H29) -> 0.261693 | F39: =IF('B.S.'!J29=0,0,'I.S.'!J10/'B.S.'!J29) -> 0 | G39: =IF('B.S.'!L29=0,0,'I.S.'!L10/'B.S.'!L29) -> 0 | H39: =IF('B.S.'!N29=0,0,'I.S.'!N10/'B.S.'!N29) -> 0
B40: متوسط فترة تحصيل اوراق القبض الحاليه | C40: =IF('I.S.'!D10=0,0,'B.S.'!D23/'I.S.'!D10*('I.S.'!D7/12)*360) -> 23.142957 | D40: =IF('I.S.'!F10=0,0,'B.S.'!F23/'I.S.'!F10*('I.S.'!F7/12)*360) -> 22.024789 | E40: =IF('I.S.'!H10=0,0,'B.S.'!H23/'I.S.'!H10*('I.S.'!H7/12)*360) -> 22.609036 | F40: =IF('I.S.'!J10=0,0,'B.S.'!J23/'I.S.'!J10*('I.S.'!J7/12)*360) -> 0 | G40: =IF('I.S.'!L10=0,0,'B.S.'!L23/'I.S.'!L10*('I.S.'!L7/12)*360) -> 0 | H40: =IF('I.S.'!N10=0,0,'B.S.'!N23/'I.S.'!N10*('I.S.'!N7/12)*360) -> 0
B41: متوسط فترة التحصيل الاجماليه لاوراق القبض | C41: =IF('I.S.'!D10=0,0,('B.S.'!D23+'B.S.'!D33+'B.S.'!D26)/'I.S.'!D10*('I.S.'!D7/12)*360) -> 31.284845 | D41: =IF('I.S.'!F10=0,0,('B.S.'!F23+'B.S.'!F26+'B.S.'!F33)/'I.S.'!F10*('I.S.'!F7/12)*360) -> 28.522623 | E41: =IF('I.S.'!H10=0,0,('B.S.'!H23+'B.S.'!H26+'B.S.'!H33)/'I.S.'!H10*('I.S.'!H7/12)*360) -> 33.678499 | F41: =IF('I.S.'!J10=0,0,('B.S.'!J23+'B.S.'!J26+'B.S.'!J33)/'I.S.'!J10*('I.S.'!J7/12)*360) -> 0 | G41: =IF('I.S.'!L10=0,0,('B.S.'!L23+'B.S.'!L26+'B.S.'!L33)/'I.S.'!L10*('I.S.'!L7/12)*360) -> 0 | H41: =IF('I.S.'!N7=0,0,('B.S.'!N23+'B.S.'!N26+'B.S.'!N33)/'I.S.'!N10*('I.S.'!N7/12)*360) -> 0
B42: متوسط فترة التخزين | C42: =IF('I.S.'!D11=0,0,'B.S.'!D24/'I.S.'!D11*('I.S.'!D7/12)*360) -> 63.708192 | D42: =IF('I.S.'!F11=0,0,'B.S.'!F24/'I.S.'!F11*('I.S.'!F7/12)*360) -> 46.3824 | E42: =IF('I.S.'!H11=0,0,'B.S.'!H24/'I.S.'!H11*('I.S.'!H7/12)*360) -> 49.298114 | F42: =IF('I.S.'!J11=0,0,'B.S.'!J24/'I.S.'!J11*('I.S.'!J7/12)*360) -> 0 | G42: =IF('I.S.'!L11=0,0,'B.S.'!L24/'I.S.'!L11*('I.S.'!L7/12)*360) -> 0 | H42: =IF('I.S.'!N11=0,0,'B.S.'!N24/'I.S.'!N11*('I.S.'!N7/12)*360) -> 0
B43: متوسط فترة سداد اوراق الدفع | C43: =IF('I.S.'!D11=0,0,'B.S.'!D38/'I.S.'!D11*('I.S.'!D7/12)*360) -> 17.226573 | D43: =IF('I.S.'!F11=0,0,'B.S.'!F38/'I.S.'!F11*('I.S.'!F7/12)*360) -> 8.5124628 | E43: =IF('I.S.'!H11=0,0,'B.S.'!H38/'I.S.'!H11*('I.S.'!H7/12)*360) -> 17.474919 | F43: =IF('I.S.'!J11=0,0,'B.S.'!J38/'I.S.'!J11*('I.S.'!J7/12)*360) -> 0 | G43: =IF('I.S.'!L7=0,0,'B.S.'!L38/'I.S.'!L11*('I.S.'!L7/12)*360) -> 0 | H43: =IF('I.S.'!N11=0,0,'B.S.'!N38/'I.S.'!N11*('I.S.'!N7/12)*360) -> 0
B44: صافى النقديه الناتجه من تحول الاصول | C44: =C41+C42-C43 -> 77.766463 | D44: =D41+D42-D43 -> 66.39256 | E44: =E41+E42-E43 -> 65.501695 | F44: =F41+F42-F43 -> 0 | G44: =G41+G42-G43 -> 0 | H44: =H41+H42-H43 -> 0
...
