Workbook

Sheet احتساب متوسط سبتمبر
A1: ABOHASHEM FOR MEAT — متوسط التكلفة المرجّح للخامات آخر سبتمبر 2026 وتقييم جرد 30/9
A2: المتوسط = (كمية جرد 31/8 × متوسط أغسطس + قيمة مشتريات سبتمبر) ÷ (كمية جرد 31/8 + كمية مشتريات سبتمبر). عمود «السعر المُدخل بالملف» هو ما وُضع فى «تسعير جرد اخر شهر ٩».
A4: اسم الصنف | B4: كمية أول المدة (جرد 31/8) | C4: سعر أول المدة (متوسط أغسطس) | D4: قيمة أول المدة | E4: كمية مشتريات سبتمبر | F4: قيمة مشتريات سبتمبر | G4: إجمالى الكمية المتاحة | H4: إجمالى القيمة المتاحة | I4: متوسط السعر (WAC) 30/9 | J4: السعر المُدخل بالملف | K4: كمية جرد 30/9 | L4: قيمة مخزون 30/9 | M4: التغير عن أغسطس % | N4: الحالة / ملاحظة
A5: بصل | B5: 500 | C5: 13.7773 | D5: =IF(C5="","",B5*C5) | E5: =SUMIF('مشتريات سبتمبر التفصيلية'!$I$4:$I$92,A5,'مشتريات سبتمبر التفصيلية'!$F$4:$F$92) | F5: =SUMIF('مشتريات سبتمبر التفصيلية'!$I$4:$I$92,A5,'مشتريات سبتمبر التفصيلية'!$H$4:$H$92) | G5: =IF(C5="",E5,B5+E5) | H5: =N(D5)+F5 | I5: =IF(G5>0,ROUND(H5/G5,4),IF(C5="","",C5)) | J5: 18.7559 | K5: 1969 | L5: =IF(J5="","",K5*J5) | M5: =IF(OR(C5="",I5=""),"",I5/C5-1) | N5: قياسى: (أول المدة + المشتريات)
A6: ثوم | B6: 1249.55 | C6: 25.0724 | D6: =IF(C6="","",B6*C6) | E6: =SUMIF('مشتريات سبتمبر التفصيلية'!$I$4:$I$92,A6,'مشتريات سبتمبر التفصيلية'!$F$4:$F$92) | F6: =SUMIF('مشتريات سبتمبر التفصيلية'!$I$4:$I$92,A6,'مشتريات سبتمبر التفصيلية'!$H$4:$H$92) | G6: =IF(C6="",E6,B6+E6) | H6: =N(D6)+F6 | I6: =IF(G6>0,ROUND(H6/G6,4),IF(C6="","",C6)) | J6: 25.0724 | K6: 953 | L6: =IF(J6="","",K6*J6) | M6: =IF(OR(C6="",I6=""),"",I6/C6-1) | N6: لا مشتريات فى سبتمبر ⇒ سعر أغسطس ثابت
A7: فلفل بارد | B7: 320 | C7: 9.1171 | D7: =IF(C7="","",B7*C7) | E7: =SUMIF('مشتريات سبتمبر التفصيلية'!$I$4:$I$92,A7,'مشتريات سبتمبر التفصيلية'!$F$4:$F$92) | F7: =SUMIF('مشتريات سبتمبر التفصيلية'!$I$4:$I$92,A7,'مشتريات سبتمبر التفصيلية'!$H$4:$H$92) | G7: =IF(C7="",E7,B7+E7) | H7: =N(D7)+F7 | I7: =IF(G7>0,ROUND(H7/G7,4),IF(C7="","",C7)) | J7: 10.4234 | K7: 445 | L7: =IF(J7="","",K7*J7) | M7: =IF(OR(C7="",I7=""),"",I7/C7-1) | N7: قياسى: (أول المدة + المشتريات)
A8: مفروم فراخ شعبي | B8: 2120 | C8: 28.386 | D8: =IF(C8="","",B8*C8) | E8: =SUMIF('مشتريات سبتمبر التفصيلية'!$I$4:$I$92,A8,'مشتريات سبتمبر التفصيلية'!$F$4:$F$92) | F8: =SUMIF('مشتريات سبتمبر التفصيلية'!$I$4:$I$92,A8,'مشتريات سبتمبر التفصيلية'!$H$4:$H$92) | G8: =IF(C8="",E8,B8+E8) | H8: =N(D8)+F8 | I8: =IF(G8>0,ROUND(H8/G8,4),IF(C8="","",C8)) | J8: 30 | K8: 860 | L8: =IF(J8="","",K8*J8) | M8: =IF(OR(C8="",I8=""),"",I8/C8-1) | N8: ⚠ لم يُغيَّر السعر — بيانات شراء متعارضة; فاتورة 1111115217 (09/09): «مفروم فراخ C» 1,500 كجم بسعر 57 بينما نطاق الرتبة C 30–35، وفى نفس الفاتورة «مفروم فراخ A» بسعر 30 بينما نطاق A 55–60 — السعران يبدوان معكوسين
A9: صميد | B9: 1241 | C9: 16.1708 | D9: =IF(C9="","",B9*C9) | E9: =SUMIF('مشتريات سبتمبر التفصيلية'!$I$4:$I$92,A9,'مشتريات سبتمبر التفصيلية'!$F$4:$F$92) | F9: =SUMIF('مشتريات سبتمبر التفصيلية'!$I$4:$I$92,A9,'مشتريات سبتمبر التفصيلية'!$H$4:$H$92) | G9: =IF(C9="",E9,B9+E9) | H9: =N(D9)+F9 | I9: =IF(G9>0,ROUND(H9/G9,4),IF(C9="","",C9)) | J9: 16.6485 | K9: 1650 | L9: =IF(J9="","",K9*J9) | M9: =IF(OR(C9="",I9=""),"",I9/C9-1) | N9: قياسى: (أول المدة + المشتريات)
A10: صويا لحمه | B10: 777 | C10: 36.8234 | D10: =IF(C10="","",B10*C10) | E10: =SUMIF('مشتريات سبتمبر التفصيلية'!$I$4:$I$92,A10,'مشتريات سبتمبر التفصيلية'!$F$4:$F$92) | F10: =SUMIF('مشتريات سبتمبر التفصيلية'!$I$4:$I$92,A10,'مشتريات سبتمبر التفصيلية'!$H$4:$H$92) | G10: =IF(C10="",E10,B10+E10) | H10: =N(D10)+F10 | I10: =IF(G10>0,ROUND(H10/G10,4),IF(C10="","",C10)) | J10: 38.2273 | K10: 270 | L10: =IF(J10="","",K10*J10) | M10: =IF(OR(C10="",I10=""),"",I10/C10-1) | N10: قياسى: (أول المدة + المشتريات)
A11: صويا اوزيليت | B11: 151.5 | C11: 168.445 | D11: =IF(C11="","",B11*C11) | E11: =SUMIF('مشتريات سبتمبر التفصيلية'!$I$4:$I$92,A11,'مشتريات سبتمبر التفصيلية'!$F$4:$F$92) | F11: =SUMIF('مشتريات سبتمبر التفصيلية'!$I$4:$I$92,A11,'مشتريات سبتمبر التفصيلية'!$H$4:$H$92) | G11: =IF(C11="",E11,B11+E11) | H11: =N(D11)+F11 | I11: =IF(G11>0,ROUND(H11/G11,4),IF(C11="","",C11)) | J11: 166.2683 | K11: 264 | L11: =IF(J11="","",K11*J11) | M11: =IF(OR(C11="",I11=""),"",I11/C11-1) | N11: قياسى: (أول المدة + المشتريات)
A12: مفروم فراخ فاخر | B12: 415 | C12: 55.082 | D12: =IF(C12="","",B12*C12) | E12: =SUMIF('مشتريات سبتمبر التفصيلية'!$I$4:$I$92,A12,'مشتريات سبتمبر التفصيلية'!$F$4:$F$92) | F12: =SUMIF('مشتريات سبتمبر التفصيلية'!$I$4:$I$92,A12,'مشتريات سبتمبر التفصيلية'!$H$4:$H$92) | G12: =IF(C12="",E12,B12+E12) | H12: =N(D12)+F12 | I12: =IF(G12>0,ROUND(H12/G12,4),IF(C12="","",C12)) | J12: 60 | K12: 370 | L12: =IF(J12="","",K12*J12) | M12: =IF(OR(C12="",I12=""),"",I12/C12-1) | N12: ⚠ لم يُغيَّر السعر — بيانات شراء متعارضة; فاتورة 1111115217 (09/09): «مفروم فراخ A» 450 كجم بسعر 30 بينما نطاق الرتبة A 55–60، وفى نفس الفاتورة «مفروم فراخ C» بسعر 57 — السعران يبدوان معكوسين
A13: دهن بلدي | B13: 1754.85 | C13: 53.8106 | D13: =IF(C13="","",B13*C13) | E13: =SUMIF('مشتريات سبتمبر التفصيلية'!$I$4:$I$92,A13,'مشتريات سبتمبر التفصيلية'!$F$4:$F$92) | F13: =SUMIF('مشتريات سبتمبر التفصيلية'!$I$4:$I$92,A13,'مشتريات سبتمبر التفصيلية'!$H$4:$H$92) | G13: =IF(C13="",E13,B13+E13) | H13: =N(D13)+F13 | I13: =IF(G13>0,ROUND(H13/G13,4),IF(C13="","",C13)) | J13: 62.4178 | K13: 391.5 | L13: =IF(J13="","",K13*J13) | M13: =IF(OR(C13="",I13=""),"",I13/C13-1) | N13: قياسى: (أول المدة + المشتريات)
A14: لحم كتف | B14: 40 | C14: 253.0246 | D14: =IF(C14="","",B14*C14) | E14: =SUMIF('مشتريات سبتمبر التفصيلية'!$I$4:$I$92,A14,'مشتريات سبتمبر التفصيلية'!$F$4:$F$92) | F14: =SUMIF('مشتريات سبتمبر التفصيلية'!$I$4:$I$92,A14,'مشتريات سبتمبر التفصيلية'!$H$4:$H$92) | G14: =IF(C14="",E14,B14+E14) | H14: =N(D14)+F14 | I14: =I174 | J14: 260.2402 | K14: 40 | L14: =IF(J14="","",K14*J14) | M14: =IF(OR(C14="",I14=""),"",I14/C14-1) | N14: متوسط مجمّع اللحوم الهندى
A15: لحم رقبه | B15: 60 | C15: 253.0246 | D15: =IF(C15="","",B15*C15) | E15: =SUMIF('مشتريات سبتمبر التفصيلية'!$I$4:$I$92,A15,'مشتريات سبتمبر التفصيلية'!$F$4:$F$92) | F15: =SUMIF('مشتريات سبتمبر التفصيلية'!$I$4:$I$92,A15,'مشتريات سبتمبر التفصيلية'!$H$4:$H$92) | G15: =IF(C15="",E15,B15+E15) | H15: =N(D15)+F15 | I15: =I174 | J15: 260.2402 | K15: 20 | L15: =IF(J15="","",K15*J15) | M15: =IF(OR(C15="",I15=""),"",I15/C15-1) | N15: متوسط مجمّع اللحوم الهندى
A16: لحم سن | B16: 20 | C16: 253.0246 | D16: =IF(C16="","",B16*C16) | E16: =SUMIF('مشتريات سبتمبر التفصيلية'!$I$4:$I$92,A16,'مشتريات سبتمبر التفصيلية'!$F$4:$F$92) | F16: =SUMIF('مشتريات سبتمبر التفصيلية'!$I$4:$I$92,A16,'مشتريات سبتمبر التفصيلية'!$H$4:$H$92) | G16: =IF(C16="",E16,B16+E16) | H16: =N(D16)+F16 | I16: =I174 | J16: 260.2402 | K16: 20 | L16: =IF(J16="","",K16*J16) | M16: =IF(OR(C16="",I16=""),"",I16/C16-1) | N16: متوسط مجمّع اللحوم الهندى
A17: لحمه ارباع | B17: 25 | C17: 253.0246 | D17: =IF(C17="","",B17*C17) | E17: =SUMIF('مشتريات سبتمبر التفصيلية'!$I$4:$I$92,A17,'مشتريات سبتمبر التفصيلية'!$F$4:$F$92) | F17: =SUMIF('مشتريات سبتمبر التفصيلية'!$I$4:$I$92,A17,'مشتريات سبتمبر التفصيلية'!$H$4:$H$92) | G17: =IF(C17="",E17,B17+E17) | H17: =N(D17)+F17 | I17: =I174 | J17: 260.2402 | K17: 40 | L17: =IF(J17="","",K17*J17) | M17: =IF(OR(C17="",I17=""),"",I17/C17-1) | N17: متوسط مجمّع اللحوم الهندى
A18: سمانة هندي | B18: 0 | D18: =IF(C18="","",B18*C18) | E18: =SUMIF('مشتريات سبتمبر التفصيلية'!$I$4:$I$92,A18,'مشتريات سبتمبر التفصيلية'!$F$4:$F$92) | F18: =SUMIF('مشتريات سبتمبر التفصيلية'!$I$4:$I$92,A18,'مشتريات سبتمبر التفصيلية'!$H$4:$H$92) | G18: =IF(C18="",E18,B18+E18) | H18: =N(D18)+F18 | I18: =IF(G18>0,ROUND(H18/G18,4),IF(C18="","",C18)) | K18: 0 | L18: =IF(J18="","",K18*J18) | M18: =IF(OR(C18="",I18=""),"",I18/C18-1) | N18: بلا سعر — لا سعر أغسطس ولا مشتريات سبتمبر
A19: فلانك | B19: 110 | C19: 198.3869 | D19: =IF(C19="","",B19*C19) | E19: =SUMIF('مشتريات سبتمبر التفصيلية'!$I$4:$I$92,A19,'مشتريات سبتمبر التفصيلية'!$F$4:$F$92) | F19: =SUMIF('مشتريات سبتمبر التفصيلية'!$I$4:$I$92,A19,'مشتريات سبتمبر التفصيلية'!$H$4:$H$92) | G19: =IF(C19="",E19,B19+E19) | H19: =N(D19)+F19 | I19: =IF(G19>0,ROUND(H19/G19,4),IF(C19="","",C19)) | J19: 209.7882 | K19: 160 | L19: =IF(J19="","",K19*J19) | M19: =IF(OR(C19="",I19=""),"",I19/C19-1) | N19: قياسى: (أول المدة + المشتريات)
A20: برغل | B20: 3325 | C20: 21.2509 | D20: =IF(C20="","",B20*C20) | E20: =SUMIF('مشتريات سبتمبر التفصيلية'!$I$4:$I$92,A20,'مشتريات سبتمبر التفصيلية'!$F$4:$F$92) | F20: =SUMIF('مشتريات سبتمبر التفصيلية'!$I$4:$I$92,A20,'مشتريات سبتمبر التفصيلية'!$H$4:$H$92) | G20: =IF(C20="",E20,B20+E20) | H20: =N(D20)+F20 | I20: =IF(G20>0,ROUND(H20/G20,4),IF(C20="","",C20)) | J20: 21.3445 | K20: 2545 | L20: =IF(J20="","",K20*J20) | M20: =IF(OR(C20="",I20=""),"",I20/C20-1) | N20: قياسى: (أول المدة + المشتريات)
A21: صويا فراخ | B21: 180 | C21: 46.8182 | D21: =IF(C21="","",B21*C21) | E21: =SUMIF('مشتريات سبتمبر التفصيلية'!$I$4:$I$92,A21,'مشتريات سبتمبر التفصيلية'!$F$4:$F$92) | F21: =SUMIF('مشتريات سبتمبر التفصيلية'!$I$4:$I$92,A21,'مشتريات سبتمبر التفصيلية'!$H$4:$H$92) | G21: =IF(C21="",E21,B21+E21) | H21: =N(D21)+F21 | I21: =IF(G21>0,ROUND(H21/G21,4),IF(C21="","",C21)) | J21: 46.8182 | K21: 90 | L21: =IF(J21="","",K21*J21) | M21: =IF(OR(C21="",I21=""),"",I21/C21-1) | N21: لا مشتريات فى سبتمبر ⇒ سعر أغسطس ثابت
A22: كبده | B22: 63.304 | C22: 164.7217 | D22: =IF(C22="","",B22*C22) | E22: =SUMIF('مشتريات سبتمبر التفصيلية'!$I$4:$I$92,A22,'مشتريات سبتمبر التفصيلية'!$F$4:$F$92) | F22: =SUMIF('مشتريات سبتمبر التفصيلية'!$I$4:$I$92,A22,'مشتريات سبتمبر التفصيلية'!$H$4:$H$92) | G22: =IF(C22="",E22,B22+E22) | H22: =N(D22)+F22 | I22: =IF(G22>0,ROUND(H22/G22,4),IF(C22="","",C22)) | J22: 168.6305 | K22: 59.104 | L22: =IF(J22="","",K22*J22) | M22: =IF(OR(C22="",I22=""),"",I22/C22-1) | N22: قياسى: (أول المدة + المشتريات)
A23: جلد | B23: 359 | C23: 28.8872 | D23: =IF(C23="","",B23*C23) | E23: =SUMIF('مشتريات سبتمبر التفصيلية'!$I$4:$I$92,A23,'مشتريات سبتمبر التفصيلية'!$F$4:$F$92) | F23: =SUMIF('مشتريات سبتمبر التفصيلية'!$I$4:$I$92,A23,'مشتريات سبتمبر التفصيلية'!$H$4:$H$92) | G23: =IF(C23="",E23,B23+E23) | H23: =N(D23)+F23 | I23: =IF(G23>0,ROUND(H23/G23,4),IF(C23="","",C23)) | J23: 28.231 | K23: 603 | L23: =IF(J23="","",K23*J23) | M23: =IF(OR(C23="",I23=""),"",I23/C23-1) | N23: قياسى: (أول المدة + المشتريات)
A24: هانك | B24: 118 | C24: 248.9842 | D24: =IF(C24="","",B24*C24) | E24: =SUMIF('مشتريات سبتمبر التفصيلية'!$I$4:$I$92,A24,'مشتريات سبتمبر التفصيلية'!$F$4:$F$92) | F24: =SUMIF('مشتريات سبتمبر التفصيلية'!$I$4:$I$92,A24,'مشتريات سبتمبر التفصيلية'!$H$4:$H$92) | G24: =IF(C24="",E24,B24+E24) | H24: =N(D24)+F24 | I24: =IF(G24>0,ROUND(H24/G24,4),IF(C24="","",C24)) | J24: 249.8793 | K24: 214 | L24: =IF(J24="","",K24*J24) | M24: =IF(OR(C24="",I24=""),"",I24/C24-1) | N24: قياسى: (أول المدة + المشتريات)
A25: دوبريه | B25: 470 | C25: 95.2993 | D25: =IF(C25="","",B25*C25) | E25: =SUMIF('مشتريات سبتمبر التفصيلية'!$I$4:$I$92,A25,'مشتريات سبتمبر التفصيلية'!$F$4:$F$92) | F25: =SUMIF('مشتريات سبتمبر التفصيلية'!$I$4:$I$92,A25,'مشتريات سبتمبر التفصيلية'!$H$4:$H$92) | G25: =IF(C25="",E25,B25+E25) | H25: =N(D25)+F25 | I25: =IF(G25>0,ROUND(H25/G25,4),IF(C25="","",C25)) | J25: 93.0374 | K25: 85 | L25: =IF(J25="","",K25*J25) | M25: =IF(OR(C25="",I25=""),"",I25/C25-1) | N25: قياسى: (أول المدة + المشتريات)
A26: فلفل رومي حامي | B26: 15.7 | C26: 14.6228 | D26: =IF(C26="","",B26*C26) | E26: =SUMIF('مشتريات سبتمبر التفصيلية'!$I$4:$I$92,A26,'مشتريات سبتمبر التفصيلية'!$F$4:$F$92) | F26: =SUMIF('مشتريات سبتمبر التفصيلية'!$I$4:$I$92,A26,'مشتريات سبتمبر التفصيلية'!$H$4:$H$92) | G26: =IF(C26="",E26,B26+E26) | H26: =N(D26)+F26 | I26: =IF(G26>0,ROUND(H26/G26,4),IF(C26="","",C26)) | J26: 11.1014 | K26: 156 | L26: =IF(J26="","",K26*J26) | M26: =IF(OR(C26="",I26=""),"",I26/C26-1) | N26: قياسى: (أول المدة + المشتريات)
A27: فيليه | B27: 0 | C27: 195 | D27: =IF(C27="","",B27*C27) | E27: =SUMIF('مشتريات سبتمبر التفصيلية'!$I$4:$I$92,A27,'مشتريات سبتمبر التفصيلية'!$F$4:$F$92) | F27: =SUMIF('مشتريات سبتمبر التفصيلية'!$I$4:$I$92,A27,'مشتريات سبتمبر التفصيلية'!$H$4:$H$92) | G27: =IF(C27="",E27,B27+E27) | H27: =N(D27)+F27 | I27: =IF(G27>0,ROUND(H27/G27,4),IF(C27="","",C27)) | J27: 195 | K27: 0 | L27: =IF(J27="","",K27*J27) | M27: =IF(OR(C27="",I27=""),"",I27/C27-1) | N27: لا مشتريات فى سبتمبر ⇒ سعر أغسطس ثابت
A28: بقسماط اصفر | B28: 0 | C28: 38.5 | D28: =IF(C28="","",B28*C28) | E28: =SUMIF('مشتريات سبتمبر التفصيلية'!$I$4:$I$92,A28,'مشتريات سبتمبر التفصيلية'!$F$4:$F$92) | F28: =SUMIF('مشتريات سبتمبر التفصيلية'!$I$4:$I$92,A28,'مشتريات سبتمبر التفصيلية'!$H$4:$H$92) | G28: =IF(C28="",E28,B28+E28) | H28: =N(D28)+F28 | I28: =IF(G28>0,ROUND(H28/G28,4),IF(C28="","",C28)) | J28: 39.5 | K28: 0 | L28: =IF(J28="","",K28*J28) | M28: =IF(OR(C28="",I28=""),"",I28/C28-1) | N28: قياسى: (أول المدة + المشتريات)
A29: بقسماط ابيض | B29: 0 | D29: =IF(C29="","",B29*C29) | E29: =SUMIF('مشتريات سبتمبر التفصيلية'!$I$4:$I$92,A29,'مشتريات سبتمبر التفصيلية'!$F$4:$F$92) | F29: =SUMIF('مشتريات سبتمبر التفصيلية'!$I$4:$I$92,A29,'مشتريات سبتمبر التفصيلية'!$H$4:$H$92) | G29: =IF(C29="",E29,B29+E29) | H29: =N(D29)+F29 | I29: =IF(G29>0,ROUND(H29/G29,4),IF(C29="","",C29)) | K29: 0 | L29: =IF(J29="","",K29*J29) | M29: =IF(OR(C29="",I29=""),"",I29/C29-1) | N29: بلا سعر — لا سعر أغسطس ولا مشتريات سبتمبر
A30: بطاطس | B30: 0 | D30: =IF(C30="","",B30*C30) | E30: =SUMIF('مشتريات سبتمبر التفصيلية'!$I$4:$I$92,A30,'مشتريات سبتمبر التفصيلية'!$F$4:$F$92) | F30: =SUMIF('مشتريات سبتمبر التفصيلية'!$I$4:$I$92,A30,'مشتريات سبتمبر التفصيلية'!$H$4:$H$92) | G30: =IF(C30="",E30,B30+E30) | H30: =N(D30)+F30 | I30: =IF(G30>0,ROUND(H30/G30,4),IF(C30="","",C30)) | K30: 0 | L30: =IF(J30="","",K30*J30) | M30: =IF(OR(C30="",I30=""),"",I30/C30-1) | N30: بلا سعر — لا سعر أغسطس ولا مشتريات سبتمبر
A31: دوبرية بسطرمة (لحمة) | B31: 0 | C31: 185 | D31: =IF(C31="","",B31*C31) | E31: =SUMIF('مشتريات سبتمبر التفصيلية'!$I$4:$I$92,A31,'مشتريات سبتمبر التفصيلية'!$F$4:$F$92) | F31: =SUMIF('مشتريات سبتمبر التفصيلية'!$I$4:$I$92,A31,'مشتريات سبتمبر التفصيلية'!$H$4:$H$92) | G31: =IF(C31="",E31,B31+E31) | H31: =N(D31)+F31 | I31: =IF(G31>0,ROUND(H31/G31,4),IF(C31="","",C31)) | J31: 185 | K31: 0 | L31: =IF(J31="","",K31*J31) | M31: =IF(OR(C31="",I31=""),"",I31/C31-1) | N31: لا مشتريات فى سبتمبر ⇒ سعر أغسطس ثابت
A32: قلب برازيلي | B32: 0 | C32: 245 | D32: =IF(C32="","",B32*C32) | E32: =SUMIF('مشتريات سبتمبر التفصيلية'!$I$4:$I$92,A32,'مشتريات سبتمبر التفصيلية'!$F$4:$F$92) | F32: =SUMIF('مشتريات سبتمبر التفصيلية'!$I$4:$I$92,A32,'مشتريات سبتمبر التفصيلية'!$H$4:$H$92) | G32: =IF(C32="",E32,B32+E32) | H32: =N(D32)+F32 | I32: =IF(G32>0,ROUND(H32/G32,4),IF(C32="","",C32)) | J32: 245 | K32: 0 | L32: =IF(J32="","",K32*J32) | M32: =IF(OR(C32="",I32=""),"",I32/C32-1) | N32: لا مشتريات فى سبتمبر ⇒ سعر أغسطس ثابت
A33: بوش | B33: 0 | C33: 110 | D33: =IF(C33="","",B33*C33) | E33: =SUMIF('مشتريات سبتمبر التفصيلية'!$I$4:$I$92,A33,'مشتريات سبتمبر التفصيلية'!$F$4:$F$92) | F33: =SUMIF('مشتريات سبتمبر التفصيلية'!$I$4:$I$92,A33,'مشتريات سبتمبر التفصيلية'!$H$4:$H$92) | G33: =IF(C33="",E33,B33+E33) | H33: =N(D33)+F33 | I33: =IF(G33>0,ROUND(H33/G33,4),IF(C33="","",C33)) | J33: 110 | K33: 0 | L33: =IF(J33="","",K33*J33) | M33: =IF(OR(C33="",I33=""),"",I33/C33-1) | N33: لا مشتريات فى سبتمبر ⇒ سعر أغسطس ثابت
A34: شعريه | B34: 0 | D34: =IF(C34="","",B34*C34) | E34: =SUMIF('مشتريات سبتمبر التفصيلية'!$I$4:$I$92,A34,'مشتريات سبتمبر التفصيلية'!$F$4:$F$92) | F34: =SUMIF('مشتريات سبتمبر التفصيلية'!$I$4:$I$92,A34,'مشتريات سبتمبر التفصيلية'!$H$4:$H$92) | G34: =IF(C34="",E34,B34+E34) | H34: =N(D34)+F34 | I34: =IF(G34>0,ROUND(H34/G34,4),IF(C34="","",C34)) | K34: 0 | L34: =IF(J34="","",K34*J34) | M34: =IF(OR(C34="",I34=""),"",I34/C34-1) | N34: بلا سعر — لا سعر أغسطس ولا مشتريات سبتمبر
A35: دقيق | B35: 0 | C35: 17.5 | D35: =IF(C35="","",B35*C35) | E35: =SUMIF('مشتريات سبتمبر التفصيلية'!$I$4:$I$92,A35,'مشتريات سبتمبر التفصيلية'!$F$4:$F$92) | F35: =SUMIF('مشتريات سبتمبر التفصيلية'!$I$4:$I$92,A35,'مشتريات سبتمبر التفصيلية'!$H$4:$H$92) | G35: =IF(C35="",E35,B35+E35) | H35: =N(D35)+F35 | I35: =IF(G35>0,ROUND(H35/G35,4),IF(C35="","",C35)) | J35: 20 | K35: 0 | L35: =IF(J35="","",K35*J35) | M35: =IF(OR(C35="",I35=""),"",I35/C35-1) | N35: قياسى: (أول المدة + المشتريات)
A36: نشا | B36: 400 | C36: 26.974 | D36: =IF(C36="","",B36*C36) | E36: =SUMIF('مشتريات سبتمبر التفصيلية'!$I$4:$I$92,A36,'مشتريات سبتمبر التفصيلية'!$F$4:$F$92) | F36: =SUMIF('مشتريات سبتمبر التفصيلية'!$I$4:$I$92,A36,'مشتريات سبتمبر التفصيلية'!$H$4:$H$92) | G36: =IF(C36="",E36,B36+E36) | H36: =N(D36)+F36 | I36: =IF(G36>0,ROUND(H36/G36,4),IF(C36="","",C36)) | J36: 28.3958 | K36: 53.5 | L36: =IF(J36="","",K36*J36) | M36: =IF(OR(C36="",I36=""),"",I36/C36-1) | N36: قياسى: (أول المدة + المشتريات)
A37: فلفل اسود | B37: 36.38 | C37: 336.2615 | D37: =IF(C37="","",B37*C37) | E37: =SUMIF('مشتريات سبتمبر التفصيلية'!$I$4:$I$92,A37,'مشتريات سبتمبر التفصيلية'!$F$4:$F$92) | F37: =SUMIF('مشتريات سبتمبر التفصيلية'!$I$4:$I$92,A37,'مشتريات سبتمبر التفصيلية'!$H$4:$H$92) | G37: =IF(C37="",E37,B37+E37) | H37: =N(D37)+F37 | I37: =IF(G37>0,ROUND(H37/G37,4),IF(C37="","",C37)) | J37: 337.9511 | K37: 12.5 | L37: =IF(J37="","",K37*J37) | M37: =IF(OR(C37="",I37=""),"",I37/C37-1) | N37: قياسى: (أول المدة + المشتريات)
A38: قرنفل | B38: 5.1 | C38: 510.4691 | D38: =IF(C38="","",B38*C38) | E38: =SUMIF('مشتريات سبتمبر التفصيلية'!$I$4:$I$92,A38,'مشتريات سبتمبر التفصيلية'!$F$4:$F$92) | F38: =SUMIF('مشتريات سبتمبر التفصيلية'!$I$4:$I$92,A38,'مشتريات سبتمبر التفصيلية'!$H$4:$H$92) | G38: =IF(C38="",E38,B38+E38) | H38: =N(D38)+F38 | I38: =IF(G38>0,ROUND(H38/G38,4),IF(C38="","",C38)) | J38: 510.1584 | K38: 8.1 | L38: =IF(J38="","",K38*J38) | M38: =IF(OR(C38="",I38=""),"",I38/C38-1) | N38: قياسى: (أول المدة + المشتريات)
A39: كمون | B39: 14.9 | C39: 251.5284 | D39: =IF(C39="","",B39*C39) | E39: =SUMIF('مشتريات سبتمبر التفصيلية'!$I$4:$I$92,A39,'مشتريات سبتمبر التفصيلية'!$F$4:$F$92) | F39: =SUMIF('مشتريات سبتمبر التفصيلية'!$I$4:$I$92,A39,'مشتريات سبتمبر التفصيلية'!$H$4:$H$92) | G39: =IF(C39="",E39,B39+E39) | H39: =N(D39)+F39 | I39: =IF(G39>0,ROUND(H39/G39,4),IF(C39="","",C39)) | J39: 251.5284 | K39: 11.15 | L39: =IF(J39="","",K39*J39) | M39: =IF(OR(C39="",I39=""),"",I39/C39-1) | N39: لا مشتريات فى سبتمبر ⇒ سعر أغسطس ثابت
A40: كرفس | B40: 0 | C40: 140 | D40: =IF(C40="","",B40*C40) | E40: =SUMIF('مشتريات سبتمبر التفصيلية'!$I$4:$I$92,A40,'مشتريات سبتمبر التفصيلية'!$F$4:$F$92) | F40: =SUMIF('مشتريات سبتمبر التفصيلية'!$I$4:$I$92,A40,'مشتريات سبتمبر التفصيلية'!$H$4:$H$92) | G40: =IF(C40="",E40,B40+E40) | H40: =N(D40)+F40 | I40: =IF(G40>0,ROUND(H40/G40,4),IF(C40="","",C40)) | J40: 140 | K40: 0 | L40: =IF(J40="","",K40*J40) | M40: =IF(OR(C40="",I40=""),"",I40/C40-1) | N40: لا مشتريات فى سبتمبر ⇒ سعر أغسطس ثابت
A41: كبابه | B41: 10.6 | C41: 529.0464 | D41: =IF(C41="","",B41*C41) | E41: =SUMIF('مشتريات سبتمبر التفصيلية'!$I$4:$I$92,A41,'مشتريات سبتمبر التفصيلية'!$F$4:$F$92) | F41: =SUMIF('مشتريات سبتمبر التفصيلية'!$I$4:$I$92,A41,'مشتريات سبتمبر التفصيلية'!$H$4:$H$92) | G41: =IF(C41="",E41,B41+E41) | H41: =N(D41)+F41 | I41: =IF(G41>0,ROUND(H41/G41,4),IF(C41="","",C41)) | J41: 529.0464 | K41: 9.7 | L41: =IF(J41="","",K41*J41) | M41: =IF(OR(C41="",I41=""),"",I41/C41-1) | N41: لا مشتريات فى سبتمبر ⇒ سعر أغسطس ثابت
...

Sheet مشتريات سبتمبر التفصيلية
A1: مشتريات الخامات — الفترة 01/09/2026 حتى 30/09/2026 (المصدر: تقرير المشتريات فى الفترة)
A3: م | B3: التاريخ | C3: كود الصنف | D3: اسم الصنف بالمشتريات | E3: الوحدة | F3: الكمية | G3: سعر الشراء | H3: الإجمالى | I3: الصنف المقابل بالجرد | J3: درجة الثقة | K3: أساس المطابقة | L3: رقم الفاتورة
A4: 1 | B4: 2026/09/02 | C4: 328 | D4: طعم سجق زيت | E4: طبق | F4: 8 | G4: 580 | H4: 4640 | I4: زيت سجق | J4: عالية | K4: طعم سجق «زيت» = بند «زيت سجق»؛ سعر 580 = متوسط أغسطس 580 | L4: 1111115206
A5: 2 | B5: 2026/09/02 | C5: 329 | D5: طعم بسطرمة زيت | E5: طبق | F5: 4 | G5: 820 | H5: 3280 | I5: زيوت بسطرمه | J5: عالية | K5: طعم بسطرمة «زيت» = بند «زيوت بسطرمه»؛ سعر 820 ≈ 784.14 لأغسطس | L5: 1111115206
A6: 3 | B6: 2026/09/02 | C6: 89 | D6: طعم ليه | E6: طبق | F6: 50 | G6: 295 | H6: 14750 | I6: طعم ليه | J6: عالية | K6: نفس ربط الكود فى يوليو: تطابق اسمى تام | L6: 1111115206
A7: 4 | B7: 2026/09/02 | C7: 222 | D7: طعم كفته | E7: طبق | F7: 50 | G7: 190 | H7: 9500 | I7: طعم كفته | J7: عالية | K7: نفس ربط الكود فى أغسطس: تطابق اسمى تام | L7: 1111115206
A8: 5 | B8: 2026/09/02 | C8: 235 | D8: طعم بيف | E8: طبق | F8: 100 | G8: 310 | H8: 31000 | I8: طعم بيف | J8: عالية | K8: نفس ربط الكود فى يوليو: تطابق اسمى تام | L8: 1111115206
A9: 6 | B9: 2026/09/02 | C9: 244 | D9: طعم شواي | E9: طبق | F9: 50 | G9: 295 | H9: 14750 | I9: طعم شواي | J9: عالية | K9: نفس ربط الكود فى يوليو: سعر الشراء 295.00 = سعر يونيه 295.00 | L9: 1111115206
A10: 7 | B10: 2026/09/03 | C10: 49 | D10: دهن | E10: طبق | F10: 1450 | G10: 60 | H10: 87000 | I10: دهن بلدي | J10: عالية | K10: نفس ربط الكود فى يوليو: بند الدهن الوحيد بالجرد | L10: 1111115212
A11: 8 | B11: 2026/09/05 | C11: 95 | D11: هانك | E11: طبق | F11: 400 | G11: 250 | H11: 100000 | I11: هانك | J11: عالية | K11: نفس ربط الكود فى يوليو: تطابق اسمى تام | L11: 1111115207
A12: 9 | B12: 2026/09/05 | C12: 379 | D12: بكرة لزق شفاف | E12: طبق | F12: 240 | G12: 30.83 | H12: 7400 | I12: لازق | J12: عالية | K12: بكرة لزق شفاف = «لازق»؛ سعر 30.83 ≈ 30.22 لأغسطس | L12: 1111115208
A13: 10 | B13: 2026/09/05 | C13: 443 | D13: اكياس تغليف استربس اسبشيال صغير | E13: كيلو | F13: 124.8 | G13: 125 | H13: 15600 | I13: أكياس استربس اسبيشيال ص | J13: عالية | K13: أكياس تغليف استربس اسبشيال صغير = «أكياس استربس اسبيشيال ص»؛ بلا سعر سابق | L13: 1111115209
A14: 11 | B14: 2026/09/05 | C14: 50 | D14: بصل | E14: طبق | F14: 740 | G14: 15 | H14: 11100 | I14: بصل | J14: عالية | K14: نفس ربط الكود فى يوليو: تطابق اسمى تام | L14: 1111115210
A15: 12 | B15: 2026/09/05 | C15: 334 | D15: فلنك | E15: طبق | F15: 200 | G15: 208 | H15: 41600 | I15: فلانك | J15: عالية | K15: نفس ربط الكود فى يوليو: فرق إملائى فقط (فلنك/فلانك) + نفس نطاق السعر | L15: 1111115211
... A92: 89 | B92: 2026/09/30 | C92: 95445 | D92: اطباق 4/3عام عام | E92: طبق | F92: 20000 | G92: 0.7 | H92: 14000 | I92: اطباق 3/4 | J92: عالية | K92: نفس ربط الكود فى يوليو: تطابق اسمى تام | L92: 1111115274
D94: إجمالى مشتريات سبتمبر | H94: =SUM(H4:H92)
D95: الإجمالى المطبوع بالتقرير | H95: 2217803.1
D96: منها: بلا مقابل بالجرد (مستبعدة) | H96: =SUMIF(I4:I92,"— بلا مقابل —",H4:H92)

Sheet رصيد أول المدة (31-8)
A1: رصيد أول المدة لسبتمبر = الجرد الفعلى المعدَّل 31/8 («جر د شهر 8.xlsx») × متوسط أغسطس
A2: متوسط أغسطس أُعيد احتسابه من مصادره (جرد 31/7 × متوسط يوليو + مشتريات أغسطس) وطوبق مع ملف «تسعير جرد اخر شهر ٨ -2».
A4: الصنف بجرد 31/8 | B4: كمية الجرد 31/8 | C4: متوسط أغسطس (إعادة احتساب) | D4: متوسط أغسطس بملف «-2» | E4: كمية الصنف بملف «-2» | F4: قيمة أول المدة | G4: مطابقة السعر | H4: ملاحظة
A5: بصل | B5: 500 | C5: 13.7773 | D5: 13.7773 | E5: 500 | F5: =IF(C5="","",B5*C5) | G5: =IF(OR(C5="",D5=""),"",IF(ABS(C5-D5)<0.00005,"✔","✘"))
A6: ثوم | B6: 1249.55 | C6: 25.0724 | D6: 25.0724 | E6: 1249.3 | F6: =IF(C6="","",B6*C6) | G6: =IF(OR(C6="",D6=""),"",IF(ABS(C6-D6)<0.00005,"✔","✘"))
A7: فلفل بارد | B7: 320 | C7: 9.1171 | D7: 9.1171 | E7: 320 | F7: =IF(C7="","",B7*C7) | G7: =IF(OR(C7="",D7=""),"",IF(ABS(C7-D7)<0.00005,"✔","✘"))
A8: مفروم فراخ شعبي | B8: 2120 | C8: 28.386 | D8: 28.386 | E8: 2120 | F8: =IF(C8="","",B8*C8) | G8: =IF(OR(C8="",D8=""),"",IF(ABS(C8-D8)<0.00005,"✔","✘"))
A9: صميد | B9: 1241 | C9: 16.1708 | D9: 16.1708 | E9: 1241 | F9: =IF(C9="","",B9*C9) | G9: =IF(OR(C9="",D9=""),"",IF(ABS(C9-D9)<0.00005,"✔","✘"))
A10: صويا لحمه | B10: 777 | C10: 36.8234 | D10: 36.8234 | E10: 777 | F10: =IF(C10="","",B10*C10) | G10: =IF(OR(C10="",D10=""),"",IF(ABS(C10-D10)<0.00005,"✔","✘"))
A11: صويا اوزيليت | B11: 151.5 | C11: 168.445 | D11: 168.445 | E11: 151.5 | F11: =IF(C11="","",B11*C11) | G11: =IF(OR(C11="",D11=""),"",IF(ABS(C11-D11)<0.00005,"✔","✘"))
A12: مفروم فراخ فاخر | B12: 415 | C12: 55.082 | D12: 55.082 | E12: 415 | F12: =IF(C12="","",B12*C12) | G12: =IF(OR(C12="",D12=""),"",IF(ABS(C12-D12)<0.00005,"✔","✘"))
A13: دهن بلدي | B13: 1754.85 | C13: 53.8106 | D13: 53.8106 | E13: 1754.85 | F13: =IF(C13="","",B13*C13) | G13: =IF(OR(C13="",D13=""),"",IF(ABS(C13-D13)<0.00005,"✔","✘"))
A14: لحم كتف | B14: 40 | C14: 253.0246 | D14: 253.0246 | E14: 40 | F14: =IF(C14="","",B14*C14) | G14: =IF(OR(C14="",D14=""),"",IF(ABS(C14-D14)<0.00005,"✔","✘"))
A15: لحم رقبه | B15: 60 | C15: 253.0246 | D15: 253.0246 | E15: 60 | F15: =IF(C15="","",B15*C15) | G15: =IF(OR(C15="",D15=""),"",IF(ABS(C15-D15)<0.00005,"✔","✘"))
A16: لحم سن | B16: 20 | C16: 253.0246 | D16: 253.0246 | E16: 20 | F16: =IF(C16="","",B16*C16) | G16: =IF(OR(C16="",D16=""),"",IF(ABS(C16-D16)<0.00005,"✔","✘"))
A17: لحمه ارباع | B17: 25 | C17: 253.0246 | D17: 253.0246 | E17: 25 | F17: =IF(C17="","",B17*C17) | G17: =IF(OR(C17="",D17=""),"",IF(ABS(C17-D17)<0.00005,"✔","✘"))
A18: سمانة هندي | B18: 0 | E18: 0 | F18: =IF(C18="","",B18*C18) | G18: =IF(OR(C18="",D18=""),"",IF(ABS(C18-D18)<0.00005,"✔","✘"))
A19: فلانك | B19: 110 | C19: 198.3869 | D19: 198.3869 | E19: 110 | F19: =IF(C19="","",B19*C19) | G19: =IF(OR(C19="",D19=""),"",IF(ABS(C19-D19)<0.00005,"✔","✘")) | H19: بملف «-2» وجرد سبتمبر باسم «فلانك + مجمل رصيد اللحمة بالنفق»
A20: برغل | B20: 3325 | C20: 21.2509 | D20: 21.2509 | E20: 3325 | F20: =IF(C20="","",B20*C20) | G20: =IF(OR(C20="",D20=""),"",IF(ABS(C20-D20)<0.00005,"✔","✘"))
A21: صويا فراخ | B21: 180 | C21: 46.8182 | D21: 46.8182 | E21: 180 | F21: =IF(C21="","",B21*C21) | G21: =IF(OR(C21="",D21=""),"",IF(ABS(C21-D21)<0.00005,"✔","✘"))
A22: كبده | B22: 63.304 | C22: 164.7217 | D22: 164.7217 | E22: 63.3 | F22: =IF(C22="","",B22*C22) | G22: =IF(OR(C22="",D22=""),"",IF(ABS(C22-D22)<0.00005,"✔","✘"))
A23: جلد | B23: 359 | C23: 28.8872 | D23: 28.8872 | E23: 359 | F23: =IF(C23="","",B23*C23) | G23: =IF(OR(C23="",D23=""),"",IF(ABS(C23-D23)<0.00005,"✔","✘"))
A24: هانك | B24: 118 | C24: 248.9842 | D24: 248.9842 | E24: 118 | F24: =IF(C24="","",B24*C24) | G24: =IF(OR(C24="",D24=""),"",IF(ABS(C24-D24)<0.00005,"✔","✘"))
A25: دوبريه | B25: 470 | C25: 95.2993 | D25: 95.2993 | E25: 470 | F25: =IF(C25="","",B25*C25) | G25: =IF(OR(C25="",D25=""),"",IF(ABS(C25-D25)<0.00005,"✔","✘"))
A26: فلفل رومي حامي | B26: 15.7 | C26: 14.6228 | D26: 14.6228 | E26: 15.7 | F26: =IF(C26="","",B26*C26) | G26: =IF(OR(C26="",D26=""),"",IF(ABS(C26-D26)<0.00005,"✔","✘"))
A27: فيليه | B27: 0 | C27: 195 | D27: 195 | E27: 0 | F27: =IF(C27="","",B27*C27) | G27: =IF(OR(C27="",D27=""),"",IF(ABS(C27-D27)<0.00005,"✔","✘"))
A28: بقسماط اصفر | B28: 0 | C28: 38.5 | D28: 38.5 | E28: 0 | F28: =IF(C28="","",B28*C28) | G28: =IF(OR(C28="",D28=""),"",IF(ABS(C28-D28)<0.00005,"✔","✘"))
A29: بقسماط ابيض | B29: 0 | E29: 0 | F29: =IF(C29="","",B29*C29) | G29: =IF(OR(C29="",D29=""),"",IF(ABS(C29-D29)<0.00005,"✔","✘"))
A30: بطاطس | B30: 0 | E30: 0 | F30: =IF(C30="","",B30*C30) | G30: =IF(OR(C30="",D30=""),"",IF(ABS(C30-D30)<0.00005,"✔","✘"))
A31: دوبرية بسطرمة (لحمة) | B31: 0 | C31: 185 | D31: 185 | E31: 0 | F31: =IF(C31="","",B31*C31) | G31: =IF(OR(C31="",D31=""),"",IF(ABS(C31-D31)<0.00005,"✔","✘"))
A32: قلب برازيلي | B32: 0 | C32: 245 | D32: 245 | E32: 0 | F32: =IF(C32="","",B32*C32) | G32: =IF(OR(C32="",D32=""),"",IF(ABS(C32-D32)<0.00005,"✔","✘"))
A33: بوش | B33: 0 | C33: 110 | D33: 110 | E33: 0 | F33: =IF(C33="","",B33*C33) | G33: =IF(OR(C33="",D33=""),"",IF(ABS(C33-D33)<0.00005,"✔","✘"))
A34: شعريه | B34: 0 | E34: 0 | F34: =IF(C34="","",B34*C34) | G34: =IF(OR(C34="",D34=""),"",IF(ABS(C34-D34)<0.00005,"✔","✘"))
A35: دقيق | B35: 0 | C35: 17.5 | D35: 17.5 | E35: 0 | F35: =IF(C35="","",B35*C35) | G35: =IF(OR(C35="",D35=""),"",IF(ABS(C35-D35)<0.00005,"✔","✘"))
A36: نشا | B36: 400 | C36: 26.974 | D36: 26.974 | E36: 400 | F36: =IF(C36="","",B36*C36) | G36: =IF(OR(C36="",D36=""),"",IF(ABS(C36-D36)<0.00005,"✔","✘"))
A37: فلفل اسود | B37: 36.38 | C37: 336.2615 | D37: 336.2615 | E37: 36.38 | F37: =IF(C37="","",B37*C37) | G37: =IF(OR(C37="",D37=""),"",IF(ABS(C37-D37)<0.00005,"✔","✘"))
A38: قرنفل | B38: 5.1 | C38: 510.4691 | D38: 510.4691 | E38: 5.1 | F38: =IF(C38="","",B38*C38) | G38: =IF(OR(C38="",D38=""),"",IF(ABS(C38-D38)<0.00005,"✔","✘"))
A39: كمون | B39: 14.9 | C39: 251.5284 | D39: 251.5284 | E39: 14.9 | F39: =IF(C39="","",B39*C39) | G39: =IF(OR(C39="",D39=""),"",IF(ABS(C39-D39)<0.00005,"✔","✘"))
A40: كرفس | B40: 0 | C40: 140 | D40: 140 | E40: 0 | F40: =IF(C40="","",B40*C40) | G40: =IF(OR(C40="",D40=""),"",IF(ABS(C40-D40)<0.00005,"✔","✘"))
A41: كبابه | B41: 10.6 | C41: 529.0464 | D41: 529.0464 | E41: 10.6 | F41: =IF(C41="","",B41*C41) | G41: =IF(OR(C41="",D41=""),"",IF(ABS(C41-D41)<0.00005,"✔","✘"))
...

Sheet تفصيل الوصفات بأسعار سبتمبر
A1: تفصيل وصفات التصنيع بأسعار خامات سبتمبر (نفس كميات ومعاملات إنتاجية وصفات يونيه)
A3: الوصفة | B3: القسم | C3: الخامة بالوصفة | D3: الصنف المقابل بالجرد | E3: الكمية (كجم) | F3: سعر سبتمبر | G3: القيمة | H3: ملاحظة
A4: سجق ابوهاشم | B4: خلطة فرعية (توابل) | C4: فوسفات | D4: فوسفات | E4: 0.3 | F4: ='احتساب متوسط سبتمبر'!I56 | G4: =E4*F4 | H4: مطابقة سعر يونيه بالوصفة مع سعر الصنف بالجرد
A5: سجق ابوهاشم | B5: خلطة فرعية (توابل) | C5: جلتومات | D5: جلتومات | E5: 0.32 | F5: ='احتساب متوسط سبتمبر'!I57 | G5: =E5*F5 | H5: مطابقة سعر يونيه بالوصفة مع سعر الصنف بالجرد
A6: سجق ابوهاشم | B6: خلطة فرعية (توابل) | C6: طعم بسطرمة | D6: زيوت بسطرمه | E6: 0.04 | F6: ='احتساب متوسط سبتمبر'!I72 | G6: =E6*F6 | H6: مطابقة سعر يونيه بالوصفة مع سعر الصنف بالجرد
A7: سجق ابوهاشم | B7: خلطة فرعية (توابل) | C7: طعم سجق | D7: طعم سجق بودر | E7: 0.06 | F7: ='احتساب متوسط سبتمبر'!I58 | G7: =E7*F7 | H7: مطابقة سعر يونيه بالوصفة مع سعر الصنف بالجرد
A8: سجق ابوهاشم | B8: خلطة فرعية (توابل) | C8: فلفل اسود | D8: فلفل اسود | E8: 0.08 | F8: ='احتساب متوسط سبتمبر'!I37 | G8: =E8*F8 | H8: مطابقة سعر يونيه بالوصفة مع سعر الصنف بالجرد
A9: سجق ابوهاشم | B9: خلطة فرعية (توابل) | C9: كزبرة | D9: كزبره | E9: 0 | F9: ='احتساب متوسط سبتمبر'!I45 | G9: =E9*F9 | H9: مطابقة سعر يونيه بالوصفة مع سعر الصنف بالجرد
A10: سجق ابوهاشم | B10: خلطة فرعية (توابل) | C10: بابريكا | D10: بابريكا | E10: 0.15 | F10: ='احتساب متوسط سبتمبر'!I53 | G10: =E10*F10 | H10: مطابقة سعر يونيه بالوصفة مع سعر الصنف بالجرد
A11: سجق ابوهاشم | B11: خلطة فرعية (توابل) | C11: حلبه | D11: — | E11: 0 | F11: 0 | G11: =E11*F11 | H11: صنف غير موجود ضمن قاعدة بيانات الخامات المُسعّرة
A12: سجق ابوهاشم | B12: خلطة فرعية (توابل) | C12: قرنفل | D12: قرنفل | E12: 0.04 | F12: ='احتساب متوسط سبتمبر'!I38 | G12: =E12*F12 | H12: مطابقة سعر يونيه بالوصفة مع سعر الصنف بالجرد
A13: سجق ابوهاشم | B13: خلطة فرعية (توابل) | C13: قرفه | D13: قرفه | E13: 0.1 | F13: ='احتساب متوسط سبتمبر'!I46 | G13: =E13*F13 | H13: مطابقة سعر يونيه بالوصفة مع سعر الصنف بالجرد
A14: سجق ابوهاشم | B14: خلطة فرعية (توابل) | C14: شطه | D14: شطه | E14: 0.1 | F14: ='احتساب متوسط سبتمبر'!I48 | G14: =E14*F14 | H14: مطابقة سعر يونيه بالوصفة مع سعر الصنف بالجرد
A15: سجق ابوهاشم | B15: خلطة فرعية (توابل) | C15: ملح | D15: الملح | E15: 1.8 | F15: ='احتساب متوسط سبتمبر'!I55 | G15: =E15*F15 | H15: مطابقة سعر يونيه بالوصفة مع سعر الصنف بالجرد
A16: سجق ابوهاشم | B16: خلطة فرعية (توابل) | C16: ينسون | D16: ينسون | E16: 0.1 | F16: ='احتساب متوسط سبتمبر'!I50 | G16: =E16*F16 | H16: مطابقة سعر يونيه بالوصفة مع سعر الصنف بالجرد
A17: سجق ابوهاشم | B17: خلطة فرعية (توابل) | C17: لون | D17: لون طبيعي | E17: 0.15 | F17: ='احتساب متوسط سبتمبر'!I70 | G17: =E17*F17 | H17: مطابقة سعر يونيه بالوصفة مع سعر الصنف بالجرد
A18: سجق ابوهاشم | B18: خلطة فرعية (توابل) | C18: حبهان | D18: حبهان | E18: 0.03 | F18: ='احتساب متوسط سبتمبر'!I51 | G18: =E18*F18 | H18: مطابقة سعر يونيه بالوصفة مع سعر الصنف بالجرد
A19: سجق ابوهاشم | B19: إجمالى خلطة فرعية (توابل) | E19: =SUM(E4:E18) | F19: =G19/E19 | G19: =SUM(G4:G18)
A21: سجق ابوهاشم | B21: الوصفة الرئيسية | C21: مفروم فراخ فاخر | D21: مفروم فراخ فاخر | E21: 20 | F21: ='احتساب متوسط سبتمبر'!C12 | G21: =E21*F21 | H21: مؤقت: سعر أغسطس لحين حسم فاتورة الفراخ المفرومة
A22: سجق ابوهاشم | B22: الوصفة الرئيسية | C22: بصل | D22: بصل | E22: 10 | F22: ='احتساب متوسط سبتمبر'!I5 | G22: =E22*F22 | H22: مطابقة سعر يونيه بالوصفة مع سعر الصنف بالجرد
A23: سجق ابوهاشم | B23: الوصفة الرئيسية | C23: دهن | D23: دهن بلدي | E23: 10 | F23: ='احتساب متوسط سبتمبر'!I13 | G23: =E23*F23 | H23: مطابقة سعر يونيه بالوصفة مع سعر الصنف بالجرد
A24: سجق ابوهاشم | B24: الوصفة الرئيسية | C24: فلانك | D24: فلانك | E24: 20 | F24: ='احتساب متوسط سبتمبر'!I19 | G24: =E24*F24 | H24: مطابقة سعر يونيه بالوصفة مع سعر الصنف بالجرد
A25: سجق ابوهاشم | B25: الوصفة الرئيسية | C25: فلفل | D25: — | E25: 0 | F25: 0 | G25: =E25*F25 | H25: غير محدد النوع (فلفل اسود/احمر/اخضر) — لا يمكن تحديد سعر بدقة دون توضيح
A26: سجق ابوهاشم | B26: الوصفة الرئيسية | C26: توام | D26: ثوم | E26: 2 | F26: ='احتساب متوسط سبتمبر'!I6 | G26: =E26*F26 | H26: مطابقة سعر يونيه بالوصفة مع سعر الصنف بالجرد
A27: سجق ابوهاشم | B27: الوصفة الرئيسية | C27: صويا | D27: صويا لحمه | E27: 10 | F27: ='احتساب متوسط سبتمبر'!I10 | G27: =E27*F27 | H27: مطابقة سعر يونيه بالوصفة مع سعر الصنف بالجرد
A28: سجق ابوهاشم | B28: الوصفة الرئيسية | C28: بطاطس | D28: — | E28: 0 | F28: 0 | G28: =E28*F28 | H28: صنف غير موجود ضمن قاعدة بيانات الخامات المُسعّرة
A29: سجق ابوهاشم | B29: الوصفة الرئيسية | C29: برغل | D29: برغل | E29: 4 | F29: ='احتساب متوسط سبتمبر'!I20 | G29: =E29*F29 | H29: مطابقة سعر يونيه بالوصفة مع سعر الصنف بالجرد
A30: سجق ابوهاشم | B30: الوصفة الرئيسية | C30: جلد | D30: جلد | E30: 10 | F30: ='احتساب متوسط سبتمبر'!I23 | G30: =E30*F30 | H30: مطابقة سعر يونيه بالوصفة مع سعر الصنف بالجرد
A31: سجق ابوهاشم | B31: الوصفة الرئيسية | C31: مايه | D31: — | E31: 28 | F31: 0 | G31: =E31*F31 | H31: لا يوجد سعر شراء مسجل للمياه ضمن الخامات — عادة تكلفة مرافق غير مباشرة
A32: سجق ابوهاشم | B32: الوصفة الرئيسية | C32: دوبريه | D32: دوبريه | E32: 10 | F32: ='احتساب متوسط سبتمبر'!I25 | G32: =E32*F32 | H32: مطابقة سعر يونيه بالوصفة مع سعر الصنف بالجرد
A33: سجق ابوهاشم | B33: الوصفة الرئيسية | C33: نشا | D33: نشا | E33: 0 | F33: ='احتساب متوسط سبتمبر'!I36 | G33: =E33*F33 | H33: مطابقة سعر يونيه بالوصفة مع سعر الصنف بالجرد
A34: سجق ابوهاشم | B34: الوصفة الرئيسية | C34: توابيل | D34: سعر كجم الخلطة الفرعية | E34: 3.12 | F34: =F19 | G34: =E34*F34 | H34: سعر كجم الخلطة الفرعية
A35: سجق ابوهاشم | B35: إجمالى الوصفة الرئيسية | E35: =SUM(E21:E34) | G35: =SUM(G21:G34) | H35: سعر الكجم = قيمة الوصفة ÷ 98.96 كجم
A37: كفته ابوهاشم | B37: خلطة فرعية (توابل) | C37: فوسفات | D37: فوسفات | E37: 0.4 | F37: ='احتساب متوسط سبتمبر'!I56 | G37: =E37*F37 | H37: مطابقة سعر يونيه بالوصفة مع سعر الصنف بالجرد
A38: كفته ابوهاشم | B38: خلطة فرعية (توابل) | C38: مونوصوديم | D38: جلتومات | E38: 0.3 | F38: ='احتساب متوسط سبتمبر'!I57 | G38: =E38*F38 | H38: مطابقة سعر يونيه بالوصفة مع سعر الصنف بالجرد
A39: كفته ابوهاشم | B39: خلطة فرعية (توابل) | C39: طعم كفته | D39: طعم كفته | E39: 0 | F39: ='احتساب متوسط سبتمبر'!I61 | G39: =E39*F39 | H39: مطابقة سعر يونيه بالوصفة مع سعر الصنف بالجرد
A40: كفته ابوهاشم | B40: خلطة فرعية (توابل) | C40: طعم شواء | D40: طعم شواي | E40: 0.1 | F40: ='احتساب متوسط سبتمبر'!I64 | G40: =E40*F40 | H40: مطابقة سعر يونيه بالوصفة مع سعر الصنف بالجرد
A41: كفته ابوهاشم | B41: خلطة فرعية (توابل) | C41: طعم بيف | D41: طعم بيف | E41: 0.1 | F41: ='احتساب متوسط سبتمبر'!I63 | G41: =E41*F41 | H41: مطابقة سعر يونيه بالوصفة مع سعر الصنف بالجرد
A42: كفته ابوهاشم | B42: خلطة فرعية (توابل) | C42: خلنجان | D42: خلنجان | E42: 0 | F42: ='احتساب متوسط سبتمبر'!I44 | G42: =E42*F42 | H42: مطابقة سعر يونيه بالوصفة مع سعر الصنف بالجرد
A43: كفته ابوهاشم | B43: خلطة فرعية (توابل) | C43: فلفل اسود | D43: فلفل اسود | E43: 0.3 | F43: ='احتساب متوسط سبتمبر'!I37 | G43: =E43*F43 | H43: مطابقة سعر يونيه بالوصفة مع سعر الصنف بالجرد
...

Sheet سعر الكجم من الوصفات
A1: سعر كيلو الخلطة لكل منتج (خامات مباشرة فقط) — أغسطس مقابل سبتمبر
A3: المنتج | B3: العلامة | C3: قيمة الوصفة (أغسطس) | D3: قيمة الوصفة (سبتمبر) | E3: سعر الكجم (أغسطس) | F3: سعر الكجم (سبتمبر) | G3: التغير % | H3: معامل الإنتاجية (كجم)
A4: سجق ابوهاشم | B4: أبو هاشم | C4: 8167.9465 | D4: ='تفصيل الوصفات بأسعار سبتمبر'!G35 | E4: 82.537832 | F4: =D4/H4 | G4: =F4/E4-1 | H4: 98.960031
A5: كفته ابوهاشم | B5: أبو هاشم | C5: 6204.1825 | D5: ='تفصيل الوصفات بأسعار سبتمبر'!G68 | E5: 79.034172 | F5: =D5/H5 | G5: =F5/E5-1 | H5: 78.5
A6: برجر ابوهاشم | B6: أبو هاشم | C6: 4776.136 | D6: ='تفصيل الوصفات بأسعار سبتمبر'!G98 | E6: 76.229127 | F6: =D6/H6 | G6: =F6/E6-1 | H6: 62.655
A7: برجر اسبشيال | B7: سبيشال | C7: 9320.5612 | D7: ='تفصيل الوصفات بأسعار سبتمبر'!G123 | E7: 23.632854 | F7: =D7/H7 | G7: =F7/E7-1 | H7: 394.39
A8: سجق اسبشيال | B8: سبيشال | C8: 5610.9726 | D8: ='تفصيل الوصفات بأسعار سبتمبر'!G149 | E8: 24.538617 | F8: =D8/H8 | G8: =F8/E8-1 | H8: 228.65888
A9: كفته اسبشيال | B9: سبيشال | C9: 11366.585 | D9: ='تفصيل الوصفات بأسعار سبتمبر'!G179 | E9: 31.107238 | F9: =D9/H9 | G9: =F9/E9-1 | H9: 365.4
A10: سجق الهنا | B10: الهنا | C10: 5372.8626 | D10: ='تفصيل الوصفات بأسعار سبتمبر'!G206 | E10: 23.641919 | F10: =D10/H10 | G10: =F10/E10-1 | H10: 227.26
A11: برجر الهنا | B11: الهنا | C11: 10415.404 | D11: ='تفصيل الوصفات بأسعار سبتمبر'!G227 | E11: 24.216802 | F11: =D11/H11 | G11: =F11/E11-1 | H11: 430.09
A12: كفته الهنا | B12: الهنا | C12: 9320.5612 | D12: ='تفصيل الوصفات بأسعار سبتمبر'!G252 | E12: 23.632854 | F12: =D12/H12 | G12: =F12/E12-1 | H12: 394.39

Sheet المنتج التام آخر سبتمبر
A1: تقييم مخزون المنتج التام آخر سبتمبر 2026 (الوصفات بأسعار خامات سبتمبر + تكلفة التعبئة)
A3: اسم الصنف | B3: كمية الجرد 30/9 | C3: سعر أغسطس | D3: سعر سبتمبر | E3: التغير % | F3: قيمة المخزون 30/9 | G3: ملاحظة
A4: مفروم ابو هاشم 350 | B4: 145 | C4: 84.61 | D4: 84.61 | E4: =IF(OR(C4="",D4=""),"",D4/C4-1) | F4: =IF(D4="","",B4*D4) | G4: خارج الوصفات التسع — آخر سعر متاح (أغسطس، ملف «-2»): خارج نطاق الوصفات التسع — سعر يوليو مُبقًى دون تحديث
A5: مفروم صافي ابوهاشم 500 | B5: 0 | C5: 126 | D5: 126 | E5: =IF(OR(C5="",D5=""),"",D5/C5-1) | F5: =IF(D5="","",B5*D5) | G5: خارج الوصفات التسع — آخر سعر متاح (أغسطس، ملف «-2»): خارج نطاق الوصفات التسع — سعر يوليو مُبقًى دون تحديث
A6: كبده اسكندراني 370 | B6: 248 | C6: 64.1 | D6: 64.1 | E6: =IF(OR(C6="",D6=""),"",D6/C6-1) | F6: =IF(D6="","",B6*D6) | G6: خارج الوصفات التسع — آخر سعر متاح (أغسطس، ملف «-2»): خارج نطاق الوصفات التسع — سعر يوليو مُبقًى دون تحديث
A7: سجق ابوهاشم 3ك | B7: 111 | C7: 256.8435 | D7: =ROUND(3*'سعر الكجم من الوصفات'!F4+9.23,4) | E7: =IF(OR(C7="",D7=""),"",D7/C7-1) | F7: =IF(D7="","",B7*D7) | G7: من وصفة «سجق ابوهاشم»: 3 كجم × سعر كجم سبتمبر + تعبئة 9.23 ج.م | مؤقت: الوصفة تستخدم مفروم الفراخ بسعر أغسطس لحين حسم الفاتورة
A8: سجق ابوهاشم 1ك | B8: 0 | C8: 82.5378 | D8: =ROUND(1*'سعر الكجم من الوصفات'!F4+0,4) | E8: =IF(OR(C8="",D8=""),"",D8/C8-1) | F8: =IF(D8="","",B8*D8) | G8: من وصفة «سجق ابوهاشم»: 1 كجم × سعر كجم سبتمبر بدون تكلفة تعبئة (غير محددة بالوصفة) | مؤقت: الوصفة تستخدم مفروم الفراخ بسعر أغسطس لحين حسم الفاتورة
A9: سجق ابوهاشم 800 | B9: 101 | C9: 72.3003 | D9: =ROUND(0.8*'سعر الكجم من الوصفات'!F4+6.27,4) | E9: =IF(OR(C9="",D9=""),"",D9/C9-1) | F9: =IF(D9="","",B9*D9) | G9: من وصفة «سجق ابوهاشم»: 0.8 كجم × سعر كجم سبتمبر + تعبئة 6.27 ج.م | مؤقت: الوصفة تستخدم مفروم الفراخ بسعر أغسطس لحين حسم الفاتورة
A10: سجق ابوهاشم 350 | B10: 36 | C10: 33.5583 | D10: =ROUND(0.35*'سعر الكجم من الوصفات'!F4+4.67,4) | E10: =IF(OR(C10="",D10=""),"",D10/C10-1) | F10: =IF(D10="","",B10*D10) | G10: من وصفة «سجق ابوهاشم»: 0.35 كجم × سعر كجم سبتمبر + تعبئة 4.67 ج.م | مؤقت: الوصفة تستخدم مفروم الفراخ بسعر أغسطس لحين حسم الفاتورة
A11: كفته ابوهاشم 800 | B11: 23 | C11: 68.579 | D11: =ROUND(0.8*'سعر الكجم من الوصفات'!F5+5.35,4) | E11: =IF(OR(C11="",D11=""),"",D11/C11-1) | F11: =IF(D11="","",B11*D11) | G11: من وصفة «كفته ابوهاشم»: 0.8 كجم × سعر كجم سبتمبر + تعبئة 5.35 ج.م | مؤقت: الوصفة تستخدم مفروم الفراخ بسعر أغسطس لحين حسم الفاتورة
A12: كفته ابوهاشم 350 | B12: 34 | C12: 32.1627 | D12: =ROUND(0.35*'سعر الكجم من الوصفات'!F5+4.5,4) | E12: =IF(OR(C12="",D12=""),"",D12/C12-1) | F12: =IF(D12="","",B12*D12) | G12: من وصفة «كفته ابوهاشم»: 0.35 كجم × سعر كجم سبتمبر + تعبئة 4.50 ج.م | مؤقت: الوصفة تستخدم مفروم الفراخ بسعر أغسطس لحين حسم الفاتورة
A13: برجر ابوهاشم 1.5 | B13: 18 | C13: 120.4126 | D13: =ROUND(1.5*'سعر الكجم من الوصفات'!F6+6.07,4) | E13: =IF(OR(C13="",D13=""),"",D13/C13-1) | F13: =IF(D13="","",B13*D13) | G13: من وصفة «برجر ابوهاشم»: 1.5 كجم × سعر كجم سبتمبر + تعبئة 6.07 ج.م | مؤقت: الوصفة تستخدم مفروم الفراخ بسعر أغسطس لحين حسم الفاتورة
A14: برجر ابوهاشم1100 | B14: 0 | C14: 83.852 | D14: =ROUND(1.1*'سعر الكجم من الوصفات'!F6+0,4) | E14: =IF(OR(C14="",D14=""),"",D14/C14-1) | F14: =IF(D14="","",B14*D14) | G14: من وصفة «برجر ابوهاشم»: 1.1 كجم × سعر كجم سبتمبر بدون تكلفة تعبئة (غير محددة بالوصفة) | مؤقت: الوصفة تستخدم مفروم الفراخ بسعر أغسطس لحين حسم الفاتورة
A15: برجر ابو هاشم 800 | B15: 0 | C15: 60.9833 | D15: =ROUND(0.8*'سعر الكجم من الوصفات'!F6+0,4) | E15: =IF(OR(C15="",D15=""),"",D15/C15-1) | F15: =IF(D15="","",B15*D15) | G15: من وصفة «برجر ابوهاشم»: 0.8 كجم × سعر كجم سبتمبر بدون تكلفة تعبئة (غير محددة بالوصفة) | مؤقت: الوصفة تستخدم مفروم الفراخ بسعر أغسطس لحين حسم الفاتورة
A16: برجر ابوهاشم 600 | B16: 0 | C16: 51.7274 | D16: =ROUND(0.6*'سعر الكجم من الوصفات'!F6+5.99,4) | E16: =IF(OR(C16="",D16=""),"",D16/C16-1) | F16: =IF(D16="","",B16*D16) | G16: من وصفة «برجر ابوهاشم»: 0.6 كجم × سعر كجم سبتمبر + تعبئة 5.99 ج.م | مؤقت: الوصفة تستخدم مفروم الفراخ بسعر أغسطس لحين حسم الفاتورة
A17: برجر ابوهاشم 400 | B17: 121 | C17: 35.4817 | D17: =ROUND(0.4*'سعر الكجم من الوصفات'!F6+4.99,4) | E17: =IF(OR(C17="",D17=""),"",D17/C17-1) | F17: =IF(D17="","",B17*D17) | G17: من وصفة «برجر ابوهاشم»: 0.4 كجم × سعر كجم سبتمبر + تعبئة 4.99 ج.م | مؤقت: الوصفة تستخدم مفروم الفراخ بسعر أغسطس لحين حسم الفاتورة
A18: شاورما 400 | B18: 0 | E18: =IF(OR(C18="",D18=""),"",D18/C18-1) | F18: =IF(D18="","",B18*D18) | G18: بلا وصفة ولا سعر سابق — يلزم توفير سعره
A19: بفتيك 400 | B19: 0 | E19: =IF(OR(C19="",D19=""),"",D19/C19-1) | F19: =IF(D19="","",B19*D19) | G19: بلا وصفة ولا سعر سابق — يلزم توفير سعره
A20: قطع 400 | B20: 0 | E20: =IF(OR(C20="",D20=""),"",D20/C20-1) | F20: =IF(D20="","",B20*D20) | G20: بلا وصفة ولا سعر سابق — يلزم توفير سعره
A21: قطع 800 | B21: 0 | E21: =IF(OR(C21="",D21=""),"",D21/C21-1) | F21: =IF(D21="","",B21*D21) | G21: بلا وصفة ولا سعر سابق — يلزم توفير سعره
A22: مفروم ابو هاشم 3 ك | B22: 9 | E22: =IF(OR(C22="",D22=""),"",D22/C22-1) | F22: =IF(D22="","",B22*D22) | G22: بلا وصفة ولا سعر سابق — يلزم توفير سعره
A23: سجق ابو هاشم 2 ك | B23: 0 | C23: 165.0757 | D23: =ROUND(2*'سعر الكجم من الوصفات'!F4+0,4) | E23: =IF(OR(C23="",D23=""),"",D23/C23-1) | F23: =IF(D23="","",B23*D23) | G23: من وصفة «سجق ابوهاشم»: 2 كجم × سعر كجم سبتمبر بدون تكلفة تعبئة (غير محددة بالوصفة) | مؤقت: الوصفة تستخدم مفروم الفراخ بسعر أغسطس لحين حسم الفاتورة
A24: كبده امريكي3 ك | B24: 0 | E24: =IF(OR(C24="",D24=""),"",D24/C24-1) | F24: =IF(D24="","",B24*D24) | G24: بلا وصفة ولا سعر سابق — يلزم توفير سعره
A25: مفروم صويا-بروتين 400 ش | B25: 0 | E25: =IF(OR(C25="",D25=""),"",D25/C25-1) | F25: =IF(D25="","",B25*D25) | G25: بلا وصفة ولا سعر سابق — يلزم توفير سعره
A26: مفروم صويا-بروتين 400 علب | B26: 0 | E26: =IF(OR(C26="",D26=""),"",D26/C26-1) | F26: =IF(D26="","",B26*D26) | G26: بلا وصفة ولا سعر سابق — يلزم توفير سعره
A27: برجر ابوهاشم 1200 | B27: 0 | C27: 97.655 | D27: =ROUND(1.2*'سعر الكجم من الوصفات'!F6+6.18,4) | E27: =IF(OR(C27="",D27=""),"",D27/C27-1) | F27: =IF(D27="","",B27*D27) | G27: من وصفة «برجر ابوهاشم»: 1.2 كجم × سعر كجم سبتمبر + تعبئة 6.18 ج.م | مؤقت: الوصفة تستخدم مفروم الفراخ بسعر أغسطس لحين حسم الفاتورة
A28: كبده اك | B28: 0 | E28: =IF(OR(C28="",D28=""),"",D28/C28-1) | F28: =IF(D28="","",B28*D28) | G28: بلا وصفة ولا سعر سابق — يلزم توفير سعره
A29: برجر ابوهاشم 1000 | B29: 33 | C29: 81.8291 | D29: =ROUND(1*'سعر الكجم من الوصفات'!F6+5.6,4) | E29: =IF(OR(C29="",D29=""),"",D29/C29-1) | F29: =IF(D29="","",B29*D29) | G29: من وصفة «برجر ابوهاشم»: 1 كجم × سعر كجم سبتمبر + تعبئة 5.60 ج.م | مؤقت: الوصفة تستخدم مفروم الفراخ بسعر أغسطس لحين حسم الفاتورة
A30: ممبار | B30: 0 | E30: =IF(OR(C30="",D30=""),"",D30/C30-1) | F30: =IF(D30="","",B30*D30) | G30: بلا وصفة ولا سعر سابق — يلزم توفير سعره
A31: عجينة سجق ابوهاشم 1ك | B31: 0 | C31: 82.5378 | D31: =ROUND(1*'سعر الكجم من الوصفات'!F4+0,4) | E31: =IF(OR(C31="",D31=""),"",D31/C31-1) | F31: =IF(D31="","",B31*D31) | G31: من وصفة «سجق ابوهاشم»: 1 كجم × سعر كجم سبتمبر بدون تكلفة تعبئة (غير محددة بالوصفة) | مؤقت: الوصفة تستخدم مفروم الفراخ بسعر أغسطس لحين حسم الفاتورة
A32: عجينة كفته ابو هاشم 5 ك | B32: 0 | C32: 395.1817 | D32: =ROUND(5*'سعر الكجم من الوصفات'!F5+0,4) | E32: =IF(OR(C32="",D32=""),"",D32/C32-1) | F32: =IF(D32="","",B32*D32) | G32: من وصفة «كفته ابوهاشم»: 5 كجم × سعر كجم سبتمبر بدون تكلفة تعبئة (غير محددة بالوصفة) | مؤقت: الوصفة تستخدم مفروم الفراخ بسعر أغسطس لحين حسم الفاتورة
A33: كفتة ابو هاشم 1ك | B33: 0 | C33: 79.0364 | D33: =ROUND(1*'سعر الكجم من الوصفات'!F5+0,4) | E33: =IF(OR(C33="",D33=""),"",D33/C33-1) | F33: =IF(D33="","",B33*D33) | G33: من وصفة «كفته ابوهاشم»: 1 كجم × سعر كجم سبتمبر بدون تكلفة تعبئة (غير محددة بالوصفة) | مؤقت: الوصفة تستخدم مفروم الفراخ بسعر أغسطس لحين حسم الفاتورة
A34: كيس كبده 3 ك برازيلي | B34: 0 | E34: =IF(OR(C34="",D34=""),"",D34/C34-1) | F34: =IF(D34="","",B34*D34) | G34: بلا وصفة ولا سعر سابق — يلزم توفير سعره
A35: سجق ابو هاشم 1.5 ك | B35: 0 | C35: 123.8068 | D35: =ROUND(1.5*'سعر الكجم من الوصفات'!F4+0,4) | E35: =IF(OR(C35="",D35=""),"",D35/C35-1) | F35: =IF(D35="","",B35*D35) | G35: من وصفة «سجق ابوهاشم»: 1.5 كجم × سعر كجم سبتمبر بدون تكلفة تعبئة (غير محددة بالوصفة) | مؤقت: الوصفة تستخدم مفروم الفراخ بسعر أغسطس لحين حسم الفاتورة
A36: عجينة سجق ابوهاشم 3ك | B36: 0 | C36: 256.8435 | D36: =ROUND(3*'سعر الكجم من الوصفات'!F4+9.23,4) | E36: =IF(OR(C36="",D36=""),"",D36/C36-1) | F36: =IF(D36="","",B36*D36) | G36: من وصفة «سجق ابوهاشم»: 3 كجم × سعر كجم سبتمبر + تعبئة 9.23 ج.م | مؤقت: الوصفة تستخدم مفروم الفراخ بسعر أغسطس لحين حسم الفاتورة
A37: كبده 500 | B37: 0 | E37: =IF(OR(C37="",D37=""),"",D37/C37-1) | F37: =IF(D37="","",B37*D37) | G37: بلا وصفة ولا سعر سابق — يلزم توفير سعره
A38: سجق الهنا 700 | B38: 126 | C38: 22.5393 | D38: =ROUND(0.7*'سعر الكجم من الوصفات'!F10+5.99,4) | E38: =IF(OR(C38="",D38=""),"",D38/C38-1) | F38: =IF(D38="","",B38*D38) | G38: من وصفة «سجق الهنا»: 0.7 كجم × سعر كجم سبتمبر + تعبئة 5.99 ج.م | مؤقت: الوصفة تستخدم مفروم الفراخ بسعر أغسطس لحين حسم الفاتورة
A39: سجق الهنا 300 | B39: 875 | C39: 11.7226 | D39: =ROUND(0.3*'سعر الكجم من الوصفات'!F10+4.63,4) | E39: =IF(OR(C39="",D39=""),"",D39/C39-1) | F39: =IF(D39="","",B39*D39) | G39: من وصفة «سجق الهنا»: 0.3 كجم × سعر كجم سبتمبر + تعبئة 4.63 ج.م | مؤقت: الوصفة تستخدم مفروم الفراخ بسعر أغسطس لحين حسم الفاتورة
A40: كفته الهنا 800 | B40: 1633 | C40: 24.9863 | D40: =ROUND(0.8*'سعر الكجم من الوصفات'!F12+6.08,4) | E40: =IF(OR(C40="",D40=""),"",D40/C40-1) | F40: =IF(D40="","",B40*D40) | G40: من وصفة «كفته الهنا»: 0.8 كجم × سعر كجم سبتمبر + تعبئة 6.08 ج.م | مؤقت: الوصفة تستخدم مفروم الفراخ بسعر أغسطس لحين حسم الفاتورة
A41: كفته الهنا 350 | B41: 1513 | C41: 13.447 | D41: =ROUND(0.35*'سعر الكجم من الوصفات'!F12+5.18,4) | E41: =IF(OR(C41="",D41=""),"",D41/C41-1) | F41: =IF(D41="","",B41*D41) | G41: من وصفة «كفته الهنا»: 0.35 كجم × سعر كجم سبتمبر + تعبئة 5.18 ج.م | مؤقت: الوصفة تستخدم مفروم الفراخ بسعر أغسطس لحين حسم الفاتورة
...

Sheet الفراخ المفرومة (معلّق)
A1: صنفا الفراخ المفرومة — بيانات شراء متعارضة (السعر بملف سبتمبر تُرك كما هو)
A3: القراءة | B3: مفروم فراخ شعبي | C3: مفروم فراخ فاخر
A4: متوسط سبتمبر — كما سُجّلت بالتقرير | B4: 35.6294 | C4: 50.3771
A5: متوسط سبتمبر — باستبعاد الفاتورة 1111115217 | B5: 32.1107 | C5: 58.2481
A6: متوسط سبتمبر — بعكس سعرَى الفاتورة (C=30، A=57) | B6: 31.8123 | C6: 57.9003
A7: متوسط أغسطس (للمقارنة) | B7: 28.386 | C7: 55.082
A8: السعر الموجود بملف سبتمبر (تُرك) | B8: 30 | C8: 60
A9: كمية جرد 30/9 | B9: 860 | C9: 370
A11: فاتورة 1111115217 (09/09): «مفروم فراخ C» 1,500 كجم بسعر 57 بينما نطاق الرتبة C 30–35، وفى نفس الفاتورة «مفروم فراخ A» بسعر 30 بينما نطاق A 55–60 — السعران يبدوان معكوسين

Sheet المطابقة
A1: المطابقة النهائية — كل فحص يجب أن يكون الفرق صفرًا
A3: الفحص | B3: القيمة المحسوبة | C3: القيمة المرجعية | D3: الفرق | E3: النتيجة
A4: إجمالى أسطر مشتريات سبتمبر = الإجمالى المطبوع بالتقرير | B4: ='مشتريات سبتمبر التفصيلية'!H94 | C4: ='مشتريات سبتمبر التفصيلية'!H95 | D4: =B4-C4 | E4: =IF(ABS(D4)<=0.005,"✔ مطابق","✘ فرق")
A5: المشتريات المحمّلة على الأصناف + المجمّع + المستبعدة = إجمالى المشتريات | B5: ='احتساب متوسط سبتمبر'!F171+'احتساب متوسط سبتمبر'!F174+'مشتريات سبتمبر التفصيلية'!H96 | C5: ='مشتريات سبتمبر التفصيلية'!H94 | D5: =B5-C5 | E5: =IF(ABS(D5)<=0.005,"✔ مطابق","✘ فرق")
A6: قيمة أول المدة بورقة الاحتساب = قيمة أصناف جرد 31/8 المنقولة لسبتمبر | B6: ='احتساب متوسط سبتمبر'!D171 | C6: =N('رصيد أول المدة (31-8)'!F5)+N('رصيد أول المدة (31-8)'!F6)+N('رصيد أول المدة (31-8)'!F7)+N('رصيد أول المدة (31-8)'!F8)+N('رصيد أول المدة (31-8)'!F9)+N('رصيد أول المدة (31-8)'!F10)+N('رصيد أول المدة (31-8)'!F11)+N('رصيد أول المدة (31-8)'!F12)+N('رصيد أول المدة (31-8)'!F13)+N('رصيد أول المدة (31-8)'!F14)+N('رصيد أول المدة (31-8)'!F15)+N('رصيد أول المدة (31-8)'!F16)+N('رصيد أول المدة (31-8)'!F17)+N('رصيد أول المدة (31-8)'!F18)+N('رصيد أول المدة (31-8)'!F19)+N('رصيد أول المدة (31-8)'!F20)+N('رصيد أول المدة (31-8)'!F21)+N('رصيد أول المدة (31-8)'!F22)+N('رصيد أول المدة (31-8)'!F23)+N('رصيد أول المدة (31-8)'!F24)+N('رصيد أول المدة (31-8)'!F25)+N('رصيد أول المدة (31-8)'!F26)+N('رصيد أول المدة (31-8)'!F27)+N('رصيد أول المدة (31-8)'!F28)+N('رصيد أول المدة (31-8)'!F29)+N('رصيد أول المدة (31-8)'!F30)+N('رصيد أول المدة (31-8)'!F31)+N('رصيد أول المدة (31-8)'!F32)+N('رصيد أول المدة (31-8)'!F33)+N('رصيد أول المدة (31-8)'!F34)+N('رصيد أول المدة (31-8)'!F35)+N('رصيد أول المدة (31-8)'!F36)+N('رصيد أول المدة (31-8)'!F37)+N('رصيد أول المدة (31-8)'!F38)+N('رصيد أول المدة (31-8)'!F39)+N('رصيد أول المدة (31-8)'!F40)+N('رصيد أول المدة (31-8)'!F41)+N('رصيد أول المدة (31-8)'!F42)+N('رصيد أول المدة (31-8)'!F43)+N('رصيد أول المدة (31-8)'!F44)+N('رصيد أول المدة (31-8)'!F45)+N('رصيد أول المدة (31-8)'!F46)+N('رصيد أول المدة (31-8)'!F47)+N('رصيد أول المدة (31-8)'!F48)+N('رصيد أول المدة (31-8)'!F49)+N('رصيد أول المدة (31-8)'!F50)+N('رصيد أول المدة (31-8)'!F51)+N('رصيد أول المدة (31-8)'!F52)+N('رصيد أول المدة (31-8)'!F53)+N('رصيد أول المدة (31-8)'!F54)+N('رصيد أول المدة (31-8)'!F55)+N('رصيد أول المدة (31-8)'!F56)+N('رصيد أول المدة (31-8)'!F57)+N('رصيد أول المدة (31-8)'!F58)+N('رصيد أول المدة (31-8)'!F59)+N('رصيد أول المدة (31-8)'!F60)+N('رصيد أول المدة (31-8)'!F61)+N('رصيد أول المدة (31-8)'!F62)+N('رصيد أول المدة (31-8)'!F63)+N('رصيد أول المدة (31-8)'!F64)+N('رصيد أول المدة (31-8)'!F65)+N('رصيد أول المدة (31-8)'!F66)+N('رصيد أول المدة (31-8)'!F67)+N('رصيد أول المدة (31-8)'!F68)+N('رصيد أول المدة (31-8)'!F69)+N('رصيد أول المدة (31-8)'!F70)+N('رصيد أول المدة (31-8)'!F71)+N('رصيد أول المدة (31-8)'!F72)+N('رصيد أول المدة (31-8)'!F73)+N('رصيد أول المدة (31-8)'!F74)+N('رصيد أول المدة (31-8)'!F75)+N('رصيد أول المدة (31-8)'!F76)+N('رصيد أول المدة (31-8)'!F77)+N('رصيد أول المدة (31-8)'!F78)+N('رصيد أول المدة (31-8)'!F79)+N('رصيد أول المدة (31-8)'!F80)+N('رصيد أول المدة (31-8)'!F81)+N('رصيد أول المدة (31-8)'!F82)+N('رصيد أول المدة (31-8)'!F83)+N('رصيد أول المدة (31-8)'!F84)+N('رصيد أول المدة (31-8)'!F85)+N('رصيد أول المدة (31-8)'!F86)+N('رصيد أول المدة (31-8)'!F87)+N('رصيد أول المدة (31-8)'!F88)+N('رصيد أول المدة (31-8)'!F89)+N('رصيد أول المدة (31-8)'!F90)+N('رصيد أول المدة (31-8)'!F91)+N('رصيد أول المدة (31-8)'!F92)+N('رصيد أول المدة (31-8)'!F93)+N('رصيد أول المدة (31-8)'!F94)+N('رصيد أول المدة (31-8)'!F95)+N('رصيد أول المدة (31-8)'!F96)+N('رصيد أول المدة (31-8)'!F97)+N('رصيد أول المدة (31-8)'!F98)+N('رصيد أول المدة (31-8)'!F99)+N('رصيد أول المدة (31-8)'!F100)+N('رصيد أول المدة (31-8)'!F101)+N('رصيد أول المدة (31-8)'!F102)+N('رصيد أول المدة (31-8)'!F103)+N('رصيد أول المدة (31-8)'!F104)+N('رصيد أول المدة (31-8)'!F105)+N('رصيد أول المدة (31-8)'!F106)+N('رصيد أول المدة (31-8)'!F107)+N('رصيد أول المدة (31-8)'!F108)+N('رصيد أول المدة (31-8)'!F109)+N('رصيد أول المدة (31-8)'!F110)+N('رصيد أول المدة (31-8)'!F111)+N('رصيد أول المدة (31-8)'!F112)+N('رصيد أول المدة (31-8)'!F113)+N('رصيد أول المدة (31-8)'!F143)+N('رصيد أول المدة (31-8)'!F114)+N('رصيد أول المدة (31-8)'!F115)+N('رصيد أول المدة (31-8)'!F116)+N('رصيد أول المدة (31-8)'!F117)+N('رصيد أول المدة (31-8)'!F118)+N('رصيد أول المدة (31-8)'!F119)+N('رصيد أول المدة (31-8)'!F120)+N('رصيد أول المدة (31-8)'!F121)+N('رصيد أول المدة (31-8)'!F123)+N('رصيد أول المدة (31-8)'!F124)+N('رصيد أول المدة (31-8)'!F125)+N('رصيد أول المدة (31-8)'!F126)+N('رصيد أول المدة (31-8)'!F127)+N('رصيد أول المدة (31-8)'!F128)+N('رصيد أول المدة (31-8)'!F129)+N('رصيد أول المدة (31-8)'!F130)+N('رصيد أول المدة (31-8)'!F131)+N('رصيد أول المدة (31-8)'!F132)+N('رصيد أول المدة (31-8)'!F133)+N('رصيد أول المدة (31-8)'!F134)+N('رصيد أول المدة (31-8)'!F135)+N('رصيد أول المدة (31-8)'!F136)+N('رصيد أول المدة (31-8)'!F137)+N('رصيد أول المدة (31-8)'!F138)+N('رصيد أول المدة (31-8)'!F140)+N('رصيد أول المدة (31-8)'!F139)+N('رصيد أول المدة (31-8)'!F146)+N('رصيد أول المدة (31-8)'!F151)+N('رصيد أول المدة (31-8)'!F147)+N('رصيد أول المدة (31-8)'!F148)+N('رصيد أول المدة (31-8)'!F149)+N('رصيد أول المدة (31-8)'!F150)+N('رصيد أول المدة (31-8)'!F141)+N('رصيد أول المدة (31-8)'!F142)+N('رصيد أول المدة (31-8)'!F144)+N('رصيد أول المدة (31-8)'!F152)+N('رصيد أول المدة (31-8)'!F145) | D6: =B6-C6 | E6: =IF(ABS(D6)<=0.005,"✔ مطابق","✘ فرق")
A7: قيمة مخزون الخامات 30/9 = Σ (كمية جرد 30/9 × السعر المُدخل بالملف) | B7: ='احتساب متوسط سبتمبر'!L171 | C7: =SUMPRODUCT('احتساب متوسط سبتمبر'!K5:K169,'احتساب متوسط سبتمبر'!J5:J169) | D7: =B7-C7 | E7: =IF(ABS(D7)<=0.01,"✔ مطابق","✘ فرق")
A8: أسعار ملف «تسعير جرد اخر شهر ٩» = الاحتساب المستقل (عدد الأصناف) | B8: 165 | C8: 165 | D8: 0 | E8: ✔ مطابق
A9: قيمة مخزون الخامات بملف سبتمبر بعد إعادة الاحتساب (Σ عمود القيمة) | B9: 2202045.1 | C9: 2202045.1 | D9: 0 | E9: ✔ مطابق
A10: قيمة جرد 31/8 المعدَّل × متوسط أغسطس = إجمالى ملف «-2» + أثر فروق الكميات بينهما (-19,014.85، أغلبه «زيت سيارات» 2 بالجرد مقابل 16 بملف «-2») | B10: 2642846.2 | C10: 2642846.2 | D10: 0.0099999998 | E10: ✔ مطابق
A11: أصناف جرد 31/8 ذات قيمة غير موجودة بجرد سبتمبر (قيمة) | B11: 0 | C11: 0 | D11: 0 | E11: ✔ مطابق

Sheet المنهجية والاستثناءات
A1: المنهجية، الافتراضات، والاستثناءات — سبتمبر 2026
A3: نطاق العمل | B3: متوسط التكلفة المرجّح (WAC) للخامات فقط — لم تُستخدم FIFO / LIFO / التكلفة المعيارية.
A4: المعادلة | B4: متوسط سبتمبر = (كمية جرد 31/8 × متوسط أغسطس + قيمة مشتريات سبتمبر) ÷ (كمية جرد 31/8 + كمية مشتريات سبتمبر). يُحتسب بالدقة الكاملة ويُقرَّب السعر المُدخل لأربعة أرقام عشرية.
A5: رصيد أول المدة | B5: الجرد الفعلى المعدَّل «جر د شهر 8.xlsx» (مجموع المواقع الخمسة) × متوسط أغسطس المُعاد احتسابه من مصادره؛ طوبق السعر مع ملف «تسعير جرد اخر شهر ٨ -2» لكل صنف مشترك (لا فرق).
A6: المشتريات | B6: تقرير المشتريات 01/09–30/09/2026: 89 سطرًا، الإجمالى مطابق للمطبوع. قيمة الشراء = «الإجمالى» بالفاتورة (7 أسطر بها فرق تقريب بين الكمية × السعر والإجمالى). المحمَّل على الأصناف 2,197,994.05 ج.م.
A7: ربط الأكواد | B7: الكود المستخدم فى يوليو/أغسطس يُربط بنفس الصنف؛ الأكواد الجديدة رُبطت بالاسم ونطاق السعر بدرجة ثقة مُسجّلة. مجمّع اللحوم الهندى متوسط واحد للبنود الأربعة.
A8: أصناف معلّقة | B8: صنفا الفراخ المفرومة (شعبي/فاخر) تُرك سعرهما بالملف كما هو لتعارض فاتورة 1111115217؛ ثلاث قراءات بديلة بورقة «الفراخ المفرومة (معلّق)». الوصفات تستخدم لهما سعر أغسطس مؤقتًا.
A9: أصناف بلا مشتريات | B9: يبقى سعر أغسطس كما هو. رصيد بلا سعر يُستبعد من البسط والمقام.
A10: ملف سبتمبر | B10: «تسعير جرد اخر شهر ٩ سنة ٢٠٢٦.xlsx» نسخة من «جرد شهر 9.xlsx» تغيّرت فيها خانات السعر فقط (عمود H للخامات و L للمنتج التام)؛ تحقق آلى من عدم تغيّر أى خانة أخرى. أُضيفت تعليقات على الأصناف المعلّقة أو بلا سعر.
A11: المنتج التام | B11: الوزن × سعر كجم الوصفة بأسعار سبتمبر + تكلفة التعبئة؛ الأصناف خارج الوصفات بآخر سعر متاح.
A13: نوع الملاحظة | B13: الصنف / البند | C13: التفصيل
A14: سعر معلّق | B14: مفروم فراخ شعبي | C14: فاتورة 1111115217 (09/09): «مفروم فراخ C» 1,500 كجم بسعر 57 بينما نطاق الرتبة C 30–35، وفى نفس الفاتورة «مفروم فراخ A» بسعر 30 بينما نطاق A 55–60 — السعران يبدوان معكوسين — كما سُجّلت بالتقرير: 35.6294، باستبعاد الفاتورة 1111115217: 32.1107، بعكس سعرَى الفاتورة (C=30، A=57): 31.8123
A15: سعر معلّق | B15: مفروم فراخ فاخر | C15: فاتورة 1111115217 (09/09): «مفروم فراخ A» 450 كجم بسعر 30 بينما نطاق الرتبة A 55–60، وفى نفس الفاتورة «مفروم فراخ C» بسعر 57 — السعران يبدوان معكوسين — كما سُجّلت بالتقرير: 50.3771، باستبعاد الفاتورة 1111115217: 58.2481، بعكس سعرَى الفاتورة (C=30، A=57): 57.9003
A16: ربط بثقة متوسطة | B16: كود 14 «تشكيله هندى امامى» ← @مجمع اللحوم الهندى | C16: نفس ربط الكود فى يوليو: لحوم هندى مجمَّعة: بنود (كتف/رقبه/سن/أرباع) بسعر يونيه موحَّد 253
A17: ربط بثقة متوسطة | B17: كود 40 «علب شفاف» ← علب بلاستيك شفاف | C17: نفس ربط الكود فى يوليو: تطابق اسمى؛ رصيد أول المدة كان بلا سعر ⇒ السعر = سعر الشراء
A18: ربط بثقة متوسطة | B18: كود 409 «طبق شفاف كيلو» ← طبق مسطح 1 ك شفاف | C18: طبق شفاف كيلو = البند الشفاف الوحيد مقاس 1 ك بالجرد؛ بلا سعر سابق — يُراجَع
A19: ربط بثقة متوسطة | B19: كود 51 «صويا مصرى» ← صويا لحمه | C19: نفس ربط الكود فى يوليو: الصويا العامة تُحمَّل على «صويا لحمه» (سعر 32–40 ≈ 39.44) — نفس افتراض ملف يونيه
A20: ربط بثقة متوسطة | B20: كود 344 «فلفل حامى» ← فلفل رومي حامي | C20: فلفل حامى = عائلة الفلفل الحار الوحيدة بالجرد (نفس معالجة «فلفل احمر» كود 187)
A21: شراء بلا مقابل | B21: كود 453 «ببريكا مدخنه» — 5,600.00 ج.م | C21: بابريكا مدخنة صنف مختلف عن «بابريكا» العادية ولا يوجد له بند بالجرد — لم تُحمَّل على أى صنف
A22: سعر شاذ (دخل كما سُجّل) | B22: سطر 58 كود 87 «جلتومات الصوديوم» | C22: نفس ربط الكود فى أغسطس: جلوتامات الصوديوم = «جلتومات/مونوصوديم» بالوصفات؛ سعر 88 مقابل 104.00 ليوليو | ⚠ جلتومات 25 كجم بسعر 132 مقابل 80 لسطر الشراء الآخر
A23: ربط بثقة متوسطة | B23: كود 154 «فلفل اخضر عام عام» ← فلفل بارد | C23: نفس ربط الكود فى يوليو: الفلفل الأخضر غير الحار = «البارد»؛ سعر 12–14 ≈ 14.92 ليونيه
A24: ربط بثقة متوسطة | B24: كود 371 «مفروم فراخ B» ← مفروم فراخ شعبي | C24: الرتبة B غير موجودة بالجرد؛ سعرها 34 داخل نطاق الرتبة C (30–35) فحُمّلت على «شعبي» — يُراجَع
... A39: منتج تام بلا سعر | B39: مفروم ابو هاشم 3 ك — كمية 9.00 | C39: بلا وصفة ولا سعر سابق — يلزم توفير سعره
