Workbook

Sheet الهاشم
B1: تكلفه كفته ابوهاشم لاغى | D1: لاغى لاتعمل | J1: تكلفه برجر | K1: ابوهاشم | Q1: تكلفه سجق ابوهاشم | V1: كفته شوى
B2: النوع | C2: الكميه | D2: السعر | E2: الاجمالي | J2: النوع | K2: الكميه | L2: السعر | M2: الاجمالي | Q2: النوع | R2: الكميه | S2: السعر | T2: الاجمالي | V2: النوع | W2: الكميه | X2: السعر | Y2: الاجمالي | AB2: تكلفه كفته ابوهاشم تعديل 7-1-2026
B3: فلانك | C3: 20 | D3: 132 | E3: =D3*C3 -> 2640 | J3: لحمه | K3: 12 | L3: 233 | M3: =L3*K3 -> 2796 | Q3: مفروم فراخ فاخر | R3: 20 | S3: 57 | T3: =R3*S3 -> 1140 | V3: لحمه | W3: 8.667 | X3: 190 | Y3: =W3*X3 -> 1646.73 | AB3: النوع | AC3: الكميه | AD3: السعر | AE3: الاجمالي
B4: مفروم فراخ فاخر | C4: 5 | D4: 54 | E4: =D4*C4 -> 270 | J4: بوش/دهن | K4: 5 | L4: 35 | M4: =L4*K4 -> 175 | O4: =5*245 -> 1225 | Q4: بصل | R4: 10 | S4: =+L7 -> 12 | T4: =R4*S4 -> 120 | V4: بوش | W4: 3.33 | X4: 97 | Y4: =W4*X4 -> 323.01 | AB4: فلانك | AC4: 20 | AD4: 223 | AE4: =AD4*AC4 -> 4460
B5: فلفل اخضر | C5: 2 | D5: 16 | E5: =D5*C5 -> 32 | J5: دوبريه | K5: 6 | L5: 135 | M5: =L5*K5 -> 810 | O5: =223*7 -> 1561 | Q5: دهن | R5: 10 | S5: 35 | T5: =R5*S5 -> 350 | V5: بصل | W5: 0.25 | X5: 12 | Y5: =W5*X5 -> 3 | AB5: مفروم فراخ فاخر | AC5: 5 | AD5: 58 | AE5: =AD5*AC5 -> 290
B6: دهن | C6: 10 | D6: 51 | E6: =D6*C6 -> 510 | J6: صويا | K6: 6 | L6: 39 | M6: =L6*K6 -> 234 | O6: =O5+O4 -> 2786 | Q6: فلانك | R6: 20 | S6: 223 | T6: =R6*S6 -> 4460 | V6: فلفل | W6: 0.25 | X6: 8 | Y6: =W6*X6 -> 2 | AB6: فلفل اخضر | AC6: 2.5 | AD6: 25 | AE6: =AD6*AC6 -> 62.5
B7: صويا | C7: 10 | D7: 31 | E7: =D7*C7 -> 310 | J7: بصل | K7: 4 | L7: =+D10 -> 12 | M7: =L7*K7 -> 48 | O7: =O6/12 -> 232.16667 | Q7: فلفل | R7: 0 | S7: 5 | T7: =R7*S7 -> 0 | V7: صويا | W7: 0.2 | X7: 33.5 | Y7: =W7*X7 -> 6.7 | AB7: دهن | AC7: 9 | AD7: 35 | AE7: =AD7*AC7 -> 315
B8: فلفل حار | C8: 0.1 | D8: 16 | E8: =D8*C8 -> 1.6 | J8: صميد | K8: 1 | L8: 15 | M8: =L8*K8 -> 15 | Q8: توام | R8: 2 | S8: 29 | T8: =R8*S8 -> 58 | V8: مايه | W8: =0.44+0.125 -> 0.565 | Y8: =W8*X8 -> 0 | AB8: صويا | AC8: 7.5 | AD8: 39 | AE8: =AD8*AC8 -> 292.5
B9: برغل | C9: 5 | D9: 19 | E9: =D9*C9 -> 95 | J9: ثوم | K9: 0.5 | L9: 29 | M9: =L9*K9 -> 14.5 | Q9: صويا | R9: 10 | S9: 39 | T9: =R9*S9 -> 390 | V9: برغل | W9: 0.125 | X9: 20 | Y9: =W9*X9 -> 2.5 | AB9: فلفل حار | AC9: 0.2 | AD9: 25 | AE9: =AD9*AC9 -> 5
B10: بصل | C10: 7.5 | D10: 12 | E10: =D10*C10 -> 90 | J10: نشا | K10: 2 | L10: 28.5 | M10: =L10*K10 -> 57 | Q10: بطاطس | T10: =R10*S10 -> 0 | V10: نشا | W10: 0.1 | X10: 27 | Y10: =W10*X10 -> 2.7 | AB10: برغل | AC10: 0 | AD10: 20 | AE10: =AD10*AC10 -> 0
B11: صويا ايزوليت | C11: 1 | D11: 130 | E11: =D11*C11 -> 130 | J11: برغل | K11: 4 | L11: 20 | M11: =L11*K11 -> 80 | Q11: برغل | R11: 4 | S11: 20 | T11: =R11*S11 -> 80 | V11: توابل | W11: =+X38 -> 0.138 | X11: =+W39 -> 114.45261 | Y11: =W11*X11 -> 15.79446 | AB11: بصل | AC11: 6 | AD11: 12 | AE11: =AD11*AC11 -> 72
B12: مايه | C12: 22 | D12: 0 | E12: =D12*C12 -> 0 | I12: ان وجدت | J12: ايزوليت | K12: 0.25 | L12: 190 | M12: =L12*K12 -> 47.5 | O12: =R13/R17*3 -> 0.66079295 | Q12: جلد | R12: 10 | S12: 35 | T12: =R12*S12 -> 350 | Y12: =W12*X12 -> 0 | AB12: صويا ايزوليت | AC12: 1.2 | AD12: 190 | AE12: =AD12*AC12 -> 228
B13: نشا | C13: 4 | D13: 24.5 | E13: =D13*C13 -> 98 | J13: مفروم فراخ فاخر | K13: 6 | L13: 57 | M13: =L13*K13 -> 342 | Q13: مايه | R13: 28 | S13: 0 | T13: =R13*S13 -> 0 | Y13: =W13*X13 -> 0 | AB13: مايه | AC13: 15 | AD13: 1 | AE13: =AD13*AC13 -> 15
B14: صميد | C14: 3 | D14: 14.5 | E14: =D14*C14 -> 43.5 | J14: مياه | K14: 14 | L14: 1 | M14: =L14*K14 -> 14 | Q14: دوبريه | R14: 10 | S14: 135 | T14: =R14*S14 -> 1350 | Y14: =W14*X14 -> 0 | AB14: نشا | AC14: 2.5 | AD14: 28.5 | AE14: =AD14*AC14 -> 71.25
B15: دبوبريه | C15: 5 | D15: 80 | E15: =D15*C15 -> 400 | J15: توابيل | K15: =K40 -> 1.905 | L15: =K41 -> 141.45407 | M15: =L15*K15 -> 269.47 | Q15: نشا | R15: 0 | S15: 28.5 | T15: =R15*S15 -> 0 | Y15: =W15*X15 -> 0 | AB15: صميد | AC15: 2 | AD15: 15.5 | AE15: =AD15*AC15 -> 31
B16: توابيل | C16: =+C40 -> 3.305 | D16: =+C41 -> 107.26929 | E16: =D16*C16 -> 354.525 | J16: الاجمالي | K16: =SUM(K3:K15) -> 62.655 | M16: =SUM(M3:M15) -> 4902.47 | Q16: توابيل | R16: 3.12 | S16: =R43 -> 204.01223 | T16: =R16*S16 -> 636.51817 | X16: =W43 -> 0 | Y16: =W16*X16 -> 0 | AB16: دبوبريه | AC16: 5 | AD16: 135 | AE16: =AD16*AC16 -> 675
B17: الاجمالي | C17: =SUM(C3:C16) -> 97.905 | E17: =SUM(E3:E16) -> 4974.625 | Q17: الاجمالي | R17: =SUM(R3:R16) -> 127.12 | T17: =SUM(T3:T16) -> 8934.5182 | V17: الاجمالي | W17: =SUM(W3:W16) -> 13.625 | Y17: =SUM(Y3:Y16) -> 2002.4345 | AB17: توابيل | AC17: =AC41 -> 2.6 | AD17: =+AC42 -> 124.71346 | AE17: =AD17*AC17 -> 324.255
B18: سعر الكيلو | C18: =E17/C17 -> 50.810735 | J18: سعر الكيلو | K18: =M16/K16 -> 78.245471 | Q18: هنكات للكيلو | R18: 20 | V18: هنكات للكيلو | W18: 0 | AB18: الاجمالي | AC18: =SUM(AC4:AC17) -> 78.5 | AE18: =SUM(AE4:AE17) -> 6841.505
B19: الوزن | C19: التكلفه | D19: تكاليف التغليف | E19: الاجمالي | J19: الوزن | K19: التكلفه | L19: تكاليف التغليف | M19: الاجمالي | Q19: سعر الكيلو | R19: =T17/R17+R18 -> 90.284127 | V19: سعر الكيلو | W19: =Y17/W17+W18 -> 146.96767 | AB19: سعر الكيلو الخلطة | AC19: =AE18/AC18 -> 87.15293
B20: 350جرام | C20: =C18*0.35 -> 17.783757 | D20: =F55 -> 4.64 | E20: =C20+D20 -> 22.423757 | J20: 400جرام | K20: =K18*0.4 -> 31.298188 | L20: =H55 -> 4.99 | M20: =K20+L20 -> 36.288188 | Q20: الوزن | R20: التكلفه | S20: تكاليف التغليف | T20: الاجمالي | AB20: الوزن | AC20: التكلفه | AD20: تكاليف التغليف | AE20: الاجمالي
B21: 800جرام | C21: =C18*0.8 -> 40.648588 | D21: =G55 -> 6.36 | E21: =C21+D21 -> 47.008588 | J21: 800جرام | K21: =K18*0.8 -> 62.596377 | L21: 0 | M21: =K21+L21 -> 62.596377 | Q21: 350جرام | R21: =R19*0.35 -> 31.599444 | S21: =C56 -> 4.67 | T21: =R21+S21 -> 36.269444 | AB21: 350جرام | AC21: =AC19*0.35 -> 30.503525 | AD21: 4.5 | AE21: =AC21+AD21 -> 35.003525
J22: 600جرام | K22: =K18*0.55 -> 43.035009 | L22: =I55 -> 5.99 | M22: =K22+L22 -> 49.025009 | Q22: 800جرام | R22: =R19*0.8 -> 72.227301 | S22: =D56 -> 6.27 | T22: =R22+S22 -> 78.497301 | AB22: 800جرام | AC22: =AC19*0.8 -> 69.722344 | AD22: 5.35 | AE22: =AC22+AD22 -> 75.072344
J23: برجر 1ك | K23: =K18*1 -> 78.245471 | L23: 5.6 | M23: =K23+L23 -> 83.845471 | Q23: 3كيلو | R23: =R19*3 -> 270.85238 | S23: =E56 -> 9.23 | T23: =R23+S23 -> 280.08238
B24: خلطه توابل كفته ابوهاشم | J24: 1200جرام | K24: =K18*1.2 -> 93.894565 | L24: 6.18 | M24: =K24+L24 -> 100.07457 | Q24: 5كيلو | R24: =R19*5 -> 451.42063 | S24: 2.5 | T24: =R24+S24 -> 453.92063
B25: فوسفات | C25: 0.4 | D25: 100 | E25: =C25*D25 -> 40 | J25: 1.5 | K25: =K18*1.5 -> 117.36821 | L25: =J55 -> 6.0688889 | M25: =K25+L25 -> 123.4371 | AB25: خلطه توابل كفته ابوهاشم
B26: مونوصوديم | C26: 0.3 | D26: 60 | E26: =C26*D26 -> 18 | L26: . | R26: سجق الهاشم | AB26: فوسفات | AC26: 0.4 | AD26: 160 | AE26: =AC26*AD26 -> 64
B27: طعم كفته | C27: 0.15 | D27: 150 | E27: =C27*D27 -> 22.5 | J27: فوسفات | K27: 0.25 | L27: 160 | M27: =K27*L27 -> 40 | Q27: فوسفات | R27: 0.3 | S27: 160 | T27: =S27*R27 -> 48 | W27: ملح | X27: 0.06 | Y27: 2.02 | Z27: =+Y27*X27 -> 0.1212 | AB27: مونوصوديم | AC27: 0.3 | AD27: 100 | AE27: =AC27*AD27 -> 30
B28: طعم شواء | C28: 0.12 | D28: 270 | E28: =C28*D28 -> 32.4 | J28: مونوصوديم | K28: 0.2 | L28: 100 | M28: =K28*L28 -> 20 | Q28: جلتومات | R28: 0.32 | S28: 100 | T28: =S28*R28 -> 32 | W28: فوسفات | X28: 0.02 | Y28: 115 | Z28: =+Y28*X28 -> 2.3 | AB28: طعم كفته | AC28: 0 | AD28: 250 | AE28: =AC28*AD28 -> 0
B29: طعم بيف | C29: 0.05 | D29: 270 | E29: =C29*D29 -> 13.5 | J29: طعم برجر | K29: 0.1 | L29: 310 | M29: =K29*L29 -> 31 | Q29: طعم بسطرمة | R29: 0.04 | S29: 730 | T29: =S29*R29 -> 29.2 | W29: جلوتومات | X29: 0.015 | Y29: 84.04 | Z29: =+Y29*X29 -> 1.2606 | AB29: طعم شواء | AC29: 0.1 | AD29: 295 | AE29: =AC29*AD29 -> 29.5
B30: خلنجان | D30: 230 | E30: =C30*D30 -> 0 | J30: طعم دخان | K30: 0 | L30: 290 | M30: =K30*L30 -> 0 | Q30: طعم سجق | R30: 0.06 | S30: 385 | T30: =S30*R30 -> 23.1 | W30: اسود | X30: 0.016 | Y30: 361 | Z30: =+Y30*X30 -> 5.776 | AB30: طعم بيف | AC30: 0.1 | AD30: 310 | AE30: =AC30*AD30 -> 31
B31: فلفل اسود | C31: 0.5 | D31: 325 | E31: =C31*D31 -> 162.5 | J31: طعم بيف | K31: 0.15 | L31: 310 | M31: =K31*L31 -> 46.5 | Q31: فلفل اسود | R31: 0.08 | S31: 400 | T31: =S31*R31 -> 32 | W31: كبابه | X31: 0.003 | Y31: 450 | Z31: =+Y31*X31 -> 1.35 | AB31: خلنجان | AC31: 0 | AE31: =AC31*AD31 -> 0
B32: كزبرة | C32: 0.07 | D32: 65 | E32: =C32*D32 -> 4.55 | J32: قرفه | K32: 0.05 | L32: 130 | M32: =K32*L32 -> 6.5 | Q32: كزبرة | R32: 0 | S32: 75 | T32: =S32*R32 -> 0 | W32: قرنفل | X32: 0.003 | Y32: 532.22 | Z32: =+Y32*X32 -> 1.59666 | AB32: فلفل اسود | AC32: 0.3 | AD32: 400 | AE32: =AC32*AD32 -> 120
B33: كبابة | C33: 0.06 | D33: 450 | E33: =C33*D33 -> 27 | J33: فلفل اسود | K33: 0.25 | L33: 400 | M33: =K33*L33 -> 100 | Q33: بابريكا | R33: 0.15 | S33: 140 | T33: =S33*R33 -> 21 | W33: جوزه الطيب | X33: 0.004 | Y33: 280 | Z33: =+Y33*X33 -> 1.12 | AB33: كزبرة | AC33: 0.05 | AD33: 70 | AE33: =AC33*AD33 -> 3.5
B34: قرنفل | C34: 0.015 | D34: 480 | E34: =C34*D34 -> 7.2 | J34: كزبرة | K34: 0.07 | L34: 70 | M34: =K34*L34 -> 4.9 | Q34: حلبه | R34: 0 | S34: 65 | T34: =S34*R34 -> 0 | W34: قرفه | X34: 0.003 | Y34: 160 | Z34: =+Y34*X34 -> 0.48 | AB34: كبابة | AC34: 0.04 | AD34: 450 | AE34: =AC34*AD34 -> 18
B35: طعم ليه | C35: 0.07 | D35: 250 | E35: =C35*D35 -> 17.5 | J35: كبابة | K35: 0 | L35: 450 | M35: =K35*L35 -> 0 | Q35: قرنفل | R35: 0.04 | S35: 800 | T35: =S35*R35 -> 32 | W35: كزبره | X35: 0.005 | Y35: 80 | Z35: =+Y35*X35 -> 0.4 | AB35: قرنفل | AC35: 0.01 | AD35: 650 | AE35: =AC35*AD35 -> 6.5
B36: سكر | C36: 0.035 | D36: 35 | E36: =C36*D36 -> 1.225 | J36: قرنفل | K36: 0.025 | L36: 720 | M36: =K36*L36 -> 18 | Q36: قرفه | R36: 0.1 | S36: 130 | T36: =S36*R36 -> 13 | W36: سكر | X36: 0.004 | Y36: 35 | Z36: =+Y36*X36 -> 0.14 | AB36: طعم ليه | AC36: 0.05 | AD36: 295 | AE36: =AC36*AD36 -> 14.75
B37: قرفة | C37: 0.035 | D37: 130 | E37: =C37*D37 -> 4.55 | J37: زعتر | K37: 0 | L37: 120 | M37: =K37*L37 -> 0 | Q37: شطه | R37: 0.1 | S37: 65 | T37: =S37*R37 -> 6.5 | W37: شواء | X37: 0.005 | Y37: 250 | Z37: =+Y37*X37 -> 1.25 | AB37: سكر | AC37: 0.025 | AD37: 35 | AE37: =AC37*AD37 -> 0.875
B38: شطه | C38: 0 | D38: 60 | E38: =C38*D38 -> 0 | J38: شطه | K38: 0.01 | L38: 65 | M38: =K38*L38 -> 0.65 | Q38: ملح | R38: 1.8 | S38: 2.4 | T38: =S38*R38 -> 4.32 | X38: =SUM(X27:X37) -> 0.138 | Y38: =SUM(Y27:Y37) -> 2349.28 | Z38: =SUM(Z27:Z37) -> 15.79446 | AB38: قرفة | AC38: 0.025 | AD38: 130 | AE38: =AC38*AD38 -> 3.25
B39: ملح | C39: 1.5 | D39: 2.4 | E39: =C39*D39 -> 3.6 | J39: ملح | K39: 0.8 | L39: 2.4 | M39: =K39*L39 -> 1.92 | Q39: ينسون | R39: 0.1 | S39: 120 | T39: =S39*R39 -> 12 | W39: =++Z38/X38 -> 114.45261 | AB39: شطه | AC39: 0 | AD39: 65 | AE39: =AC39*AD39 -> 0
B40: اجمالي | C40: =SUM(C25:C39) -> 3.305 | E40: =SUM(E25:E39) -> 354.525 | J40: اجمالي | K40: =SUM(K27:K39) -> 1.905 | M40: =SUM(M27:M39) -> 269.47 | Q40: لون | R40: 0.15 | S40: 2500 | T40: =S40*R40 -> 375 | AB40: ملح | AC40: 1.2 | AD40: 2.4 | AE40: =AC40*AD40 -> 2.88
...

Sheet اسبشيل غير صالح 
E4: كفته
C5: النوع | D5: الكميه | E5: السعر | K5: صح | L5: برجر
C6: مفروم | D6: 30 | E6: 35 | F6: =D6*E6 -> 1050 | J6: النوع | K6: الكميه | L6: السعر
C7: دهن | D7: 20 | E7: 70 | F7: =D7*E7 -> 1400 | L7: 0
C8: جلد | E8: 35 | F8: =D8*E8 -> 0 | J8: جلد | K8: 5 | L8: 35 | M8: =K8*L8 -> 175
C9: لورا | D9: 0.1 | E9: 130 | F9: =D9*E9 -> 13 | J9: فلفل اسود | K9: 0.4 | L9: 373.22 | M9: =K9*L9 -> 149.288
C10: فلفل اسود | D10: 0.5 | E10: =+'[1]5-2025'!$A$19 -> 373.22042 | F10: =D10*E10 -> 186.61021 | J10: مفروم | K10: 30 | L10: 35 | M10: =K10*L10 -> 1050
C11: فلفل رومى | D11: 5 | E11: 13 | F11: =D11*E11 -> 65 | J11: دهن | K11: 15 | L11: 70 | M11: =K11*L11 -> 1050
C12: صويا | D12: 9 | E12: 34 | F12: =D12*E12 -> 306 | J12: برغل | K12: 5 | L12: 19 | M12: =K12*L12 -> 95
C13: فلفل حار | D13: 0.5 | E13: 13 | F13: =D13*E13 -> 6.5 | J13: مياه\ | K13: 23 | L13: 0 | M13: =K13*L13 -> 0
C14: برغل | D14: 5 | E14: 19 | F14: =D14*E14 -> 95 | J14: صويا | K14: 9 | L14: 34 | M14: =K14*L14 -> 306
C15: نشا | D15: 5 | E15: 30 | F15: =D15*E15 -> 150 | J15: سميد | K15: 3 | L15: 15 | M15: =K15*L15 -> 45
C16: ايزوليت1 | D16: 1.5 | E16: 170 | F16: =D16*E16 -> 255 | J16: ايزوليت | K16: 1 | L16: 170 | M16: =K16*L16 -> 170
C17: بصل | D17: 10 | E17: 21 | F17: =D17*E17 -> 210 | J17: نشا | K17: 3 | L17: 30 | M17: =K17*L17 -> 90
C18: سميد | D18: 6.5 | E18: 15 | F18: =D18*E18 -> 97.5 | J18: بصل | K18: 7 | L18: 21 | M18: =K18*L18 -> 147
C19: مياه | D19: 20 | E19: 0 | F19: =D19*E19 -> 0 | J19: ملح | K19: 1.7 | L19: 1.7 | M19: =K19*L19 -> 2.89
C20: مونوصوديم | D20: 0.4 | E20: 74 | F20: =D20*E20 -> 29.6 | J20: فوسفات | K20: 0.5 | L20: 115 | M20: =K20*L20 -> 57.5
C21: لون كارمن | D21: 0.01 | E21: 2500 | F21: =D21*E21 -> 25 | J21: لورا | K21: 0.06 | L21: 130 | M21: =K21*L21 -> 7.8
C22: كسبرة | D22: 0.25 | E22: 75 | F22: =D22*E22 -> 18.75 | J22: شطه | K22: 0.1 | L22: 80 | M22: =K22*L22 -> 8
... C26: طعم كفته | D26: 0.25 | E26: 158 | F26: =D26*E26 -> 39.5 | J26: طعم شواء | K26: 0.4 | L26: 270 | M26: =K26*L26 -> 108
C27: طعم بيف | D27: 0.25 | E27: =+'[1]4-2025'!$A$52 -> 270 | F27: =D27*E27 -> 67.5 | J27: بيف | K27: 0.4 | L27: 270 | M27: =K27*L27 -> 108
C28: فوسفات | D28: 0.6 | E28: 115 | F28: =D28*E28 -> 69
C29: شواء | D29: 0.25 | E29: 270 | F29: =D29*E29 -> 67.5 | J29: لون | K29: 0.01 | L29: 2500 | M29: =K29*L29 -> 25 | N29: 2500 | S29: تكلفة عجينة بقرى 5 ك | T29: =T27*5 -> 0 | Y29: جوزة الطيب | Z29: 0.06 | AC29: =Z29*3 -> 0.18
C30: سكر | D30: 0.04 | E30: 35 | F30: =D30*E30 -> 1.4 | J30: الاجمالي | K30: =SUM(K8:K29) -> 105.39 | M30: =SUM(M8:M29) -> 3668.228
C31: طعم ليه | D31: 0.4 | E31: =+'[1]4-2025'!$A$51 -> 250 | F31: =D31*E31 -> 100 | J31: سعر الكيلو | K31: =M30/K30 -> 34.806224 | Y31: الاجمالى | Z31: =SUM(Z8:Z29) -> 0.06
C32: بابريكا | D32: 0.2 | E32: 175 | F32: =D32*E32 -> 35
C33: الاجمالي | D33: =SUM(D6:D32) -> 117.54 | F33: =SUM(F6:F32) -> 4324.6302
C34: سعر الكيلو | D34: =F33/D33 -> 36.792838 | S34: الصنف | T34: الخلطة | U34: تغليف | V34: الاجمالى
S35: سجق اسبشيال ص | T35: 12.956977 | U35: 3.9633333 | V35: 16.92031
D36: =22.96+15+2 -> 39.96 | E36: سعر الكيلو | S36: سجق الهنا ك | T36: 30.232945 | U36: 5.0066667 | V36: 35.239612
C38: الصنف | D38: الخلطة | E38: تغليف | F38: الاجمالى | G38: سعر قايمة قديم | H38: خصم 20% | I38: صافى سعر بيع | J38: هامش ربح | K38: نسبة هامش الربح | L38: خصم 18 | M38: صافى سعر بيع | N38: هامش الربح | O38: نسبة هامش الربح
C39: سجق اسبشيال ص | D39: 12.956977 | E39: 3.9633333 | F39: =D39+E39 -> 16.92031 | G39: 44 | H39: =G39*0.2 -> 8.8 | I39: =G39-H39 -> 35.2 | J39: =I39-F39 -> 18.27969 | K39: =J39/I39 -> 0.51930938 | L39: =G39*0.18 -> 7.92 | M39: =G38:G39-L39 -> 36.08 | N39: =M39-F39 -> 19.15969 | O39: =N39/M39 -> 0.53103354
C40: سجق اسبشيال ك | D40: 30.232945 | E40: 5.0066667 | F40: =D40+E40 -> 35.239612 | G40: 73.25 | H40: =G40*0.2 -> 14.65 | I40: =G40-H40 -> 58.6 | J40: =I40-F40 -> 23.360388 | K40: =J40/I40 -> 0.39864144 | L40: =G40*0.18 -> 13.185 | M40: =G39:G40-L40 -> 60.065 | N40: =M40-F40 -> 24.825388 | O40: =N40/M40 -> 0.41330872
C42: الصنف | D42: الخلطة | E42: تغليف | F42: الاجمالى
C43: كفته اسبشيال ص | D43: =D34*0.35 -> 12.877493 | E43: 3.2 | F43: =E43+D43 -> 16.077493 | G43: 30 | H43: =G43*0.2 -> 6 | I43: =G43-H43 -> 24 | J43: =I43-F43 -> 7.9225066 | K43: =J43/I43 -> 0.33010444 | L43: =G43*0.18 -> 5.4 | M43: =G42:G43-L43 -> 24.6 | N43: =M43-F43 -> 8.5225066 | O43: =N43/M43 -> 0.34644336 | P43: =G43*1.05 -> 31.5
C44: كفته اسبشياتل ك | D44: =D34*0.9 -> 33.113554 | E44: 5.1 | F44: =E44+D44 -> 38.213554 | G44: 67.5 | H44: =G44*0.2 -> 13.5 | I44: =G44-H44 -> 54 | J44: =I44-F44 -> 15.786446 | K44: =J44/I44 -> 0.29234158 | L44: =G44*0.18 -> 12.15 | M44: =G43:G44-L44 -> 55.35 | N44: =M44-F44 -> 17.136446 | O44: =N44/M44 -> 0.30960155 | P44: =G44*1.05 -> 70.875
P45: =G45*1.05 -> 0
C46: الصنف | D46: الخلطة | E46: تغليف | F46: الاجمالى | P46: =G46*1.05 -> 0
C47: برجر اسبشيال ص | D47: =K31*0.4 -> 13.92249 | E47: 4.22 | F47: =E47+D47 -> 18.14249 | G47: 32.5 | H47: =G47*0.2 -> 6.5 | I47: =G47-H47 -> 26 | J47: =I47-F47 -> 7.8575102 | K47: =J47/I47 -> 0.30221193 | L47: =G47*0.18 -> 5.85 | M47: =G46:G47-L47 -> 26.65 | N47: =M47-F47 -> 8.5075102 | O47: =N47/M47 -> 0.31923115 | P47: =G47*1.05 -> 34.125
C48: برجر اسبشيال ك | D48: =K31 -> 34.806224 | E48: 5.62 | F48: =E48+D48 -> 40.426224 | G48: 72.5 | H48: =G48*0.2 -> 14.5 | I48: =G48-H48 -> 58 | J48: =I48-F48 -> 17.573776 | K48: =J48/I48 -> 0.30299613 | L48: =G48*0.18 -> 13.05 | M48: =G47:G48-L48 -> 59.45 | N48: =M48-F48 -> 19.023776 | O48: =N48/M48 -> 0.31999622 | P48: =G48*1.05 -> 76.125
...

Sheet اسبشيال 2026
D4: برجر اسبشيال | J4: اسبشيال | K4: سجق | O4: اسبشيال | P4: كفته
B5: النوع | C5: الكميه | D5: السعر | I5: النوع | J5: الكميه | K5: السعر | N5: النوع | O5: الكميه | P5: السعر | Q5: الاجمالي
B6: مفروم فراخ شعبى | C6: 80 | D6: 37 | E6: =C6*D6 -> 2960 | I6: مفروم فراخ شعبى | J6: 105 | K6: 35 | L6: =J6*K6 -> 3675 | N6: مفروم فراخ شعبى | O6: 90 | P6: 35 | Q6: =O6*P6 -> 3150
B7: دهن | C7: 28 | D7: 35 | E7: =C7*D7 -> 980 | I7: دهن | J7: 0 | K7: 35 | L7: =J7*K7 -> 0 | N7: دهن | O7: 60 | P7: 35 | Q7: =O7*P7 -> 2100
B8: فلفل احمر | C8: 25 | D8: 25 | E8: =C8*D8 -> 625 | I8: برغل | J8: 10.5 | K8: =+D11 -> 20 | L8: =J8*K8 -> 210 | N8: فلفل | O8: 15 | P8: 25 | Q8: =O8*P8 -> 375
B9: صويا | C9: 43 | D9: 39 | E9: =C9*D9 -> 1677 | I9: مياه\ | J9: 48 | K9: 0 | L9: =J9*K9 -> 0 | N9: صويا | O9: 27 | P9: 39 | Q9: =O9*P9 -> 1053
B10: فلفل اخضر حار | C10: 2 | D10: 25 | E10: =C10*D10 -> 50 | I10: صويا | J10: 21.75 | K10: 39 | L10: =J10*K10 -> 848.25 | N10: فلفل احمر | O10: 15 | P10: 25 | Q10: =O10*P10 -> 375
B11: برغل | C11: 28 | D11: 20 | E11: =C11*D11 -> 560 | I11: سميد | J11: 0 | K11: 15 | L11: =J11*K11 -> 0 | N11: برغل | O11: 15 | P11: 20 | Q11: =O11*P11 -> 300
B12: نشا | C12: 24 | D12: 28.5 | E12: =C12*D12 -> 684 | I12: جلد | J12: 0 | K12: 35 | L12: =J12*K12 -> 0 | N12: نشا | O12: 15 | P12: 28.5 | Q12: =O12*P12 -> 427.5
B13: شعرية | C13: 0 | D13: 0 | E13: =C13*D13 -> 0 | I13: نشا | J13: 7.5 | K13: 28.5 | L13: =J13*K13 -> 213.75 | N13: بصل | O13: 30 | P13: 12 | Q13: =O13*P13 -> 360
B14: بصل | C14: 25 | D14: 12 | E14: =C14*D14 -> 300 | I14: بصل | J14: 19.5 | K14: =12 -> 12 | L14: =J14*K14 -> 234 | N14: سميد | O14: 19.5 | P14: 15 | Q14: =O14*P14 -> 292.5
B15: سميد | C15: 26 | D15: 15 | E15: =C15*D15 -> 390 | I15: ملح | J15: 4.2 | K15: 2.4 | L15: =J15*K15 -> 10.08 | N15: مياه | O15: 60 | P15: 0 | Q15: =O15*P15 -> 0
B16: مياه | C16: 99 | D16: 0 | E16: =C16*D16 -> 0 | I16: فوسفات | J16: 1.5 | K16: 160 | L16: =J16*K16 -> 240 | N16: مونوصوديم | O16: 1.2 | P16: 100 | Q16: =O16*P16 -> 120
B17: مونوصوديم | C17: 2 | D17: 100 | E17: =C17*D17 -> 200 | I17: لورا | J17: 0 | K17: 130 | L17: =J17*K17 -> 0 | N17: ايزوليت | O17: 4.5 | P17: 160 | Q17: =O17*P17 -> 720
B18: لون 601 | C18: 0.09 | D18: 2500 | E18: =C18*D18 -> 225 | I18: شطه | J18: 0.75 | K18: 65 | L18: =J18*K18 -> 48.75 | N18: كزبرة | O18: 0.75 | P18: 65 | Q18: =O18*P18 -> 48.75
B19: كسبرة | C19: 0.6 | D19: 70 | E19: =C19*D19 -> 42 | I19: مونوصوديم | J19: 1.5 | K19: 100 | L19: =J19*K19 -> 150 | N19: كبابة | O19: 0 | P19: 450 | Q19: =O19*P19 -> 0
B20: شطة | C20: 0.5 | D20: 65 | E20: =C20*D20 -> 32.5 | I20: فلفل اسود | J20: 0 | K20: 400 | L20: =J20*K20 -> 0 | N20: قرنفل | O20: 0 | P20: 480 | Q20: =O20*P20 -> 0
B21: ملح | C21: 6.8 | D21: 2.4 | E21: =C21*D21 -> 16.32 | I21: خلنجان | J21: 0.75 | K21: 230 | L21: =J21*K21 -> 172.5 | N21: قرفه | O21: 0 | P21: 130 | Q21: =O21*P21 -> 0
B22: جبهان | C22: 0.2 | D22: 1300 | E22: =C22*D22 -> 260 | I22: ثوم | J22: 4.5 | K22: 29 | L22: =J22*K22 -> 130.5 | N22: فوسفات | O22: 1.8 | P22: 1.6 | Q22: =O22*P22 -> 2.88
B23: طعم كفته | C23: 0.5 | D23: 190 | E23: =C23*D23 -> 95 | I23: زعتر | J23: 0.38 | K23: 120 | L23: =J23*K23 -> 45.6 | N23: ينسون | O23: 0 | P23: 120 | Q23: =O23*P23 -> 0
B24: طعم بيف | C24: 0.5 | D24: 310 | E24: =C24*D24 -> 155 | I24: ينسون | J24: 0.68888 | K24: 120 | L24: =J24*K24 -> 82.6656 | N24: شطة | O24: 0.15 | P24: 65 | Q24: =O24*P24 -> 9.75
B25: فوسفات | C25: 2 | D25: 160 | E25: =C25*D25 -> 320 | I25: قرفة | J25: 0.6 | K25: 130 | L25: =J25*K25 -> 78 | N25: ملح | O25: 5.1 | P25: 2.4 | Q25: =O25*P25 -> 12.24
B26: جنزبيل | C26: 0.2 | D26: 190 | E26: =C26*D26 -> 38 | I26: كزبره | J26: 1.2 | K26: 70 | L26: =J26*K26 -> 84 | N26: فلفل اسود | O26: 1.5 | P26: 400 | Q26: =O26*P26 -> 600
... B28: بابريكا | C28: 0.5 | D28: 140 | E28: =C28*D28 -> 70 | I28: بيف | J28: 0 | K28: 310 | L28: =J28*K28 -> 0 | N28: لوري | O28: 0.3 | P28: 130 | Q28: =O28*P28 -> 39
B29: الاجمالي | C29: =SUM(C6:C28) -> 394.39 | E29: =SUM(E6:E28) -> 9827.32 | I29: لون | J29: 0.04 | K29: 2500 | L29: =J29*K29 -> 100 | N29: طعم شواء | O29: 0.75 | P29: 295 | Q29: =O29*P29 -> 221.25
B30: سعر الكيلو | C30: =E29/C29 -> 24.917772 | E30: =213.6+E29 -> 10040.92 | I30: الاجمالي | J30: =SUM(J6:J29) -> 228.65888 | L30: =SUM(L6:L29) -> 6408.5956 | N30: طعم كفته | O30: 0.75 | P30: 190 | Q30: =O30*P30 -> 142.5
B31: الصنف | C31: الخلطة | D31: تكاليف التغليف | E31: الاجمالى | I31: سعر الكيلو | J31: =L30/J30 -> 28.026883 | N31: طعم ليه | O31: 1.2 | P31: 295 | Q31: =O31*P31 -> 354
B32: برجر اسبشيال 400 | C32: =C30*0.4 -> 9.9671087 | D32: 5.5 | E32: =C32+D32 -> 15.467109 | I32: هانك | J32: =250/15 -> 16.666667 | N32: طعم بيف | O32: 0.75 | P32: 310 | Q32: =O32*P32 -> 232.5
B33: برجر اسبشيال 1 ك | C33: =C30*1 -> 24.917772 | D33: 6.7 | E33: =C33+D33 -> 31.617772 | I33: الاجمالي | J33: =J32+J31 -> 44.693549 | N33: لون احمر | O33: 0.03 | P33: 2500 | Q33: =O33*P33 -> 75
I34: الصنف | J34: خلطة | K34: تغليف | L34: الاجمالى | N34: الاجمالي | O34: =SUM(O6:O33) -> 365.4 | Q34: =SUM(Q6:Q33) -> 11166.87
I35: سجق اسبشيال 300 | J35: =J33*0.3 -> 13.408065 | K35: 5.2 | L35: =K35+J35 -> 18.608065 | N35: سعر الكيلو | O35: =Q34/O34 -> 30.560673 | P35: .
I36: سجق اسبشيال 700 | J36: =J33*0.7 -> 31.285485 | K36: 7.2 | L36: =K36+J36 -> 38.485485 | P36: 0
I37: سجق 5 ك | J37: =J33*5 -> 223.46775 | K37: 14 | L37: =K37+J37 -> 237.46775
L38: =K38+J38 -> 0 | N38: الصنف | O38: الخلطة | P38: تغليف | Q38: الاجمالى
L39: =K39+J39 -> 0 | N39: كفته اسبشيال 350 | O39: =O35*0.35 -> 10.696236 | P39: 5.5 | Q39: =P39+O39 -> 16.196236
N40: كفته اسبشيال 900 | O40: =O35*0.9 -> 27.504606 | P40: 7.2 | Q40: =P40+O40 -> 34.704606
O41: =R34*5 -> 0 | Q41: =P41+O41 -> 0
P42: =K53 -> 0 | Q42: =P42+O42 -> 0

Sheet Sheet2
K6: سعر | L6: خامات
K7: 31 | L7: صويا مجروش
K8: 27 | L8: جلد
K9: 925 | L9: MX
K10: 30 | L10: بقسماط ابيض
K11: 34 | L11: بقسماط الكرسبى
K12: 14 | L12: بصل فريش مقشر
K13: 27 | L13: نشا ذرة
K14: 260 | L14: لون تيتانيوم
K15: 220 | L15: مكسب طعم فراخ
K16: 125 | L16: مرقة
K17: 175 | L17: زنجبيل
K18: 60 | L18: مونوصوديوم
... K20: 520 | L20: فلفل ابيض
L21: كرفس
K22: 95 | L22: ثوم بودر
L23: بصل بودر
K24: 105 | L24: فوسفات

Sheet Sheet1
E7: سجق اسباشيل
E8: الكمية | F8: النوع
E9: 105 | F9: مفروم
E10: 18 | F10: صويا
E11: 48 | F11: ماء
E12: 19.5 | F12: بصل
E13: 10.5 | F13: برغل
E14: 7.5 | F14: شعرية
E15: 7.5 | F15: نشا
E16: 4.5 | F16: توام
E17: 4.2 | F17: ملح
E18: 1.5 | F18: فوسفات
E19: 1.5 | F19: مونوصوديم
E20: 0.075 | F20: لون احمر
... E24: 0.6 | F24: قرفه
E25: 0.675 | F25: ينسون | N25: من تاريخ 13/5
E26: 0.375 | F26: زعتر
E27: 0.3 | F27: طعم سجق بودر | O27: النوع | P27: الكميه
E28: 232.425 | F28: الاجمالى | O28: مفروم | P28: 80
O29: دهن | P29: 28
O30: فلفل احمر | P30: 25
O31: صويا | P31: 43
O32: فلفل اخضر حار | P32: 2
O33: برغل | P33: 28
O34: نشا | P34: 24
O35: شعرية | P35: 0
O36: بصل | P36: 25
C37: النوع | D37: الكميه | G37: النوع | H37: الكميه | O37: سميد | P37: 26
G38: مفروم | H38: 7 | O38: مياه | P38: 99
C39: جلد | D39: 5 | E39: =D39*4 -> 20 | G39: صويا | H39: 1.2
C40: مفروم | D40: 30 | E40: =D40*4 -> 120 | G40: صميد | H40: 1
C41: دهن | D41: 15 | E41: =D41*4 -> 60 | G41: ماء | H41: 4.2
C42: برغل | D42: 5 | E42: =D42*4 -> 20 | G42: بصل | H42: 1.3
C43: مياه\ | D43: 23 | E43: =D43*4 -> 92 | G43: برغل | H43: 0.7
C44: صويا | D44: 9 | E44: =D44*4 -> 36 | G44: شعرية | H44: 0.5
C45: سميد | D45: 3 | E45: =D45*4 -> 12 | G45: نشا | H45: 0.5
C46: ايزوليت | D46: 1 | E46: =D46*4 -> 4 | G46: توام | H46: 0.3
C47: نشا | D47: 3 | E47: =D47*4 -> 12
C48: بصل | D48: 7 | E48: =D48*4 -> 28
C49: ملح | D49: 1.7 | E49: =D49*4 -> 6.8
...

Sheet الهنا
C4: كفته الهنا
A5: النوع | B5: الكميه | C5: السعر | M5: الهنا | N5: سجق | U5: انتاج البانيه
A6: مفروم فراخ شعبى | B6: 80 | C6: 37 | D6: =B6*C6 -> 2960 | E6: =21.36*10 -> 213.6 | H6: الهنا | I6: برجر | L6: النوع | M6: الكميه | N6: السعر | O6: الاجمالي | U6: ب
A7: دهن | B7: 28 | C7: 35 | D7: =B7*C7 -> 980 | G7: النوع | H7: الكميه | I7: السعر | L7: مفروم فراخ شعبى | M7: =20*3 -> 60 | N7: =I8 -> 37 | O7: =M7*N7 -> 2220 | U7: الصنف | V7: الكمية | W7: سعر الكيلو | X7: الاجمالى
A8: فلفل احمر | B8: 25 | C8: 25 | D8: =B8*C8 -> 625 | G8: مفروم فراخ شعبى | H8: 100 | I8: =+C6 -> 37 | J8: =H8*I8 -> 3700 | L8: دهن | M8: =9*3 -> 27 | N8: =+I9 -> 35 | O8: =M8*N8 -> 945 | U8: ام اكس | V8: 4 | W8: 819.2 | X8: =W8*V8 -> 3276.8
A9: صويا | B9: 43 | C9: 39 | D9: =B9*C9 -> 1677 | G9: دهن | H9: 40 | I9: 35 | J9: =H9*I9 -> 1400 | L9: فلفل | M9: 0 | N9: 5 | O9: =M9*N9 -> 0 | U9: بقسماط كرسبى | V9: 30 | W9: 30 | X9: =W9*V9 -> 900
A10: فلفل اخضر حار | B10: 2 | C10: 25 | D10: =B10*C10 -> 50 | G10: برغل | H10: 20 | I10: =+C11 -> 20 | J10: =H10*I10 -> 400 | L10: صويا | M10: 15 | N10: =+I12 -> 39 | O10: =M10*N10 -> 585 | U10: مرقة دجاج | V10: 2 | W10: 120 | X10: =W10*V10 -> 240
A11: برغل | B11: 28 | C11: 20 | D11: =B11*C11 -> 560 | G11: مياه\ | H11: 116 | I11: 1 | J11: =H11*I11 -> 116 | O11: =M11*N11 -> 0 | X11: =W11*V11 -> 0
A12: نشا | B12: 24 | C12: 28.5 | D12: =B12*C12 -> 684 | G12: صويا | H12: 44 | I12: =+C9 -> 39 | J12: =H12*I12 -> 1716 | L12: برغل | M12: =7.5*3 -> 22.5 | N12: =+I10 -> 20 | O12: =M12*N12 -> 450 | U12: جلد | V12: 290 | W12: 34.4 | X12: =W12*V12 -> 9976
A13: شعرية | B13: 0 | C13: 0 | D13: =B13*C13 -> 0 | G13: سميد | H13: 20 | I13: =+C15 -> 14.5 | J13: =H13*I13 -> 290 | L13: جلد | M13: 0 | N13: 35 | O13: =M13*N13 -> 0 | U13: دقيق | V13: 400 | W13: 16.8 | X13: =W13*V13 -> 6720
A14: بصل | B14: 25 | C14: 12 | D14: =B14*C14 -> 300 | G14: جلد | H14: 20 | I14: 35 | J14: =H14*I14 -> 700 | L14: توام | M14: =2.5*3 -> 7.5 | N14: 29 | O14: =M14*N14 -> 217.5 | U14: نشا | V14: 125 | W14: 30 | X14: =W14*V14 -> 3750
A15: سميد | B15: 26 | C15: 14.5 | D15: =B15*C15 -> 377 | G15: نشا | H15: 20 | I15: 28.5 | J15: =H15*I15 -> 570 | L15: سميد | M15: 21 | N15: 14.5 | O15: =M15*N15 -> 304.5 | U15: فلفل ابيض | V15: 1 | W15: 550 | X15: =W15*V15 -> 550
A16: مياه | B16: 99 | C16: 1 | D16: =B16*C16 -> 99 | G16: بصل | H16: 36 | I16: =+C14 -> 12 | J16: =H16*I16 -> 432 | L16: مياه | M16: =22.5*3 -> 67.5 | N16: 1 | O16: =M16*N16 -> 67.5 | U16: مرقة | V16: 1 | W16: 120 | X16: =W16*V16 -> 120
A17: مونوصوديم | B17: 2 | C17: 100 | D17: =B17*C17 -> 200 | G17: ملح | H17: 6.4 | I17: 2.4 | J17: =H17*I17 -> 15.36 | L17: مونوصوديم | M17: =0.3*3 -> 0.9 | N17: 100 | O17: =M17*N17 -> 90 | U17: بصل | V17: 50 | W17: 14.24 | X17: =W17*V17 -> 712
A18: لون 601 | B18: 0.09 | C18: 2500 | D18: =B18*C18 -> 225 | G18: فوسفات | H18: 2 | I18: 160 | J18: =H18*I18 -> 320 | L18: لون احمر | M18: 0 | N18: 0 | O18: =M18*N18 -> 0 | U18: صميد | V18: 60 | W18: 14 | X18: =W18*V18 -> 840
A19: كسبرة | B19: 0.6 | C19: 70 | D19: =B19*C19 -> 42 | G19: لورا | H19: 0.2 | I19: 130 | J19: =H19*I19 -> 26 | L19: كزبرة | M19: 0 | N19: 65 | O19: =M19*N19 -> 0 | U19: صويا زياد | V19: 100 | W19: 31 | X19: =W19*V19 -> 3100
A20: شطة | B20: 0.5 | C20: 65 | D20: =B20*C20 -> 32.5 | G20: شطه | H20: 0.4 | I20: 65 | J20: =H20*I20 -> 26 | L20: كبابة | M20: 0 | N20: 450 | O20: =M20*N20 -> 0 | U20: خلطة التوابل | V20: 37 | W20: =X42 -> 84.873684 | X20: =W20*V20 -> 3140.3263
A21: ملح | B21: 6.8 | C21: 2.4 | D21: =B21*C21 -> 16.32 | G21: مونوصوديم | H21: 2 | I21: =+C17 -> 100 | J21: =H21*I21 -> 200 | L21: قرنفل | M21: =0.05*3 -> 0.15 | N21: 480 | O21: =M21*N21 -> 72 | U21: بقسماط كريسبى | V21: 500 | W21: 30.5 | X21: =W21*V21 -> 15250
A22: جبهان | B22: 0.2 | C22: 1300 | D22: =B22*C22 -> 260 | G22: قرفة | H22: 0.6 | I22: 130 | J22: =H22*I22 -> 78 | L22: قرفه | M22: =0.08*3 -> 0.24 | N22: 130 | O22: =M22*N22 -> 31.2 | U22: كامينا ابيض | V22: 2 | W22: 395 | X22: =W22*V22 -> 790
A23: طعم كفته | B23: 0.5 | C23: 190 | D23: =B23*C23 -> 95 | G23: كزبره | H23: 0.8 | I23: 65 | J23: =H23*I23 -> 52 | L23: فوسفات | M23: =0.05*3 -> 0.15 | N23: 160 | O23: =M23*N23 -> 24 | U23: ام اكس | V23: 9 | W23: 825 | X23: =W23*V23 -> 7425
A24: طعم بيف | B24: 0.5 | C24: 310 | D24: =B24*C24 -> 155 | G24: طعم شواء | H24: 0.8 | I24: 310 | J24: =H24*I24 -> 248 | L24: ينسون | M24: =0.04*3 -> 0.12 | N24: 120 | O24: =M24*N24 -> 14.4
A25: فوسفات | B25: 2 | C25: 160 | D25: =B25*C25 -> 320 | G25: بيف | H25: 0.8 | I25: 310 | J25: =H25*I25 -> 248 | L25: شطة | M25: =0.14*3 -> 0.42 | N25: 65 | O25: =M25*N25 -> 27.3
A26: جنزبيل | B26: 0.2 | C26: 190 | D26: =B26*C26 -> 38 | G26: لون | H26: 0.09 | I26: 2500 | J26: =H26*I26 -> 225 | L26: ملح | M26: =1.4*3 -> 4.2 | N26: 2.4 | O26: =M26*N26 -> 10.08
A27: طعم ليه | B27: 0.5 | C27: 295 | D27: =B27*C27 -> 147.5 | G27: الاجمالي | H27: =SUM(H8:H26) -> 430.09 | J27: =SUM(J8:J26) -> 10762.36 | L27: ببريكا | M27: =0.1*3 -> 0.3 | N27: 140 | O27: =M27*N27 -> 42
A28: بابريكا | B28: 0.5 | C28: 140 | D28: =B28*C28 -> 70 | G28: سعر الكيلو | H28: =J27/H27 -> 25.023507 | L28: كمون | M28: 0 | N28: 350 | O28: =M28*N28 -> 0
A29: الاجمالي | B29: =SUM(B6:B28) -> 394.39 | D29: =SUM(D6:D28) -> 9913.32 | L29: لوري | M29: 0 | N29: 130 | O29: =M29*N29 -> 0
A30: سعر الكيلو | B30: =D29/B29 -> 25.13583 | D30: =213.6+D29 -> 10126.92 | L30: طعم ليه | M30: =0.05*3 -> 0.15 | N30: 270 | O30: =M30*N30 -> 40.5 | U30: الاجمالى | V30: =SUM(V8:V29) -> 1611 | X30: =SUM(X8:X26) -> 56790.126
A31: الصنف | B31: الخلطة | C31: تغليف | D31: الاجمالى | G31: الصنف | H31: خلطة | I31: تغليف | J31: الاجمالى | L31: طعم بيف | M31: =0.01*3 -> 0.03 | N31: 11 | O31: =M31*N31 -> 0.33 | U31: الخلطة
A32: كفته الهنا 350 | B32: =B30*0.35 -> 8.7975405 | C32: =B49 -> 5.1754545 | D32: =B32+C32 -> 13.972995 | G32: برجر الهنا 380 | H32: =H28*0.38 -> 9.5089325 | I32: =D49 -> 4.88 | J32: =I32+H32 -> 14.388933 | L32: لون احمر | M32: 0.1 | N32: 2500 | O32: =M32*N32 -> 250 | U32: فوسفات | V32: 0.5 | W32: 115.35 | X32: =W32*V32 -> 57.675
A33: كفته الهنا 800 | B33: =B30*0.8 -> 20.108664 | C33: =C49 -> 6.08 | D33: =B33+C33 -> 26.188664 | G33: برجر الهنا 900 | H33: =H28*0.9 -> 22.521156 | I33: =E49 -> 6.63 | J33: =I33+H33 -> 29.151156 | L33: الاجمالي | M33: =SUM(M7:M32) -> 227.26 | O33: =SUM(O7:O32) -> 5391.31 | U33: مونوصوديوم | V33: 1.5 | W33: 70.59 | X33: =W33*V33 -> 105.885
A34: عجينة كفته 5 ك | B34: =B30*5 -> 125.67915 | C34: =J49 -> 14.26 | D34: =B34+C34 -> 139.93915 | G34: برجر 400 | H34: =H28*0.4 -> 10.009403 | I34: 4.22 | J34: =I34+H34 -> 14.229403 | L34: سعر الكيلو | M34: =O33/M33 -> 23.723092 | U34: جنزبيل | V34: 2 | W34: 25.77 | X34: =W34*V34 -> 51.54
A35: كفته الهنا 900 | B35: =B30*0.9 -> 22.622247 | C35: 5.1 | D35: =B35+C35 -> 27.722247 | E35: =D35*1.5 -> 41.583371 | G35: برجر 1 | H35: =H28*1 -> 25.023507 | I35: 5.63 | J35: =I35+H35 -> 30.653507 | M35: هانك | N35: 20 | P35: =M34+N35 -> 43.723092 | U35: مرقه | V35: 3 | W35: 120 | X35: =W35*V35 -> 360
E36: =E35*1.25 -> 51.979213 | G36: برجر 2 | H36: =H28*0.8 -> 20.018805 | I36: 5.6216667 | J36: =I36+H36 -> 25.640472 | U36: طعم فرؤاخ | V36: 1.5 | W36: 220 | X36: =W36*V36 -> 330
E37: =E36/0.9 -> 57.754681 | H37: =K34*1.25 -> 0 | I37: =H37/0.9 -> 0 | L37: الصنف | M37: الخلطة | N37: تغليف | O37: الاجمالى | U37: فلفل ابيض | V37: 1 | W37: 550 | X37: =W37*V37 -> 550
H38: =K35*1.25 -> 0 | I38: =H38/0.9 -> 0 | L38: سجق الهنا 300 | M38: =P35*0.3 -> 13.116928 | N38: =F49 -> 4.63 | O38: =N38+M38 -> 17.746928 | U38: ملح | V38: 7.5 | W38: 2 | X38: =W38*V38 -> 15
A39: الصنف | B39: كفته الهنا ص | C39: كفته الهنا ك | D39: برجر الهنا ص | E39: برجر الهنا ك | F39: سجق الهنا ص | G39: سجق الهنا ك | H39: سجق الهنا 5 ك | I39: عجينة سجق 5 ك | J39: عجينة كفته 5 ك | L39: سجق الهنا 700 | M39: =P35*0.7 -> 30.606165 | N39: =G49 -> 5.99 | O39: =N39+M39 -> 36.596165 | U39: ثوم بودر | V39: 1.5 | W39: 95 | X39: =W39*V39 -> 142.5
A40: أكياس | B40: =280/110 -> 2.5454545 | C40: 2.5 | D40: 2 | E40: 2.75 | F40: 2 | G40: 2.5 | H40: 4 | I40: 4 | J40: 2.2 | L40: سجق الهنا 5 ك | M40: =P35*5 -> 218.61546 | N40: =H49 -> 16.06 | O40: =N40+M40 -> 234.67546 | U40: فلفل اسود | V40: 0.5
A41: فوم | B41: 0.76 | C41: 1.02 | D41: 0.76 | F41: 0.76 | G41: 1.02 | L41: عجينة سجق 5 ك | M41: =M34*5 -> 118.61546 | N41: =I49 -> 16.06 | O41: =N41+M41 -> 134.67546 | U41: سعر الخلطة | V41: =SUM(V32:V40) -> 19 | X41: =SUM(X32:X39) -> 1612.6
A42: كراتين | B42: 1.8 | C42: 2.4 | D42: 1.8 | E42: 2.4 | F42: 1.8 | G42: 2.4 | H42: 12 | I42: 12 | J42: 12 | U42: سعر الكيلو | X42: =X41/V41 -> 84.873684
A43: لزق | B43: 0.07 | C43: 0.07 | D43: 0.07 | E43: 0.07 | F43: 0.07 | G43: 0.07
...

Sheet ورقة1
B3: الهنا
A4: الصنف | B4: الخلطة | C4: تغليف | D4: الاجمالى
A5: سجق الهنا 300 | B5: 13.116928 | C5: 4.63 | D5: 17.746928
A6: سجق الهنا 700 | B6: 30.606165 | C6: 5.99 | D6: 36.596165
A7: سجق الهنا 5 ك | B7: 218.61546 | C7: 16.06 | D7: 234.67546
A8: عجينة سجق 5 ك | B8: 118.61546 | C8: 16.06 | D8: 134.67546
A10: الصنف | B10: الخلطة | C10: تغليف | D10: الاجمالى
A11: كفته الهنا 350 | B11: 8.7975405 | C11: 4.63 | D11: 13.427541
A12: كفته الهنا 800 | B12: 20.108664 | C12: 6.08 | D12: 26.188664
A13: عجينة كفته 5 ك | B13: 125.67915 | C13: 14.26 | D13: 139.93915
A15: الصنف | B15: خلطة | C15: تغليف | D15: الاجمالى
A16: برجر الهنا 380 | B16: 9.5089325 | C16: 4.88 | D16: 14.388933
A17: برجر الهنا 900 | B17: 22.521156 | C17: 6.63 | D17: 29.151156
B21: اسباشيل
A22: الصنف | B22: الخلطة | C22: تغليف | D22: الاجمالى
A23: برجر اسبشيال 400 | B23: 9.9671087 | C23: 5.5 | D23: 15.467109
A24: برجر اسبشيال 1 ك | B24: 24.917772 | C24: 6.7 | D24: 31.617772
A26: الصنف | B26: خلطة | C26: تغليف | D26: الاجمالى
A27: سجق اسبشيال 300 | B27: 12.908065 | C27: 5.2 | D27: 18.108065
A28: سجق اسبشيال 700 | B28: 30.118818 | C28: 7.2 | D28: 37.318818
A29: سجق 5 ك | B29: 215.13441 | C29: 14 | D29: 229.13441
A30: الصنف | B30: الخلطة | C30: تغليف | D30: الاجمالى
A31: كفته اسبشيال 350 | B31: 10.696236 | C31: 5.5 | D31: 16.196236
A32: كفته اسبشيال 900 | B32: 27.504606 | C32: 7.2 | D32: 34.704606
B34: ابو هاشم
A36: الوزن | B36: التكلفه | C36: تكاليف اخري | D36: الاجمالي
A37: برجر 400 جرام | B37: 31.34607 | C37: 4.99 | D37: 36.33607
A38: برجر 800 جرام | B38: 62.692139 | C38: 0 | D38: 62.692139
A39: برجر 600 جرام | B39: 43.100846 | C39: 5.99 | D39: 49.090846
A40: برجر 1ك | B40: 78.365174 | C40: 5.6 | D40: 83.965174
A41: 1200جرام | B41: 94.038209 | C41: 6.18 | D41: 100.21821
A42: 1.5 | B42: 117.54776 | C42: 6.0688889 | D42: 123.61665
A46: الوزن | B46: التكلفه | C46: تكاليف اخري | D46: الاجمالي
A47: سجق | B47: 31.599444 | C47: 4.67 | D47: 36.269444
A48: 800جرام | B48: 72.227301 | C48: 6.27 | D48: 78.497301
A49: 3كيلو | B49: 270.85238 | C49: 9.23 | D49: 280.08238
A50: 5كيلو | B50: 451.42063 | C50: 2.5 | D50: 453.92063
A54: الوزن | B54: التكلفه | C54: تكاليف اخري | D54: الاجمالي
A55: 350جرام | B55: 30.053195 | C55: 4.5 | D55: 34.553195
A56: 800جرام | B56: 68.693017 | C56: 5.35 | D56: 74.043017
